Workbook

Sheet Read Me
B2: DailyObjects — Category Building Block View
B3: Adaptors Range (POP · Loft) · 3-Year View: FY27–FY29
B5: Focus | C5: Adaptors range only — DailyObjects' charging accessories. Two lines: POP (charging adapters & cables — wired GaN/PD fast charging) and Loft (wireless charging stations & docks). Loft is the newer, in-house/IP, more premium line.
B6: Scope | C6: POP = GaN/PD wall adapters + premium USB-C cables (incl. 140W). Loft = Qi2/MagSafe multi-device wireless charging stations, foldable & 3-in-1 docks. Product pages: POP /lp?type=adapter-and-cables · Loft /lp?type=charging-stations (cid 1809).
B7: Currency / horizon | C7: INR; USD converted at Rs 88/USD; values in Rs Crore. FY ends 31 March; market data is calendar-year mapped to nearest FY.
B8: Tabs | C8: Read Me · Assumptions · Adaptors 3Y (six blocks, POP & Loft) · TG & Audience (real Meta data + TG sizing) · Competition · Marketing Strategy (holistic).
B9: Data | C9: Market: IMARC, Grand View, Expert Market Research, Ken Research, Counterpoint/IDC. TG & performance: your LIVE Meta 'pop' & 'loft' campaigns, last 12 months, via Windsor.ai (account: DailyObjects Prepaid 1).
B10: How to read | C10: POP is the established, high-ROAS, younger/value line; Loft is the newer, premium, slightly older/higher-AOV line still scaling. The workbook keeps them side by side so you can see where each wins.
B12: Colour key
C13: Blue = input / assumption you can change
C14: Black = formula
C15: Green = pulled from another tab

Sheet Assumptions
B2: Assumptions & Market Sizing — Adaptors (POP & Loft)
B3: Blue cells are editable; the other tabs link back here. FY27–FY29 are targets you set.
B5: Global
B6: Input | C6: Value | F6: Source / note
B7: USD : INR conversion | C7: 88 | F7: Working assumption, 2026
B8: Rs per Crore | C8: 10000000 | F8: 1 Cr = 1e7
B9: DailyObjects brand AOV (Rs) | C9: 2500 | F9: Brand average, for AOV comparison
B10: DailyObjects total revenue FY27 (Rs Cr) | C10: 400 | F10: CEO guidance (context)
B12: POP — Adapters & Cables market (India wired charging: GaN/PD adapters + premium cables)
B13: Metric | C13: FY26 | D13: FY27 | E13: FY28 | F13: FY29 | G13: Source / note
B14: India TAM base 2024 (USD M) | C14: 2110 | G14: India USB/wired charger TAM ~USD 2.11B, 2024 (Expert Market Research); CAGR 8.9% (2025-34).
B15: TAM CAGR | C15: 0.089 | G15: Secondary research (see note)
B16: India TAM (Rs Cr) | C16: =$C$14*$C$7/10*(1+$C$15)^1 -> 20220.552 | D16: =$C$14*$C$7/10*(1+$C$15)^2 -> 22020.181 | E16: =$C$14*$C$7/10*(1+$C$15)^3 -> 23979.977 | F16: =$C$14*$C$7/10*(1+$C$15)^4 -> 26114.195 | G16: USD M -> Rs Cr = USD M x rate / 10
B17: Premium/branded share of value | C17: 0.18 | D17: 0.2 | E17: 0.22 | F17: 0.25 | G17: GaN/branded premium tier where POP plays. India GaN chargers ~USD 79M 2023 growing ~18-20% (Ken Research); premium cables incl. 140W. Editable.
B18: Premium SAM (Rs Cr) — total market | C18: =C16*C17 -> 3639.6994 | D18: =D16*D17 -> 4404.0362 | E18: =E16*E17 -> 5275.595 | F18: =F16*F17 -> 6528.5488 | G18: On+offline premium market (context)
B19: Online share of market (%) | C19: 0.45 | D19: 0.45 | E19: 0.45 | F19: 0.45 | G19: Accessories online channel; premium/design DTC skews online. Moderated for India offline. Editable.
B20: Online TAM (Rs Cr) | C20: =C16*C19 -> 9099.2484 | D20: =D16*D19 -> 9909.0815 | E20: =E16*E19 -> 10790.99 | F20: =F16*F19 -> 11751.388 | G20: India TAM x online share
B21: Premium ONLINE SAM (Rs Cr) — DO target | C21: =C20*C17 -> 1637.8647 | D21: =D20*D17 -> 1981.8163 | E21: =E20*E17 -> 2374.0177 | F21: =F20*F17 -> 2937.847 | G21: DO's real serviceable market (online only)
B22: DO revenue (Rs Cr) | C22: 30 | D22: 45 | E22: 58 | F22: 72 | G22: PLACEHOLDER aspiration — REPLACE with your POP actuals/targets. FY26 base, FY27-29 growth.
B23: DO share (of total premium SAM) | C23: =C22/C18 -> 0.008242439 | D23: =D22/D18 -> 0.0102179 | E23: =E22/E18 -> 0.010994021 | F23: =F22/F18 -> 0.011028485 | G23: Share of full on+offline premium market
B24: DO market share (of premium online SAM) | C24: =C22/C21 -> 0.018316531 | D24: =D22/D21 -> 0.022706444 | E24: =E22/E21 -> 0.024431157 | F24: =F22/F21 -> 0.024507744 | G24: DO share of the ONLINE serviceable market (the real read)
B25: Basket AOV (Rs) | D25: 2399 | E25: 2450 | F25: 2500 | G25: AOV MEASURED from your Meta 'pop' campaigns, last 12m (Rs 2,399). FY28-29 assume mild premiumisation.
B26: Projected units / orders (#) | D26: =(D22/D25)*$C$8 -> 187578.16 | E26: =(E22/E25)*$C$8 -> 236734.69 | F26: =(F22/F25)*$C$8 -> 288000 | G26: Revenue / AOV x Rs per Cr
B28: LOFT — Charging Stations market (India wireless charging: Qi2/MagSafe stations & docks)
B29: Metric | C29: FY26 | D29: FY27 | E29: FY28 | F29: FY29 | G29: Source / note
B30: India TAM base 2024 (USD M) | C30: 616.9 | G30: India wireless charging TAM USD 616.9M, 2024 (IMARC); CAGR 11.44% (2025-33).
B31: TAM CAGR | C31: 0.1144 | G31: Secondary research (see note)
B32: India TAM (Rs Cr) | C32: =$C$30*$C$7/10*(1+$C$31)^1 -> 6049.7656 | D32: =$C$30*$C$7/10*(1+$C$31)^2 -> 6741.8587 | E32: =$C$30*$C$7/10*(1+$C$31)^3 -> 7513.1274 | F32: =$C$30*$C$7/10*(1+$C$31)^4 -> 8372.6292 | G32: USD M -> Rs Cr = USD M x rate / 10
B33: Premium/branded share of value | C33: 0.22 | D33: 0.24 | E33: 0.26 | F33: 0.28 | G33: Multi-device Qi2/MagSafe charging STATIONS (premium slice of wireless charging, vs simple pads). Editable.
B34: Premium SAM (Rs Cr) — total market | C34: =C32*C33 -> 1330.9484 | D34: =D32*D33 -> 1618.0461 | E34: =E32*E33 -> 1953.4131 | F34: =F32*F33 -> 2344.3362 | G34: On+offline premium market (context)
B35: Online share of market (%) | C35: 0.55 | D35: 0.55 | E35: 0.55 | F35: 0.55 | G35: Premium wireless / MagSafe design buyers skew strongly online. Editable.
B36: Online TAM (Rs Cr) | C36: =C32*C35 -> 3327.3711 | D36: =D32*D35 -> 3708.0223 | E36: =E32*E35 -> 4132.2201 | F36: =F32*F35 -> 4604.946 | G36: India TAM x online share
B37: Premium ONLINE SAM (Rs Cr) — DO target | C37: =C36*C33 -> 732.02163 | D37: =D36*D33 -> 889.92535 | E37: =E36*E33 -> 1074.3772 | F37: =F36*F33 -> 1289.3849 | G37: DO's real serviceable market (online only)
B38: DO revenue (Rs Cr) | C38: 10 | D38: 22 | E38: 38 | F38: 55 | G38: PLACEHOLDER aspiration — REPLACE with your Loft actuals/targets. New IP line, faster ramp.
B39: DO share (of total premium SAM) | C39: =C38/C34 -> 0.0075134391 | D39: =D38/D34 -> 0.013596646 | E39: =E38/E34 -> 0.01945313 | F39: =F38/F34 -> 0.023460799 | G39: Share of full on+offline premium market
B40: DO market share (of premium online SAM) | C40: =C38/C37 -> 0.013660798 | D40: =D38/D37 -> 0.024721175 | E40: =E38/E37 -> 0.035369328 | F40: =F38/F37 -> 0.042655999 | G40: DO share of the ONLINE serviceable market (the real read)
B41: Basket AOV (Rs) | D41: 3353 | E41: 3450 | F41: 3550 | G41: AOV MEASURED from your Meta 'loft' campaigns, last 12m (Rs 3,353) — ~40% above POP. FY28-29 mild premiumisation.
B42: Projected units / orders (#) | D42: =(D38/D41)*$C$8 -> 65612.884 | E42: =(E38/E41)*$C$8 -> 110144.93 | F42: =(F38/F41)*$C$8 -> 154929.58 | G42: Revenue / AOV x Rs per Cr

Sheet Adaptors · POP & Loft · 3Y
B2: Adaptors (POP & Loft) — 3-Year Building Block View
B3: POP = wired GaN/PD adapters + cables · Loft = Qi2/MagSafe wireless charging stations · FY27–FY29 · figures link to Assumptions
B5: Building block | C5: Approach | D5: Metric | E5: FY26 | F5: FY27 | G5: FY28 | H5: FY29 | I5: Read / insight
B6: 1 | CATEGORY SIZE (secondary research)
C7: Secondary | D7: POP — India TAM (Rs Cr) | E7: =Assumptions!C16 -> 20220.552 | F7: =Assumptions!D16 -> 22020.181 | G7: =Assumptions!E16 -> 23979.977 | H7: =Assumptions!F16 -> 26114.195 | I7: India wired-charging accessories market (adapters + cables)
C8: Secondary | D8: POP — premium online SAM (Rs Cr) | E8: =Assumptions!C21 -> 1637.8647 | F8: =Assumptions!D21 -> 1981.8163 | G8: =Assumptions!E21 -> 2374.0177 | H8: =Assumptions!F21 -> 2937.847 | I8: Online, premium/branded slice POP actually serves
C9: Secondary | D9: Loft — India TAM (Rs Cr) | E9: =Assumptions!C32 -> 6049.7656 | F9: =Assumptions!D32 -> 6741.8587 | G9: =Assumptions!E32 -> 7513.1274 | H9: =Assumptions!F32 -> 8372.6292 | I9: India wireless-charging market (IMARC)
C10: Secondary | D10: Loft — premium online SAM (Rs Cr) | E10: =Assumptions!C37 -> 732.02163 | F10: =Assumptions!D37 -> 889.92535 | G10: =Assumptions!E37 -> 1074.3772 | H10: =Assumptions!F37 -> 1289.3849 | I10: Online Qi2/MagSafe station slice Loft serves
B12: 2 | PRICE DISTRIBUTION (secondary research)
B13: Tier | C13: Typical product | D13: Approx. share (vol / value) | I13: DO SKUs
B14: Mass wired (<Rs500) | C14: Bundled/generic bricks & cables (local, no-name) | D14: ~55% vol / ~25% value | I14: —
B15: Branded wired (Rs500-1,200) | C15: boAt/Portronics/Ambrane fast chargers & cables | D15: ~28% vol / ~30% value | I15: POP entry cables
B16: Premium GaN/PD + premium cable (Rs1,200-3,500) | C16: GaN 33-100W, 140W USB-C, braided premium cables | D16: ~13% vol / ~30% value | I16: POP adapters & 140W cable
B17: Premium wireless station (>Rs3,000) | C17: Qi2/MagSafe 3-in-1 & foldable charging stations | D17: ~4% vol / ~15% value | I17: Loft stations & docks
B18: Read: POP owns the premium wired tier (GaN/PD adapters + premium/140W cables) — above the commoditised <Rs500 mass bricks. Loft sits at the top: premium Qi2/MagSafe stations, a small but fast-growing, still-NASCENT slice (most buyers still use a bundled brick + a pad). DO avoids the mass wired price war.
B20: 3 | MARKET SHARE ASPIRATION (primary — your targets)
C21: Primary | D21: POP — DO revenue / SOM (Rs Cr) | E21: =Assumptions!C22 -> 30 | F21: =Assumptions!D22 -> 45 | G21: =Assumptions!E22 -> 58 | H21: =Assumptions!F22 -> 72 | I21: POP adapters & cables (your target)
C22: Primary | D22: POP — share of premium online SAM | E22: =Assumptions!C24 -> 0.018316531 | F22: =Assumptions!D24 -> 0.022706444 | G22: =Assumptions!E24 -> 0.024431157 | H22: =Assumptions!F24 -> 0.024507744 | I22: POP share of its ONLINE serviceable market
C23: Primary | D23: Loft — DO revenue / SOM (Rs Cr) | E23: =Assumptions!C38 -> 10 | F23: =Assumptions!D38 -> 22 | G23: =Assumptions!E38 -> 38 | H23: =Assumptions!F38 -> 55 | I23: Loft stations (your target — new IP line)
C24: Primary | D24: Loft — share of premium online SAM | E24: =Assumptions!C40 -> 0.013660798 | F24: =Assumptions!D40 -> 0.024721175 | G24: =Assumptions!E40 -> 0.035369328 | H24: =Assumptions!F40 -> 0.042655999 | I24: Loft share of its ONLINE serviceable market
C25: Primary | D25: Adaptors combined revenue (Rs Cr) | E25: =E21+E23 -> 40 | F25: =F21+F23 -> 67 | G25: =G21+G23 -> 96 | H25: =H21+H23 -> 127 | I25: POP + Loft together
B27: 4 | AOV (primary — MEASURED from your Meta campaigns)
C28: Primary | D28: POP basket AOV (Rs) | F28: =Assumptions!D25 -> 2399 | G28: =Assumptions!E25 -> 2450 | H28: =Assumptions!F25 -> 2500 | I28: Measured: Meta 'pop' campaigns, last 12m (Rs 2,399)
C29: Primary | D29: Loft basket AOV (Rs) | F29: =Assumptions!D41 -> 3353 | G29: =Assumptions!E41 -> 3450 | H29: =Assumptions!F41 -> 3550 | I29: Measured: Meta 'loft' campaigns, last 12m (Rs 3,353)
C30: Primary | D30: Loft AOV vs POP AOV | F30: =F29/F28 -> 1.3976657 | G30: =G29/G28 -> 1.4081633 | H30: =H29/H28 -> 1.42 | I30: Loft basket is ~1.4x POP — premium mix, margin & LTV accretive
C31: Primary | D31: POP implied orders (#) | F31: =Assumptions!D26 -> 187578.16 | G31: =Assumptions!E26 -> 236734.69 | H31: =Assumptions!F26 -> 288000 | I31: POP revenue / AOV
C32: Primary | D32: Loft implied orders (#) | F32: =Assumptions!D42 -> 65612.884 | G32: =Assumptions!E42 -> 110144.93 | H32: =Assumptions!F42 -> 154929.58 | I32: Loft revenue / AOV
B34: 5 | TG + 6 | MARKETING
B35: TG profile & TG SIZING (built from your live Meta 'pop' and 'loft' campaigns) are on the 'TG & Audience' tab. The holistic marketing plan is on 'Marketing Strategy'. Competitive context is on 'Competition'.

Sheet TG & Audience
B2: Target Group — Adaptors (POP & Loft)
B3: Built from your LIVE Meta 'pop' & 'loft' campaigns (last 12 months, via Windsor.ai), then sized against the India market. Blue = measured/editable.
B5: A. PERFORMANCE TODAY — your live Meta campaigns (last 12 months)
B6: Metric | C6: POP · Adapters & Cables | D6: Loft · Charging Stations | F6: Read
B7: Campaigns analysed (#) | C7: 13 | D7: 5 | F7: All 'pop' / 'loft' campaigns, last 12m
B8: Ad spend (Rs) | C8: 3663580 | D8: 5337202 | F8: Loft outspending POP as DO scales the new line
B9: Orders / purchases (#) | C9: 9880 | D9: 5180 | F9: Meta-attributed omni purchases
B10: Revenue (Rs) | C10: 23697652 | D10: 17366425 | F10: Meta-attributed purchase value
B11: ROAS | C11: =C10/C8 -> 6.4684413 | D11: =D10/D8 -> 3.2538444 | F11: POP highly efficient; Loft still ramping
B12: AOV (Rs) | C12: =C10/C9 -> 2398.5478 | D12: =D10/D9 -> 3352.5917 | F12: Loft basket ~40% richer — premium mix
B13: Cost / purchase (Rs) | C13: =C8/C9 -> 370.80769 | D13: =D8/D9 -> 1030.3479 | F13: Loft ~2.8x costlier to convert (nascent, premium)
B14: Impressions (#) | C14: 59159896 | D14: 40575884
B15: Reach (#) | C15: 13159770 | D15: 8391604
B16: Clicks (#) | C16: 397160 | D16: 372990
B17: CTR | C17: =C16/C14 -> 0.0067133316 | D17: =D16/D14 -> 0.009192406 | F17: Loft creative pulls stronger clicks
B18: CPM (Rs) | C18: =C8/C14*1000 -> 61.926748 | D18: =D8/D14*1000 -> 131.53631 | F18: Loft CPM ~2x — premium/broader prospecting
B19: Add-to-carts (#) | C19: 59137 | D19: 32335
B20: ATC → purchase rate | C20: =C9/C19 -> 0.16706969 | D20: =D9/D19 -> 0.16019793 | F20: POP converts carts better (cheaper, habitual buy)
B21: Snapshot: POP is the high-efficiency workhorse — ~6.5x ROAS, young (≈80% under 35) and male (77%), a habitual, value-led buy. Loft is the premium newcomer — ~3.3x ROAS, higher AOV & CPM, skewing older (35-44 is 21% of Loft orders vs 14% for POP) and a little more female. Loft is prospecting-heavy today; efficiency should rise as the category matures.
B23: B. WHO BUYS — age & gender (share of orders, Meta last 12m)
B24: Age band | C24: POP buyers | D24: Loft buyers | E24: Market TG mix (est.) | F24: Read
B25: 18-24 | C25: 0.3099 | D25: 0.2024 | E25: 0.24 | F25: POP over-indexes hard on Gen-Z; Loft still young but less so
B26: 25-34 | C26: 0.4863 | D26: 0.4849 | E26: 0.4 | F26: Core for both — early-career, high device turnover
B27: 35-44 | C27: 0.1393 | D27: 0.2146 | E27: 0.22 | F27: Loft's premium edge: pro buyers, desk/home stations
B28: 45-54 | C28: 0.0442 | D28: 0.0722 | E28: 0.09 | F28: Loft reaches deeper into older, higher-income tail
B29: 55-64 | C29: 0.0136 | D29: 0.0201 | E29: 0.03 | F29: Minimal
B30: 65+ | C30: 0.0068 | D30: 0.0058 | E30: 0.02 | F30: Negligible
B31: Total / check | C31: =SUM(C25:C30) -> 1.0001 | D31: =SUM(D25:D30) -> 1 | E31: =SUM(E25:E30) -> 1 | F31: Order shares (measured); market mix is an editable estimate
B32: memo: under-35 share | C32: =C25+C26 -> 0.7962 | D32: =D25+D26 -> 0.6873 | E32: =E25+E26 -> 0.64 | F32: POP skews younger than Loft; both younger than the market
B34: Gender (share of orders)
B35: Gender | C35: POP | D35: Loft | F35: Read
B36: Male | C36: 0.7714 | D36: 0.7596 | F36: Both male-dominated; Loft marginally more balanced
B37: Female | C37: =1-C36 -> 0.2286 | D37: =1-D36 -> 0.2404 | F37: Women ~23-24% — the funded growth headroom for both
B39: C. WHERE THEY ARE — top states (share of ad spend, last 12m)
B40: State | C40: POP spend share | D40: Loft spend share | F40: Read
B41: Maharashtra | C41: 0.2066 | D41: 0.1984 | F41: Metro-led; MH+KA+DL ≈ 43-44% of spend for both
B42: Karnataka | C42: 0.1434 | D42: 0.1299
B43: Delhi | C43: 0.089 | D43: 0.0893
B44: Gujarat | C44: 0.071 | D44: 0.0672
B45: Tamil Nadu | C45: 0.0645 | D45: 0.065
...

Sheet Competition
B2: Competitive Landscape — India Chargers, Cables & Wireless Stations
B3: Who POP (wired GaN/PD + cables) and Loft (Qi2/MagSafe stations) compete with, their scale, and their strategy.
B5: Competitor | C5: Type / origin | D5: Scale (India) | E5: Price band | F5: Positioning & strategy | G5: DO's angle vs them
B6: Anker (incl. MagGo) | C6: Global (HQ China); Amazon-led | D6: Global #1 charging brand; premium leader in India online | E6: Rs1,800-6,000 | F6: The GaN + Qi2 MagSafe benchmark: PowerIQ, GaNPrime, MagGo stands, brand trust, deep reviews, Amazon distribution. | G6: The one to beat in premium. DO wins on design language, aluminium build, DTC & the Stack/MagSafe ecosystem; Anker owns Amazon search & trust.
B7: UGREEN (Nexode) | C7: Global (China); value-premium | D7: Fast-growing online | E7: Rs1,500-4,500 | F7: Spec-heavy GaN (Nexode) + wireless at aggressive prices; Amazon-led. | G7: Undercuts DO on price; DO wins on premium design, finish & ecosystem — must not price-fight.
B8: Belkin | C8: Global (US / Foxconn) | D8: Premium, Apple-channel | E8: Rs2,500-8,000 | F8: Premium Qi2 MagSafe + chargers; Apple-store credibility, iPhone-ready, long warranty. | G8: Premium but less design/ecosystem-led; DO matches on Qi2, wins on design-value & DTC.
B9: Spigen | C9: Global (Korea) | D9: Mid-premium online | E9: Rs1,800-5,000 | F9: ArcStation GaN + MagFit wireless; strong case-buyer cross-sell on Amazon. | G9: Direct ecosystem rival (cases→charging); DO defends with its own case↔charging Stack cross-sell.
B10: Stuffcool | C10: India premium D2C | D10: Mid | E10: Rs1,500-5,000 | F10: Feature-rich premium Indian GaN + Qi2 wireless: built-in cable, stands, displays. | G10: Closest premium Indian rival; DO differentiates on design language, brand & ecosystem depth.
B11: boAt | C11: India mass-mid (lifestyle) | D11: Very large brand | E11: Rs499-1,800 | F11: Mass fast chargers & cables + entry wireless; huge distribution, celebrity brand. | G11: Commoditises the low/mid tier; DO must NOT price-fight — win on premium design & build.
B12: Portronics / Ambrane / URBN | C12: India value-mass | D12: High volume | E12: Rs399-2,000 | F12: Volume chargers, cables & low-price MagSafe wireless; wide availability. | G12: They own the value shelf; DO plays a tier above on premium GaN + premium stations.
B13: Apple / Samsung (first-party) | C13: OEM | D13: Premium bundled/branded | E13: Rs1,900-8,000 | F13: OEM chargers/cables & MagSafe/wireless as the 'safe default' for their phone owners. | G13: DO offers better design-value & multi-device stations vs single-brand OEM kit.
B15: Market-size context
B16: • | C16: India mobile phone accessories market ~USD 3.09B, 2024 (IMARC); mobile/USB charger market ~USD 2.1B, 2024 (Expert Market Research), CAGR ~8-9%. Mass wired dominates volume; the premium/branded tier is where POP plays.
B17: • | C17: India GaN charger market ~USD 79M (2023) growing ~18-20%/yr (Ken Research) — the fast-growing premium slice POP targets; the 'One Nation, One Charger' USB-C standardisation is a tailwind.
B18: • | C18: India wireless charging market ~USD 616.9M, 2024 (IMARC), CAGR 11.4% (2025-33) — Loft's category. Multi-device Qi2/MagSafe STATIONS are the premium, still-NASCENT top slice: a land-grab, not a share-steal.
B20: Strategic takeaway — where DO can win
B21: Two different fights. POP is a SHARE fight in a big, established market: beat boAt/Portronics/UGREEN/Anker on premium design, aluminium build, Qi2/GaN credibility and — crucially — attach POP to every phone/case/watchband order via the DO ecosystem. Loft is a CATEGORY-CREATION fight in a nascent premium slice: educate premium-phone owners that a Rs 3,000+ MagSafe/Qi2 station beats a bundled brick + cheap pad, and defend the design/ecosystem high-ground vs Anker MagGo & Belkin. Ecosystem lock-in (case↔charger↔station) is DO's moat vs single-product global brands.

Sheet Marketing Strategy
B2: Marketing Strategy — Adaptors (POP & Loft)
B3: From the TG outward: who they are → how they behave → what we say → where we reach them → the category plays that compound. Channel choices reflect measured POP (~6.5x) & Loft (~3.3x) ROAS.
B5: 1 | START WITH THE TG — who they are & how they behave
B6: Dimension | C6: Insight (from your Meta data) | D6: What it means for marketing
B7: Who | C7: Both ~77% male, metro (top 8 states ≈74% of spend). POP ≈80% under 35; Loft a bit older (35-44 = 21% of orders). | D7: Lead young+male+metro; fund women (~23-24%) and, for Loft, 35-44 professionals as growth bets.
B8: How they discover | C8: Creator/social-led. Your influencer 'pop'/'loft' campaigns drove the bulk of orders; video & carousel work. | D8: Make tech/lifestyle creators the discovery spine; demo GaN speed & the MagSafe snap-on.
B9: Purchase triggers | C9: New phone, travel, upgrade to fast/wireless charging, desk-setup upgrade (Loft), gifting. | D9: Plan around the iPhone launch & travel/festive seasons; attach to device purchases.
B10: Decision drivers | C10: POP: fast-charge speed, build, cable durability, price-value. Loft: MagSafe/Qi2 convenience, multi-device, design, TRUST/SAFETY. | D10: Sell speed+build for POP; sell convenience+design+trust for Loft (certification, warranty).
B11: Category state | C11: POP: established, competitive. Loft: premium wireless stations still NASCENT. | D11: POP = win share & attach. Loft = create the category and educate on value.
B13: 2 | POSITIONING & MESSAGING — by line & TG segment
B14: Segment | C14: Line / priority | D14: Positioning / message | E14: Hero SKU | F14: Proof / hook
B15: Core young male (25-34) | C15: POP · defend & grow | D15: 'Fast, tough, everyday charging' — GaN speed + premium braided build. | E15: POP GaN + 140W cable | F15: Speed demo; durability
B16: 18-24 students/gaming | C16: POP · volume & entry | D16: 'Charge fast, never fray' — value premium over a bundled brick. | E16: POP entry adapter/cable | F16: Price-value; creator UGC
B17: Premium / iPhone owners | C17: Loft · premiumise | D17: 'One dock, phone+watch+buds, cable-free' — Qi2/MagSafe design. | E17: Loft 3-in-1 station | F17: MagSafe snap; desk aesthetic
B18: 35-44 professionals | C18: Loft · grow | D18: 'The dependable desk & bedside station' — multi-device, safe, elegant. | E18: Loft foldable/3-in-1 | F18: Capacity, safety, warranty
B19: Women (≈23-24% → grow) | C19: POP+Loft · funded growth | D19: Slim cables & compact chargers; bag-friendly; aesthetic colourways. | E19: POP compact / Loft foldable | F19: Female creators; EDC framing
B20: Gifting | C20: Loft · seasonal | D20: A premium, useful, giftable charging upgrade. | E20: Loft station / bundle | F20: Festive + new-phone gifting
B22: 3 | CHANNELS — mapped to behaviour & measured ROAS
B23: Channel | C23: Role | D23: Why (behaviour / data) | E23: Proven signal | F23: How to use it
B24: Creators / influencers | C24: PRIMARY engine | D24: Your 'pop'/'loft' influencer campaigns drove most orders. | E24: POP ~6.5x, Loft ~3.3x ROAS | F24: Tech/lifestyle roster; GaN-speed & MagSafe-snap demos; add female creators.
B25: Meta Reels / video | C25: TOF/MOF scale | D25: Video & carousel out-performed; Loft CTR strongest. | E25: Video best | F25: Run winning creator video as paid; travel & new-phone hooks.
B26: Amazon | C26: CRITICAL intent + trust | D26: Charger buyers research & buy on Amazon; Anker's stronghold. | E26: Anker leads here | F26: Win 'GaN charger'/'MagSafe stand' queries; build reviews; defend vs Anker/UGREEN.
B27: Google Shopping / PMax + search | C27: MOF/BOF intent | D27: Captures 'GaN charger','140W cable','MagSafe stand' search. | E27: High-intent | F27: Feed + PLPs; buying-guide content; branded search.
B28: DPA retargeting | C28: BOF closer | D28: Warm audiences; proven across DO. | E28: ~4x DO-wide | F28: Always-on; 'complete your setup' with case + POP/Loft.
B29: Attach / cross-sell (owned) | C29: GROWTH lever | D29: 52% repeat base; every phone/case/watch order can attach a charger. | E29: Repeat base | F29: Case→POP cable, phone→Loft station bundles at checkout & in email/SMS.
B30: Q-commerce (Blinkit) | C30: Immediacy | D30: Travel-day / dead-phone emergencies are urgent (POP). | E30: Impulse/urgency | F30: Stock POP adapters & cables for instant buys.
B31: Offline (DO + Tier-1/2) | C31: Trust & try | D31: Holding a station builds confidence (Loft). | E31: Omnichannel | F31: Demo wireless charging; new-phone tie-ins.
B33: 4 | FULL-FUNNEL DESIGN
B34: Stage | C34: Objective | D34: Channels & concepts | E34: Audience | F34: Primary KPI
B35: TOF | C35: Reach & (for Loft) create the category | D35: Creator GaN-speed & MagSafe-snap films, 'ditch the bundled brick', desk-setup content. | E35: Lookalikes of POP/Loft buyers; iPhone owners; 18-34; expand women & 35-44 | F35: Reach, VVR, CPM, new visitors
B36: MOF | C36: Educate & compare | D36: 'Which GaN wattage','140W explained','why a Qi2 station', vs Anker/UGREEN compares, UGC. | E36: TOF engagers, PDP visitors, charger/station search | F36: CTR, ATC, PDP depth, cost/LPV
B37: BOF | C37: Convert, attach & cross-sell | D37: DPA, branded search, Amazon, Q-comm, bundle POP+cable & Loft+case, festive offers. | E37: Abandoners, 30-day visitors, 52% repeat base | F37: ROAS, CAC, CVR, AOV, attach rate
B39: 5 | CATEGORY-LED INTERVENTIONS — the plays that compound
B40: Play | C40: What it is | D40: Why it wins
B41: Ecosystem attach | C41: Attach POP cable/adapter & Loft station to every phone/case/watchband order. | D41: DO's biggest unlock & moat vs global single-product brands — lifts AOV & LTV with near-zero CAC.
B42: Loft category creation | C42: Educate 'why a Qi2/MagSafe station beats a bundled brick + cheap pad'. | D42: Loft's segment is nascent; growing it lifts Loft with it — the core job for the premium line.
B43: iPhone-launch pairing | C43: Position POP (fast charge) & Loft (MagSafe) as the new-iPhone companions; Sept bundles. | D43: New-phone buyers are primed for charging upgrades — high-intent window.
B44: Defend vs Anker/UGREEN on Amazon | C44: Reviews, ratings, A+ content, GaN/Qi2-certified & design messaging. | D44: Amazon is where charger buyers convert & Anker dominates; can't cede it.
B45: Wattage / capacity ladder | C45: Clear guidance: 33W→65W→100W GaN; single→3-in-1 station. | D45: Helps buyers self-select; lifts mix toward higher-AOV SKUs.
B46: Trust / safety content | C46: Surface GaN/Qi2 certification, BIS, warranty, safety testing. | D46: A charger is safety-sensitive; trust converts — especially for Loft.
...
