Workbook

Sheet 1. Executive Dashboard
A1: DAILYOBJECTS | TACTICAL REVENUE GROWTH PLAYBOOK
A2: Executive Dashboard · 57 tactical ideas · evidence: GA4 (India web+app) 2025-08-01 to 2026-07-31 + internal files + 52 D2C brand tactics · Priority = RevImpact x Confidence x Ease x Speed x MarginFriendly (/100)
A4: TOP 5 BETS — what we would launch immediately | P4: Ideas by Revenue Lever
A5: # | B5: Bet | C5: Target customer | D5: Category / SKUs | E5: Revenue mechanism | F5: Expected impact | G5: Margin | H5: Time to launch | P5: CVR | Q5: =COUNTIF('2. Master Opportunity List'!$E$4:$E$60,"CVR")
A6: 1 | B6: Close the mobile & payment conversion gap (ID11+ID12+ID47) | C6: 91% of traffic (mobile) + all checkout, esp. payment-stage droppers | D6: Cross-category / checkout | E6: Mobile is 49M sessions at 0.95% CVR vs 1.96% desktop; 42% drop after add-payment-info. Fix mobile PDP/checkout + UPI express + failed-payment retry. | F6: Very High - largest single prize; +0.3-0.5pp mobile CVR = ~₹150-400M | G6: Accretive (RTO down) | H6: <14-30 days | P6: AOV | Q6: =COUNTIF('2. Master Opportunity List'!$E$4:$E$60,"AOV")
A7: 2 | B7: Phone-case attach engine + FBT (ID01+ID13) | C7: Every case buyer (57% of all product views) | D7: Phone Cases + screen guard/grip/charm (1101,1103,1815,1812) | E7: Cases draw 31M views at ASP ~₹1,068; attach a 30-50%-off screen guard/grip in PDP+cart. High-margin accessory attach. | F7: High - +8-15% AOV on the biggest-traffic category | G7: Accretive | H7: <7 days | P7: Frequency | Q7: =COUNTIF('2. Master Opportunity List'!$E$4:$E$60,"Frequency")
A8: 3 | B8: Turn on lifecycle CRM (abandonment, browse, O1->O2, SMS/WhatsApp) (ID19,20,24,47,18) | C8: Abandoners, browsers, first-order buyers, owned base | D8: Cross-category | E8: Owned channels are ~0.55% of revenue today despite SMS converting at 4.2%. 1.5M checkout-abandoners/yr. Build flows + scale SMS/WA. | F8: High - recover lost demand; ₹50-150M owned-channel upside | G8: Accretive | H8: <7-14 days | P8: Traffic Monetisation | Q8: =COUNTIF('2. Master Opportunity List'!$E$4:$E$60,"Traffic Monetisation")
A9: 4 | B9: Cart free-gift ladder + threshold architecture (ID06+ID49+ID07) | C9: All carts near threshold; new users at ₹2,299 | D9: Cross-category / GWP | E9: Anchor a gift ladder at ₹1,999/₹2,999 (high perceived value, low COGS) + align WELCOME300 + prepaid free-ship. Pull baskets up without % discounts. | F9: High - +6-12% AOV | G9: Neutral (gift COGS < uplift) | H9: <7-14 days | P9: Cross-category Purchase | Q9: =COUNTIF('2. Master Opportunity List'!$E$4:$E$60,"Cross-category Purchase")
A10: 5 | B10: Ecosystem bundles: power-bank+case & bag carry-system (ID02+ID03+ID04) | C10: Power-bank, bag & watch-band shoppers | D10: Power banks (1809), Bags (1201-04), Watch bands (1801) | E10: Highest-revenue + high-consideration categories; MagSafe/carry interoperability makes bundles natural. Power bank+case, bag+sleeve+organiser, multi-band. | F10: High - +10-25% AOV on premium baskets | G10: Accretive/Neutral | H10: <7-14 days | P10: Category Penetration | Q10: =COUNTIF('2. Master Opportunity List'!$E$4:$E$60,"Category Penetration")
P11: Revenue from CRM audiences | Q11: =COUNTIF('2. Master Opportunity List'!$E$4:$E$60,"Revenue from CRM audiences")
A12: PORTFOLIO AT A GLANCE | P12: New User Conversion | Q12: =COUNTIF('2. Master Opportunity List'!$E$4:$E$60,"New User Conversion")
A13: =COUNTA('2. Master Opportunity List'!$A$4:$A$60) | D13: =COUNTIF('2. Master Opportunity List'!$AH$4:$AH$60,">=4") | G13: =COUNTIF('2. Master Opportunity List'!$AG$4:$AG$60,"Same Day")+COUNTIF('2. Master Opportunity List'!$AG$4:$AG$60,"1-3 Days")+COUNTIF('2. Master Opportunity List'!$AG$4:$AG$60,"4-7 Days") | J13: =COUNTIF('2. Master Opportunity List'!$AB$4:$AB$60,"N") | P13: Checkout Completion | Q13: =COUNTIF('2. Master Opportunity List'!$E$4:$E$60,"Checkout Completion")
A14: Total ideas | D14: High-impact (RevImpact>=4) | G14: Launchable <=7 days | J14: Require NO discount | P14: Revenue from existing traffic | Q14: =COUNTIF('2. Master Opportunity List'!$E$4:$E$60,"Revenue from existing traffic")
P15: Contribution margin | Q15: =COUNTIF('2. Master Opportunity List'!$E$4:$E$60,"Contribution margin")
A16: =COUNTIF('2. Master Opportunity List'!$E$4:$E$60,"AOV") | D16: =COUNTIF('2. Master Opportunity List'!$E$4:$E$60,"CVR") | G16: =COUNTIF('2. Master Opportunity List'!$E$4:$E$60,"Frequency")+COUNTIF('2. Master Opportunity List'!$E$4:$E$60,"Revenue from CRM audiences") | J16: =COUNTIF('2. Master Opportunity List'!$E$4:$E$60,"Cross-category Purchase")+COUNTIF('2. Master Opportunity List'!$E$4:$E$60,"Category Penetration")
A17: AOV-focused | D17: CVR-focused | G17: Retention/CRM-focused | J17: Cross-sell / category
P18: Ideas by Time to Launch
P19: Same Day | Q19: =COUNTIF('2. Master Opportunity List'!$AG$4:$AG$60,"Same Day")
P20: 1-3 Days | Q20: =COUNTIF('2. Master Opportunity List'!$AG$4:$AG$60,"1-3 Days")
A21: TOP 10 REVENUE OPPORTUNITIES (live-linked to Master list, ranked by Priority) | P21: 4-7 Days | Q21: =COUNTIF('2. Master Opportunity List'!$AG$4:$AG$60,"4-7 Days")
A22: Rank | B22: Initiative | C22: Category | D22: Segment | E22: Revenue Lever | F22: Impact | G22: Confidence(1-5) | H22: Effort | I22: Time to Launch | J22: Margin | K22: Priority(/100) | P22: 8-14 Days | Q22: =COUNTIF('2. Master Opportunity List'!$AG$4:$AG$60,"8-14 Days")
A23: 1 | B23: ='2. Master Opportunity List'!C4 | C23: ='2. Master Opportunity List'!J4 | D23: ='2. Master Opportunity List'!I4 | E23: ='2. Master Opportunity List'!E4 | F23: ='2. Master Opportunity List'!Z4 | G23: ='2. Master Opportunity List'!AI4 | H23: ='2. Master Opportunity List'!AF4 | I23: ='2. Master Opportunity List'!AG4 | J23: ='2. Master Opportunity List'!AA4 | K23: ='2. Master Opportunity List'!AM4 | P23: 15-30 Days | Q23: =COUNTIF('2. Master Opportunity List'!$AG$4:$AG$60,"15-30 Days")
A24: 2 | B24: ='2. Master Opportunity List'!C5 | C24: ='2. Master Opportunity List'!J5 | D24: ='2. Master Opportunity List'!I5 | E24: ='2. Master Opportunity List'!E5 | F24: ='2. Master Opportunity List'!Z5 | G24: ='2. Master Opportunity List'!AI5 | H24: ='2. Master Opportunity List'!AF5 | I24: ='2. Master Opportunity List'!AG5 | J24: ='2. Master Opportunity List'!AA5 | K24: ='2. Master Opportunity List'!AM5
A25: 3 | B25: ='2. Master Opportunity List'!C6 | C25: ='2. Master Opportunity List'!J6 | D25: ='2. Master Opportunity List'!I6 | E25: ='2. Master Opportunity List'!E6 | F25: ='2. Master Opportunity List'!Z6 | G25: ='2. Master Opportunity List'!AI6 | H25: ='2. Master Opportunity List'!AF6 | I25: ='2. Master Opportunity List'!AG6 | J25: ='2. Master Opportunity List'!AA6 | K25: ='2. Master Opportunity List'!AM6
A26: 4 | B26: ='2. Master Opportunity List'!C7 | C26: ='2. Master Opportunity List'!J7 | D26: ='2. Master Opportunity List'!I7 | E26: ='2. Master Opportunity List'!E7 | F26: ='2. Master Opportunity List'!Z7 | G26: ='2. Master Opportunity List'!AI7 | H26: ='2. Master Opportunity List'!AF7 | I26: ='2. Master Opportunity List'!AG7 | J26: ='2. Master Opportunity List'!AA7 | K26: ='2. Master Opportunity List'!AM7 | P26: Ideas by Category
A27: 5 | B27: ='2. Master Opportunity List'!C8 | C27: ='2. Master Opportunity List'!J8 | D27: ='2. Master Opportunity List'!I8 | E27: ='2. Master Opportunity List'!E8 | F27: ='2. Master Opportunity List'!Z8 | G27: ='2. Master Opportunity List'!AI8 | H27: ='2. Master Opportunity List'!AF8 | I27: ='2. Master Opportunity List'!AG8 | J27: ='2. Master Opportunity List'!AA8 | K27: ='2. Master Opportunity List'!AM8 | P27: Apple Watch Bands | Q27: =COUNTIF('2. Master Opportunity List'!$J$4:$J$60,"Apple Watch Bands")
A28: 6 | B28: ='2. Master Opportunity List'!C9 | C28: ='2. Master Opportunity List'!J9 | D28: ='2. Master Opportunity List'!I9 | E28: ='2. Master Opportunity List'!E9 | F28: ='2. Master Opportunity List'!Z9 | G28: ='2. Master Opportunity List'!AI9 | H28: ='2. Master Opportunity List'!AF9 | I28: ='2. Master Opportunity List'!AG9 | J28: ='2. Master Opportunity List'!AA9 | K28: ='2. Master Opportunity List'!AM9 | P28: Backpacks | Q28: =COUNTIF('2. Master Opportunity List'!$J$4:$J$60,"Backpacks")
A29: 7 | B29: ='2. Master Opportunity List'!C10 | C29: ='2. Master Opportunity List'!J10 | D29: ='2. Master Opportunity List'!I10 | E29: ='2. Master Opportunity List'!E10 | F29: ='2. Master Opportunity List'!Z10 | G29: ='2. Master Opportunity List'!AI10 | H29: ='2. Master Opportunity List'!AF10 | I29: ='2. Master Opportunity List'!AG10 | J29: ='2. Master Opportunity List'!AA10 | K29: ='2. Master Opportunity List'!AM10 | P29: Cross-category | Q29: =COUNTIF('2. Master Opportunity List'!$J$4:$J$60,"Cross-category")
A30: 8 | B30: ='2. Master Opportunity List'!C11 | C30: ='2. Master Opportunity List'!J11 | D30: ='2. Master Opportunity List'!I11 | E30: ='2. Master Opportunity List'!E11 | F30: ='2. Master Opportunity List'!Z11 | G30: ='2. Master Opportunity List'!AI11 | H30: ='2. Master Opportunity List'!AF11 | I30: ='2. Master Opportunity List'!AG11 | J30: ='2. Master Opportunity List'!AA11 | K30: ='2. Master Opportunity List'!AM11 | P30: Desk Organisers | Q30: =COUNTIF('2. Master Opportunity List'!$J$4:$J$60,"Desk Organisers")
A31: 9 | B31: ='2. Master Opportunity List'!C12 | C31: ='2. Master Opportunity List'!J12 | D31: ='2. Master Opportunity List'!I12 | E31: ='2. Master Opportunity List'!E12 | F31: ='2. Master Opportunity List'!Z12 | G31: ='2. Master Opportunity List'!AI12 | H31: ='2. Master Opportunity List'!AF12 | I31: ='2. Master Opportunity List'!AG12 | J31: ='2. Master Opportunity List'!AA12 | K31: ='2. Master Opportunity List'!AM12 | P31: Gifting | Q31: =COUNTIF('2. Master Opportunity List'!$J$4:$J$60,"Gifting")
A32: 10 | B32: ='2. Master Opportunity List'!C13 | C32: ='2. Master Opportunity List'!J13 | D32: ='2. Master Opportunity List'!I13 | E32: ='2. Master Opportunity List'!E13 | F32: ='2. Master Opportunity List'!Z13 | G32: ='2. Master Opportunity List'!AI13 | H32: ='2. Master Opportunity List'!AF13 | I32: ='2. Master Opportunity List'!AG13 | J32: ='2. Master Opportunity List'!AA13 | K32: ='2. Master Opportunity List'!AM13 | P32: Impulse tech | Q32: =COUNTIF('2. Master Opportunity List'!$J$4:$J$60,"Impulse tech")
P33: Phone Cases | Q33: =COUNTIF('2. Master Opportunity List'!$J$4:$J$60,"Phone Cases")
P34: Power Banks | Q34: =COUNTIF('2. Master Opportunity List'!$J$4:$J$60,"Power Banks")
P35: Tech Organisers | Q35: =COUNTIF('2. Master Opportunity List'!$J$4:$J$60,"Tech Organisers")
P36: Wallets | Q36: =COUNTIF('2. Master Opportunity List'!$J$4:$J$60,"Wallets")

Sheet 2. Master Opportunity List
A1: MASTER REVENUE OPPORTUNITY LIST
A2: Every idea = one row. Filterable. Priority = RevImpact x Confidence x Ease x Speed x MarginFriendly, normalised /100. Evidence source: GA4 'DO - GA4' (273672074), via Windsor.ai, pulled 2026-08-10
A3: Idea ID | B3: Rank | C3: Initiative Name | D3: Detailed Mechanic | E3: Revenue Lever | F3: Primary KPI | G3: Secondary KPI | H3: Target Customer | I3: Cohort | J3: Category | K3: Subcategory | L3: Specific SKU(s) | M3: Trigger | N3: Offer / Proposition | O3: Website Placement | P3: Channel | Q3: Journey Stage | R3: External Brand Example | S3: Benchmark Mechanic | T3: Source URL | U3: DailyObjects Evidence (OBS/INF/HYP) | V3: Why It Should Work | W3: Expected Behaviour Change | X3: Exp. CVR Impact | Y3: Exp. AOV Impact | Z3: Exp. Revenue Impact | AA3: Exp. Margin Impact | AB3: Discount? | AC3: Est. Disc % | AD3: Gift? | AE3: Technology Dependency | AF3: Implementation Effort | AG3: Time to Launch | AH3: Rev Impact (1-5) | AI3: Confidence (1-5) | AJ3: Ease (1-5) | AK3: Speed (1-5) | AL3: Margin-Friendly (1-5) | AM3: Priority (/100) | AN3: Recommended Test | AO3: Success Metric | AP3: Guardrail Metric | AQ3: Owner | AR3: Status | AS3: Notes
A4: ID01 | B4: 1 | C4: Phone Case Attach Engine (screen guard + charm + strap) | D4: On every phone-case PDP + cart, show a 'Complete your case' rail: matching tempered-glass screen guard, MagSafe charm/grip and lanyard at 30-50% off ONLY when added with the case. Auto-apply in cart. | E4: AOV | F4: Units per Transaction | G4: AOV | H4: All case buyers | I4: New & Repeat | J4: Phone Cases | K4: Screen guards / grips / straps | L4: 1101,1103,1815,1812 | M4: View/ATC of any phone case | N4: 30-50% off attach items with a case | O4: PDP below CTA + Cart FBT rail | P4: Website/App | Q4: Consideration/Cart | R4: Casetify (up to 50% off accy with case); dbrand Grip+Prism; Nomad 15% off 2 | S4: Accessory-attach discount on hero product | T4: couponfollow.com/site/casetify.com | U4: OBS: Phone cases = 31.1M item views (57% of all views) but ASP only ~Rs1,068 & view->purchase 1.2%; screen guards(1815)/grips(1812) already sell at high ATC rates. Massive under-monetised traffic. | V4: The case is the wedge; a discounted, compatible attach is the single most proven case-AOV lever across every accessory peer. | W4: Case-only buyers add 1-2 low-cost high-margin accessories. | X4: Neutral | Y4: +8-15% | Z4: High | AA4: Accretive (accy high margin even at 40% off) | AB4: Y | AC4: 0.4 | AD4: N | AE4: Merch rule / FBT widget | AF4: Easy | AG4: 4-7 Days | AH4: 5 | AI4: 5 | AJ4: 4 | AK4: 4 | AL4: 4 | AM4: =ROUND(AH4*AI4*AJ4*AK4*AL4/3125*100,1) | AN4: A/B PDP+cart attach rail vs control on iPhone case PDPs | AO4: +Rs AOV & UPT on case orders | AP4: Case CVR, return rate | AQ4: Unassigned | AR4: Backlog
A5: ID19 | B5: 2 | C5: Cart & checkout abandonment flow (email+SMS+push) | D5: 3-step abandonment series: 30min reminder, 24h with social proof, 48h with a modest incentive/free-ship reminder. Trigger separately for ATC-abandon vs checkout-abandon. | E5: CVR | F5: Revenue from CRM audiences | G5: Checkout Completion | H5: Abandoners | I5: High-intent non-purchasers | J5: Cross-category | K5: Abandonment | L5: all | M5: ATC/checkout without purchase | N5: Reminder; light incentive on step 3 | O5: Email/SMS/Push | P5: CRM | Q5: Recovery | R5: Standard Klaviyo flows; boAt/Mamaearth CRM | T5: internal best practice | U5: OBS: 5.99M add-to-cart vs 623k purchase; begin_checkout 1.55M -> purchase 623k. Email+SMS+Push together only ~0.55% of revenue (Rs7.35M) - flows are under-built. | V5: Recovering even a small % of the 1.5M checkout-abandoners is large; owned channels are near-free and currently dormant. | W5: Returns to complete purchase. | X5: + | Y5: Neutral | Z5: High | AA5: Accretive | AB5: Y | AC5: 0.05 | AD5: N | AE5: CRM/ESP flows + events | AF5: Easy | AG5: 4-7 Days | AH5: 5 | AI5: 5 | AJ5: 4 | AK5: 4 | AL5: 4 | AM5: =ROUND(AH5*AI5*AJ5*AK5*AL5/3125*100,1) | AN5: Flow on vs holdout | AO5: Recovered revenue per abandoner | AP5: Unsub rate, discount leakage | AQ5: Unassigned | AR5: Backlog
A6: ID05 | B6: 3 | C6: Cart low-price add-on rail (impulse SKUs) | D6: In cart, show a horizontal 'Add for a little more' rail of high-margin impulse SKUs <Rs499 (cable binds, screen guards, grips, coasters, charms) one-tap add. | E6: AOV | F6: Units per Transaction | G6: AOV | H6: All carts | I6: New & Repeat | J6: Impulse tech | K6: Cables/grips/guards/charms | L6: 1811,1812,1815,1705 | M6: Cart view | N6: No discount - convenience placement | O6: Cart add-on rail | P6: Website/App | Q6: Cart | R6: Amazon-style add-ons; Nykaa mini rail | T6: internal best practice | U6: OBS: Wrap-Lock cable bind is a top-review bestseller; grips(1812)/screen guards(1815) show very high ATC-to-view. Cheap, high-margin impulse inventory exists. | V6: Frictionless one-tap add of a cheap complement is pure incremental margin with zero discount. | W6: Adds a sub-Rs499 impulse item. | X6: Neutral | Y6: +3-6% | Z6: Med | AA6: Accretive (no discount) | AB6: N | AC6: 0 | AD6: N | AE6: Cart widget | AF6: Very Easy | AG6: 4-7 Days | AH6: 3 | AI6: 4 | AJ6: 5 | AK6: 5 | AL6: 5 | AM6: =ROUND(AH6*AI6*AJ6*AK6*AL6/3125*100,1) | AN6: Add-on rail vs control | AO6: Attach rate of add-on SKUs | AP6: Cart abandonment | AQ6: Unassigned | AR6: Backlog
A7: ID27 | B7: 4 | C7: Bestseller & high-margin SKU prioritisation on PLP/home | D7: Re-sort PLPs and homepage rails to lead with proven high-CVR, high-margin bestsellers (Wrap-Lock cable, Orbis sling, Valet tray, Loop power banks, top case models); pin 'Bestseller' badges. | E7: CVR | F7: Conversion Rate | G7: Revenue per Visitor | H7: All browsers | I7: New & Repeat | J7: Cross-category | K7: Merch sort | L7: bestsellers | M7: PLP/home view | N7: None | O7: PLP sort + homepage | P7: Website/App | Q7: Discovery | R7: Merch best practice; DO's own SKU-cull->sales lift | T7: d2cx.co | U7: OBS: DO grew by cutting 72->35 SKUs to focus on bestsellers (Rs50L->Rs2Cr/mo). Homepage CVR 1.54% vs /collection 0.33% - sorting matters. | V7: Leading with proven winners raises blended CVR and margin without new traffic. | W7: Sees winners first; converts faster. | X7: + | Y7: Slight + | Z7: Med | AA7: Accretive | AB7: N | AC7: 0 | AD7: N | AE7: Merch sort rules | AF7: Very Easy | AG7: Same Day | AH7: 3 | AI7: 4 | AJ7: 5 | AK7: 5 | AL7: 5 | AM7: =ROUND(AH7*AI7*AJ7*AK7*AL7/3125*100,1) | AN7: Bestseller-first sort vs default | AO7: PLP CVR, RPV | AP7: Long-tail exposure | AQ7: Unassigned | AR7: Backlog
A8: ID07 | B8: 5 | C8: Prepaid free-shipping + Rs79 COD-fee reframing | D8: Make free shipping explicit and prepaid-gated with a visible bar ('You're Rs X from free shipping - pay online'); show the Rs79 COD fee as a saveable line at checkout with a one-tap 'Switch to UPI & save Rs79 + free ship'. | E8: CVR | F8: Checkout Completion | G8: Contribution margin | H8: COD-inclined shoppers | I8: New | J8: Cross-category | K8: Shipping/payment | L8: all | M8: Checkout w/ COD selected | N8: Free ship + waive COD fee on prepaid | O8: Cart + Checkout | P8: Website/App | Q8: Checkout | R8: boAt/Zouk/Mamaearth prepaid incentives; Souled Store Rs499 free-ship | T8: grabon.in/mamaearth | U8: OBS: add_payment_info->purchase only 58% (large payment-stage drop); India COD RTO is a known margin leak. INF: existing free-ship thresholds reported inconsistently (Rs749 vs Rs1,199) - reframe clearly. | V8: Shifting COD->prepaid cuts RTO cost and lifts contribution margin more than the shipping given away; clarity reduces checkout abandonment. | W8: Chooses prepaid; completes checkout. | X8: + | Y8: Neutral | Z8: High | AA8: Accretive (RTO saved) | AB8: N | AC8: 0 | AD8: N | AE8: Checkout config | AF8: Easy | AG8: 4-7 Days | AH8: 4 | AI8: 4 | AJ8: 4 | AK8: 4 | AL8: 5 | AM8: =ROUND(AH8*AI8*AJ8*AK8*AL8/3125*100,1) | AN8: Prepaid nudge + COD-fee reframing at checkout | AO8: Prepaid share, checkout completion | AP8: Overall CVR | AQ8: Unassigned | AR8: Backlog
A9: ID02 | B9: 6 | C9: Power Bank + MagSafe Case cross-sell bundle | D9: On Loop Qi2 power-bank PDPs, add 'Powers up perfectly with' a MagSafe case at bundle price = power bank + case -10%. Reverse: on MagSafe case PDPs surface Loop power bank. | E9: AOV | F9: Cross-category Purchase | G9: AOV | H9: Power-bank & MagSafe shoppers | I9: New & Repeat | J9: Power Banks | K9: MagSafe cases | L9: 1809,1103 | M9: View Loop Qi2 PDP | N9: Bundle -10% vs buying separately | O9: PDP FBT + Cart | P9: Website/App | Q9: Consideration | R9: Anker charger+cable combo; Peak Design ecosystem | T9: anker.com/collections/bundles | U9: OBS: Power banks = highest revenue category (Rs397M, ASP Rs3,108); MagSafe cases 42k units. Both MagSafe-ecosystem; natural attach. Loop 10000mAh PDP alone did Rs10.1M. | V9: Qi2/MagSafe interoperability is a real functional reason to pair; premium buyers are least price-sensitive. | W9: Power-bank buyers add a MagSafe case (and vice-versa). | X9: Neutral | Y9: +10-18% | Z9: High | AA9: Neutral | AB9: Y | AC9: 0.1 | AD9: N | AE9: FBT widget | AF9: Easy | AG9: 4-7 Days | AH9: 4 | AI9: 4 | AJ9: 4 | AK9: 4 | AL9: 4 | AM9: =ROUND(AH9*AI9*AJ9*AK9*AL9/3125*100,1) | AN9: Bundle module on Loop PDPs | AO9: Attach rate power bank<->case | AP9: Power bank CVR | AQ9: Unassigned | AR9: Backlog
A10: ID04 | B10: 7 | C10: Watch-band multi-pack ('Band Wardrobe') | D10: On Apple Watch band PDPs offer buy-2-save-15% / buy-3-save-20% across bands (mix leather/sport/nylon). 'Build your band wardrobe' selector. | E10: AOV | F10: Units per Transaction | G10: AOV | H10: Watch-band shoppers | I10: New & Repeat | J10: Apple Watch Bands | K10: Bands | L10: 1801 | M10: View watch-band PDP/PLP | N10: Buy 2 -15%, 3+ -20% | O10: PDP selector + PLP banner | P10: Website/App | Q10: Consideration | R10: Casetify escalator 15/20/30; Noise FEST15/20 | T10: simplycodes.com/store/casetify.com | U10: OBS: Watch bands 107k units, ASP Rs1,108, Rs118.8M - a fashion-rotation SKU bought in multiples elsewhere. Ecosystem/repeat role. | V10: Bands are a wardrobe item (match outfit/occasion); multi-buy escalators convert single-band intent into 2-3. | W10: Single-band buyers add a 2nd/3rd band. | X10: Neutral | Y10: +12-20% | Z10: Med-High | AA10: Accretive | AB10: Y | AC10: 0.17 | AD10: N | AE10: Qty-tier promo | AF10: Easy | AG10: 4-7 Days | AH10: 4 | AI10: 4 | AJ10: 4 | AK10: 4 | AL10: 4 | AM10: =ROUND(AH10*AI10*AJ10*AK10*AL10/3125*100,1) | AN10: Multi-band escalator on band PDPs | AO10: UPT on band orders | AP10: Band margin | AQ10: Unassigned | AR10: Backlog
A11: ID51 | B11: 8 | C11: Reviews & UGC amplification on high-traffic PDPs | D11: Surface photo reviews, review count and Q&A prominently on top PDPs; seed Q&A for compatibility questions (fits which phone) to cut pre-purchase doubt. | E11: CVR | F11: Conversion Rate | G11: New User Conversion | H11: PDP visitors | I11: New | J11: Cross-category | K11: Social proof | L11: top PDPs | M11: PDP view | N11: None | O11: PDP | P11: Website/App | Q11: Consideration | R11: Review-led PDPs; DO VoC (80k+ reviews) | T11: internal VoC deck (80,303 reviews / 11,771 SKUs) | U11: OBS: DO has 80,303 reviews across 11,771 SKUs (VoC deck) - a huge, under-surfaced trust asset; PDPs already show ratings. | V11: Photo reviews + compatibility Q&A directly reduce the doubts that stall accessory purchases. | W11: Trusts and converts. | X11: + | Y11: Neutral | Z11: Med | AA11: Accretive | AB11: N | AC11: 0 | AD11: N | AE11: Reviews widget | AF11: Easy | AG11: 4-7 Days | AH11: 3 | AI11: 4 | AJ11: 4 | AK11: 4 | AL11: 5 | AM11: =ROUND(AH11*AI11*AJ11*AK11*AL11/3125*100,1) | AN11: Enhanced reviews vs control | AO11: PDP CVR | AP11: Review authenticity | AQ11: Unassigned | AR11: Backlog
A12: ID53 | B12: 9 | C12: Prepaid-only deeper offer to convert COD share | D12: Offer the best price/gift ONLY on prepaid (COD gets base price); reframe as 'prepaid perks' not a COD penalty. Protects margin via RTO reduction. | E12: Contribution margin | F12: Contribution margin | G12: Checkout Completion | H12: COD-preferring | I12: New | J12: Cross-category | K12: Prepaid gating | L12: all | M12: Payment selection | N12: Prepaid-only extra 5% / gift | O12: Checkout | P12: Website/App | Q12: Checkout | R12: WOW 'buy 3 pay 2' prepaid-only; boAt prepaid | T12: picodi.com/in/wow-skin-science | U12: OBS: payment-stage drop + India RTO economics; prepaid gating is standard and margin-accretive. | V12: Shifting COD->prepaid saves RTO/logistics cost that exceeds the incentive - net margin gain. | W12: Chooses prepaid. | X12: Neutral/+ | Y12: Neutral | Z12: Med | AA12: Accretive | AB12: Y | AC12: 0.05 | AD12: N | AE12: Checkout rules | AF12: Easy | AG12: 4-7 Days | AH12: 3 | AI12: 4 | AJ12: 4 | AK12: 4 | AL12: 5 | AM12: =ROUND(AH12*AI12*AJ12*AK12*AL12/3125*100,1) | AN12: Prepaid-only offer vs universal | AO12: Prepaid share, contribution/order | AP12: Overall CVR | AQ12: Unassigned | AR12: Backlog
A13: ID12 | B13: 10 | C13: Express/1-tap payment (UPI intent, wallets, tokenised cards) | D13: Add UPI-intent one-tap, popular wallets, saved/tokenised cards and a prominent 'Pay by UPI' default; add payment-failure retry with auto-fallback + 'complete your payment' recovery link. | E13: CVR | F13: Checkout Completion | G13: Revenue per Visitor | H13: All checkout | I13: New & Repeat | J13: Cross-category | K13: Payments | L13: all | M13: add_payment_info reached | N13: None | O13: Payment page | P13: Website/App | Q13: Payment | R13: boAt/Boult UPI cashback; standard India PSP stack | T13: grabon.in/boat-coupons | U13: OBS: add_payment_info=1.07M but purchase=623k -> 42% drop AFTER entering payment. /payment-processing route shows real fallout. Payment friction/failure is a top leak. | V13: A large share of the payment-stage drop is failed/abandoned payment, directly recoverable with better methods + retry. | W13: Completes payment; recovers failed attempts. | X13: ++ | Y13: Neutral | Z13: Very High | AA13: Accretive | AB13: N | AC13: 0 | AD13: N | AE13: PSP integration + retry flow | AF13: Moderate | AG13: 8-14 Days | AH13: 5 | AI13: 4 | AJ13: 3 | AK13: 3 | AL13: 5 | AM13: =ROUND(AH13*AI13*AJ13*AK13*AL13/3125*100,1) | AN13: New payment stack vs control; payment success rate | AO13: Payment success %, checkout completion | AP13: Fraud, chargebacks | AQ13: Unassigned | AR13: Backlog
A14: ID18 | B14: 11 | C14: Second-order accelerator coupon on thank-you + email | D14: Give every first-time buyer a time-boxed next-order incentive (e.g. Rs200 off next order within 30 days, min Rs1,499) on the thank-you page and in the order-confirmation email/SMS. | E14: Frequency | F14: Repeat Purchase | G14: O1->O2 rate | H14: First-order buyers | I14: O1 | J14: Cross-category | K14: Repeat incentive | L14: all | M14: First purchase | N14: Rs200 off next order in 30 days (min Rs1,499) | O14: Thank-you + email/SMS | P14: CRM | Q14: Post-purchase | R14: Gymshark loyalty; Sugar points; standard O1->O2 | T14: gymshark.com/pages/loyalty-free-next-day | U14: OBS: Returning users convert 2.56x new (1.77% vs 0.69%) & higher AOV (Rs2,573) - accelerating O1->O2 compounds. Repeat rate reported ~47%. | V14: The O1->O2 jump is the highest-leverage retention moment; a bounded incentive pulls the second order forward. | W14: Places a 2nd order sooner. | X14: Neutral | Y14: Neutral | Z14: High | AA14: Dilutive (control redemption) | AB14: Y | AC14: 0.13 | AD14: N | AE14: Coupon + CRM flow | AF14: Easy | AG14: 4-7 Days | AH14: 4 | AI14: 4 | AJ14: 4 | AK14: 4 | AL14: 3 | AM14: =ROUND(AH14*AI14*AJ14*AK14*AL14/3125*100,1) | AN14: O1 cohort with vs without coupon | AO14: 30/60-day repeat rate | AP14: Margin, redemption cannibalisation | AQ14: Unassigned | AR14: Backlog
A15: ID28 | B15: 12 | C15: First-order offer clarity + email/phone capture popup | D15: Tighten the welcome popup: 'Get Rs300 off your first order over Rs2,299 - unlock now' with email+phone capture, then persist the code in a sticky bar. Route to a first-time-buyer LP. | E15: New User Conversion | F15: New User Conversion | G15: Revenue from CRM audiences | H15: New visitors | I15: New | J15: Cross-category | K15: First-order + capture | L15: all | M15: First visit / exit intent | N15: WELCOME300 (Rs300 off > Rs2,299) | O15: Popup + sticky bar + LP | P15: Website/App/CRM | Q15: Acquisition | R15: Sugar 500pts signup; Mamaearth; standard welcome | T15: sugarcosmetics.com/pages/faqs | U15: OBS: WELCOME300 already exists but new CVR is only 0.69%; capture feeds the dormant CRM base. INF: popup value/persistence likely weak. | V15: First-order clarity + capture both lifts new CVR and builds the owned audience that CRM ideas monetise. | W15: Signs up; completes first order. | X15: + | Y15: Neutral (threshold Rs2,299) | Z15: Med-High | AA15: Neutral | AB15: Y | AC15: 0.13 | AD15: N | AE15: Popup + CRM | AF15: Easy | AG15: 4-7 Days | AH15: 4 | AI15: 4 | AJ15: 4 | AK15: 4 | AL15: 3 | AM15: =ROUND(AH15*AI15*AJ15*AK15*AL15/3125*100,1) | AN15: New popup vs current | AO15: Capture rate, new-user CVR | AP15: Discount on would-buy-anyway | AQ15: Unassigned | AR15: Backlog
A16: ID39 | B16: 13 | C16: Return/exchange-friendly messaging to unlock high-consideration bags | D16: Add prominent easy-returns + warranty + '30-day trial' style reassurance on backpack/luggage/premium-bag PDPs; show real reviews & durability proof. | E16: CVR | F16: Conversion Rate | G16: Category Penetration | H16: Bag shoppers | I16: New | J16: Backpacks | K16: Risk reversal | L16: 1201,1202 | M16: Bag PDP | N16: Trial/returns reassurance | O16: Bag PDPs | P16: Website/App | Q16: Consideration | R16: Mokobara 30-day trial + warranty | T16: grabon.in/mokobara | U16: OBS: Backpacks view->purchase 0.77% & ATC rate 3.7% (lowest of big cats) - classic high-consideration hesitation on a Rs1,900+ ASP item. | V16: Premium bag hesitation is about risk; explicit reversal is Mokobara's proven unlock. | W16: Commits to a considered bag purchase. | X16: + | Y16: Neutral | Z16: Med | AA16: Neutral (returns cost) | AB16: N | AC16: 0 | AD16: N | AE16: PDP content + returns policy | AF16: Easy | AG16: 4-7 Days | AH16: 3 | AI16: 4 | AJ16: 4 | AK16: 4 | AL16: 4 | AM16: =ROUND(AH16*AI16*AJ16*AK16*AL16/3125*100,1) | AN16: Risk-reversal messaging vs control on bag PDPs | AO16: Bag CVR | AP16: Return rate | AQ16: Unassigned | AR16: Backlog
... A60: ID40 | B60: 57 | C60: Paid low-cost membership ('DO Club') | D60: Test a Rs299/6-month membership: free shipping no-min + extra 5% + early access to drops + birthday gift. Pitch at checkout to repeat buyers. | E60: Frequency | F60: Repeat Purchase | G60: AOV | H60: Repeat buyers | I60: O2/O3+ | J60: Cross-category | K60: Membership | L60: all | M60: Checkout / account | N60: Rs299/6mo perks | O60: Checkout + account | P60: Website/App | Q60: Retention | R60: Mokobara Moko Club Rs499; Bewakoof TriBe Rs99 | T60: grabon.in/mokobara | U60: INF: repeat cohort = 57% of revenue; a paid membership converts free-shipping into a retention loop & prepaid float. | V60: Sunk-cost membership drives frequency and locks in the most valuable cohort. | W60: Joins; buys more often. | X60: Neutral | Y60: + | Z60: Med | AA60: Neutral | AB60: Y | AC60: 0.05 | AD60: N | AE60: Membership module | AF60: Hard | AG60: 15-30 Days | AH60: 3 | AI60: 2 | AJ60: 2 | AK60: 2 | AL60: 3 | AM60: =ROUND(AH60*AI60*AJ60*AK60*AL60/3125*100,1) | AN60: Membership pilot to repeat cohort | AO60: Member repeat rate, LTV | AP60: Margin, free-ship cost | AQ60: Unassigned | AR60: Backlog

Sheet 3. Launch This Week
A1: LAUNCH THIS WEEK -> hand directly to the revenue team
A2: The 15 highest-priority interventions that can realistically go live within 7 days. Tactical & specific.
A3: Rank | B3: Initiative | C3: Exact Action | D3: Target Segment | E3: Category / SKU | F3: Offer / Mechanic | G3: Placement | H3: Required Assets | I3: Required Tech | J3: Owner | K3: Time to Launch | L3: Exp. Revenue Impact | M3: Margin Risk | N3: Measurement Plan | O3: Go / Test / Hold
A4: 1 | B4: Phone Case Attach Engine (screen guard + charm + strap) | C4: On every phone-case PDP + cart, show a 'Complete your case' rail: matching tempered-glass screen guard, MagSafe charm/grip and lanyard at 30-50% off ONLY when added with the case. Auto-apply in cart. | D4: All case buyers | E4: Phone Cases / 1101,1103,1815,1812 | F4: 30-50% off attach items with a case | G4: PDP below CTA + Cart FBT rail | H4: Copy + creative + PDP/cart slots | I4: Merch rule / FBT widget | J4: Unassigned | K4: 4-7 Days | L4: High | M4: Low | N4: +Rs AOV & UPT on case orders | O4: Go
A5: 2 | B5: Cart & checkout abandonment flow (email+SMS+push) | C5: 3-step abandonment series: 30min reminder, 24h with social proof, 48h with a modest incentive/free-ship reminder. Trigger separately for ATC-abandon vs checkout-abandon. | D5: Abandoners | E5: Cross-category / all | F5: Reminder; light incentive on step 3 | G5: Email/SMS/Push | H5: Copy + creative + PDP/cart slots | I5: CRM/ESP flows + events | J5: Unassigned | K5: 4-7 Days | L5: High | M5: Low | N5: Recovered revenue per abandoner | O5: Go
A6: 3 | B6: Cart low-price add-on rail (impulse SKUs) | C6: In cart, show a horizontal 'Add for a little more' rail of high-margin impulse SKUs <Rs499 (cable binds, screen guards, grips, coasters, charms) one-tap add. | D6: All carts | E6: Impulse tech / 1811,1812,1815,1705 | F6: No discount - convenience placement | G6: Cart add-on rail | H6: Copy + creative + PDP/cart slots | I6: Cart widget | J6: Unassigned | K6: 4-7 Days | L6: Med | M6: Low | N6: Attach rate of add-on SKUs | O6: Go
A7: 4 | B7: Bestseller & high-margin SKU prioritisation on PLP/home | C7: Re-sort PLPs and homepage rails to lead with proven high-CVR, high-margin bestsellers (Wrap-Lock cable, Orbis sling, Valet tray, Loop power banks, top case models); pin 'Bestseller' badges. | D7: All browsers | E7: Cross-category / bestsellers | F7: None | G7: PLP sort + homepage | H7: Copy + creative + PDP/cart slots | I7: Merch sort rules | J7: Unassigned | K7: Same Day | L7: Med | M7: Low | N7: PLP CVR, RPV | O7: Go
A8: 5 | B8: Prepaid free-shipping + Rs79 COD-fee reframing | C8: Make free shipping explicit and prepaid-gated with a visible bar ('You're Rs X from free shipping - pay online'); show the Rs79 COD fee as a saveable line at checkout with a one-tap 'Switch to UPI & save Rs79 + free ship'. | D8: COD-inclined shoppers | E8: Cross-category / all | F8: Free ship + waive COD fee on prepaid | G8: Cart + Checkout | H8: Copy + creative + PDP/cart slots | I8: Checkout config | J8: Unassigned | K8: 4-7 Days | L8: High | M8: Low | N8: Prepaid share, checkout completion | O8: Go
A9: 6 | B9: Power Bank + MagSafe Case cross-sell bundle | C9: On Loop Qi2 power-bank PDPs, add 'Powers up perfectly with' a MagSafe case at bundle price = power bank + case -10%. Reverse: on MagSafe case PDPs surface Loop power bank. | D9: Power-bank & MagSafe shoppers | E9: Power Banks / 1809,1103 | F9: Bundle -10% vs buying separately | G9: PDP FBT + Cart | H9: Copy + creative + PDP/cart slots | I9: FBT widget | J9: Unassigned | K9: 4-7 Days | L9: High | M9: Low | N9: Attach rate power bank<->case | O9: Go
A10: 7 | B10: Watch-band multi-pack ('Band Wardrobe') | C10: On Apple Watch band PDPs offer buy-2-save-15% / buy-3-save-20% across bands (mix leather/sport/nylon). 'Build your band wardrobe' selector. | D10: Watch-band shoppers | E10: Apple Watch Bands / 1801 | F10: Buy 2 -15%, 3+ -20% | G10: PDP selector + PLP banner | H10: Copy + creative + PDP/cart slots | I10: Qty-tier promo | J10: Unassigned | K10: 4-7 Days | L10: Med-High | M10: Low | N10: UPT on band orders | O10: Go
A11: 8 | B11: Reviews & UGC amplification on high-traffic PDPs | C11: Surface photo reviews, review count and Q&A prominently on top PDPs; seed Q&A for compatibility questions (fits which phone) to cut pre-purchase doubt. | D11: PDP visitors | E11: Cross-category / top PDPs | F11: None | G11: PDP | H11: Copy + creative + PDP/cart slots | I11: Reviews widget | J11: Unassigned | K11: 4-7 Days | L11: Med | M11: Low | N11: PDP CVR | O11: Go
A12: 9 | B12: Prepaid-only deeper offer to convert COD share | C12: Offer the best price/gift ONLY on prepaid (COD gets base price); reframe as 'prepaid perks' not a COD penalty. Protects margin via RTO reduction. | D12: COD-preferring | E12: Cross-category / all | F12: Prepaid-only extra 5% / gift | G12: Checkout | H12: Copy + creative + PDP/cart slots | I12: Checkout rules | J12: Unassigned | K12: 4-7 Days | L12: Med | M12: Low | N12: Prepaid share, contribution/order | O12: Go
A13: 10 | B13: Second-order accelerator coupon on thank-you + email | C13: Give every first-time buyer a time-boxed next-order incentive (e.g. Rs200 off next order within 30 days, min Rs1,499) on the thank-you page and in the order-confirmation email/SMS. | D13: First-order buyers | E13: Cross-category / all | F13: Rs200 off next order in 30 days (min Rs1,499) | G13: Thank-you + email/SMS | H13: Copy + creative + PDP/cart slots | I13: Coupon + CRM flow | J13: Unassigned | K13: 4-7 Days | L13: High | M13: Med | N13: 30/60-day repeat rate | O13: Test
A14: 11 | B14: First-order offer clarity + email/phone capture popup | C14: Tighten the welcome popup: 'Get Rs300 off your first order over Rs2,299 - unlock now' with email+phone capture, then persist the code in a sticky bar. Route to a first-time-buyer LP. | D14: New visitors | E14: Cross-category / all | F14: WELCOME300 (Rs300 off > Rs2,299) | G14: Popup + sticky bar + LP | H14: Copy + creative + PDP/cart slots | I14: Popup + CRM | J14: Unassigned | K14: 4-7 Days | L14: Med-High | M14: Med | N14: Capture rate, new-user CVR | O14: Test
A15: 12 | B15: Return/exchange-friendly messaging to unlock high-consideration bags | C15: Add prominent easy-returns + warranty + '30-day trial' style reassurance on backpack/luggage/premium-bag PDPs; show real reviews & durability proof. | D15: Bag shoppers | E15: Backpacks / 1201,1202 | F15: Trial/returns reassurance | G15: Bag PDPs | H15: Copy + creative + PDP/cart slots | I15: PDP content + returns policy | J15: Unassigned | K15: 4-7 Days | L15: Med | M15: Low | N15: Bag CVR | O15: Go
... A18: 15 | B18: Bank/UPI offer strip surfaced across funnel | C18: Surface live bank/UPI/cashback offers (HDFC SmartBuy, UPI cashback) as a strip on PDP/cart/checkout with 'view all offers' - reduce reliance on brand discounts. | D18: Deal-sensitive | E18: Cross-category / all | F18: Bank/UPI cashback (funded by partners) | G18: PDP/Cart/Checkout | H18: Copy + creative + PDP/cart slots | I18: Offers strip | J18: Unassigned | K18: 4-7 Days | L18: Med | M18: Low | N18: CVR, prepaid share | O18: Test

Sheet 4. D2C Brand Tactic DB
A1: D2C BRAND TACTIC DATABASE
A2: Real tactics from India & international D2C brands. Status = 'Reported' (search-index snippets; egress blocked live sites) - re-verify prices/thresholds before publishing.
A3: Brand | B3: Country | C3: Category | D3: Tactic Category | E3: Exact Mechanic | F3: Customer Proposition / Why It Works | G3: Objective (CVR/AOV/Freq) | H3: Applicability to DailyObjects | I3: DO Category | J3: Source URL | K3: Confidence | L3: Observed?
A4: boAt | B4: India | C4: Audio/Tech | D4: Payment (prepaid) | E4: Code BOATHEAD = flat extra 5% off ALL prepaid orders on top of sale | F4: Frames paying online as 'save more'; cuts RTO | G4: CVR+Margin | H4: Sitewide prepaid nudge; cases/power banks | I4: (map to DO) | J4: grabon.in/boat-coupons | K4: Med | L4: Reported
A5: boAt | B5: India | C5: Audio/Tech | D5: Payment (UPI) | E5: Flash extra 15% off on UPI + up to Rs150 cashback via PhonePe/GPay; stacks with bank offers | F5: Layered discounts feel like a treasure hunt; instant prepaid | G5: CVR | H5: Payday UPI cashback windows | I5: (map to DO) | J5: grabon.in/boat-coupons | K5: Med | L5: Reported
A6: boAt | B6: India | C6: Audio/Tech | D6: Launch anchoring | E6: New SKU launched at '55% off Rs19,999 RRP -> Rs8,999 for first customers' | F6: Introductory RRP anchor makes new SKU feel a steal | G6: CVR | H6: Loop/Surge launch pricing | I6: (map to DO) | J6: notebookcheck.net | K6: Med | L6: Reported
A7: boAt | B7: India | C7: Audio/Tech | D7: Gift-card discount | E7: E-gift card = instant flat 8% off | F7: Prepaid float + self-gifting locks spend | G7: Frequency | H7: Gift-card / prepaid credit | I7: (map to DO) | J7: gopaisa.com/boat | K7: Med | L7: Reported
A8: Noise | B8: India | C8: Wearables | D8: Bundle / cross-sell | E8: Smartwatch + TWS combo SKU at price below sum | F8: Two-device starter kit lifts basket in one click | G8: AOV | H8: Case + charger / band + charger combo | I8: (map to DO) | J8: gonoise.com | K8: Med | L8: Reported
A9: Noise | B9: India | C9: Wearables | D9: Multi-buy tier | E9: FEST15=15% off buy 2; FEST20=20% off buy 3+ | F9: Explicit ladder rewards adding a 3rd item | G9: AOV | H9: Buy-2/3 cases ladder | I9: (map to DO) | J9: gonoise.com | K9: Med | L9: Reported
A10: Noise | B10: India | C10: Wearables | D10: Free shipping | E10: Free shipping ALL orders, no minimum | F10: Removes friction on low-ticket | G10: CVR | H10: Prepaid free-ship framing | I10: (map to DO) | J10: gonoise.com | K10: Med | L10: Reported
A11: Boult | B11: India | C11: Audio | D11: Payment | E11: Rs100 instant cashback on prepaid; extra 5% UPI | F11: Cash incentive to prepay small ticket | G11: CVR | H11: Prepaid cashback | I11: (map to DO) | J11: grabon.in/boult-audio | K11: Med | L11: Reported
A12: Mokobara | B12: India | C12: Luggage/Bags | D12: Paid membership | E12: Moko Club Rs499/6mo = extra 5% off + 100-day trial + priority access | F12: Sunk-cost membership drives repeat on high ticket | G12: Frequency+AOV | H12: Paid membership for bags buyers | I12: (map to DO) | J12: grabon.in/mokobara | K12: Med | L12: Reported
A13: Mokobara | B13: India | C13: Luggage/Bags | D13: Risk reversal | E13: 30-day trial + 6-year warranty | F13: Kills 'is it worth it' objection on premium | G13: CVR | H13: Backpack/luggage trial + warranty | I13: (map to DO) | J13: grabon.in/mokobara | K13: Med | L13: Reported
A14: Mokobara | B14: India | C14: Luggage/Bags | D14: Set pricing | E14: Luggage 'sets' & travel combos at reduced set price | F14: Set aspiration + AOV | G14: AOV | H14: Bag + organiser + sleeve set | I14: (map to DO) | J14: mokobara.com/collections/explore-iconic-luggage | K14: Med | L14: Reported
... A54: Sugar/Nykaa | B54: India | C54: Beauty | D54: Sample/mini ladder | E54: Add mini/sample as low-price add-on near free-ship bar | F54: Cheap trial closes the gap + trials new lines | G54: AOV | H54: Low-price add-on rail in cart | I54: (map to DO) | J54: nykaa.com (observed pattern) | K54: Med | L54: Reported

Sheet 5. Category Opportunity Map
A1: CATEGORY OPPORTUNITY MAP
A2: GA4 item metrics = OBSERVED; cid->name mapping = INFERRED from site URL taxonomy. ASP is item-level (not order AOV). 2025-08-01 to 2026-07-31
A3: cid | B3: Category (INF name) | C3: Category Role | D3: Item Revenue (Rs) | E3: Units Sold | F3: Item ASP (Rs) | G3: Item Views | H3: ATC Rate | I3: View->Purchase | J3: Price Range | K3: Purchase Behaviour | L3: Primary Problem | M3: Primary Revenue Opportunity | N3: Best Offer Mechanic | O3: Best Bundle | P3: Best Cross-Sell | Q3: Best CRM Opportunity | R3: Best Merchandising | S3: Recommended Immediate Action | T3: Priority
A4: 1809 | B4: Power Banks & Wireless Power | C4: Hero / Destination | D4: 3.9724405e+08 | E4: 127803 | F4: =IF(E4=0,0,D4/E4) | G4: 9234794 | H4: =IF(G4=0,0,647279/G4) | I4: =IF(G4=0,0,E4/G4) | J4: Rs4,999-8,499 | K4: Considered, high ASP | L4: Hero revenue driver but low ATC (7%) | M4: Bundle with MagSafe case; cross-sell cable; launch attach | N4: Bundle -10% + launch kit | O4: Power bank + MagSafe case | P4: + Cable/adapter | Q4: Restock/price-drop alerts on Loop | R4: Lead homepage + device hub | S4: Ship power-bank+case bundle on Loop PDPs (ID02) | T4: High
A5: 1101 | B5: Phone Cases (core) | C5: Hero / Destination | D5: 3.290038e+08 | E5: 307976 | F5: =IF(E5=0,0,D5/E5) | G5: 25760937 | H5: =IF(G5=0,0,2408681/G5) | I5: =IF(G5=0,0,E5/G5) | J5: Rs899-2,399 | K5: Massive traffic, low ASP entry | L5: 57% of item views convert at 1.2% & ASP only ~Rs1,068 | M5: Attach screen guard/charm/grip; tier upsell; quiz | N5: Attach 30-50% off with case | O5: Case + screen guard + grip | P5: Screen guard | Q5: BIS on new phone models; replacement cycle | R5: Lead nav + shop-by-device | S5: Launch case attach engine + tier upsell (ID01/ID16) | T5: High
A6: 1801 | B6: Apple Watch Bands | C6: Ecosystem / Repeat | D6: 1.1879657e+08 | E6: 107273 | F6: =IF(E6=0,0,D6/E6) | G6: 7095030 | H6: =IF(G6=0,0,490322/G6) | I6: =IF(G6=0,0,E6/G6) | J6: Rs1,299-2,499 | K6: Fashion rotation, repeat | L6: Bought singly; multi-band potential untapped | M6: Multi-band buy-2/3 escalator | N6: Buy 2 -15% | O6: Band wardrobe | P6: Watch charger/stand | Q6: Seasonal band drops to owners | R6: Watch hub | S6: Multi-band escalator on band PDPs (ID04) | T6: High
A7: 1703 | B7: Tech / Cable Organisers | C7: Add-on / Cross-sell | D7: 93174478 | E7: 82770 | F7: =IF(E7=0,0,D7/E7) | G7: 4325738 | H7: =IF(G7=0,0,344260/G7) | I7: =IF(G7=0,0,E7/G7) | J7: Rs499-1,999 | K7: Strong attach category | L7: Under-attached to bags/power banks | M7: Attach to bag/power-bank; hero GWP | N7: Free GWP at mid rung | O7: Bag/power bank -> organiser | P7: Cables | Q7: Cross-cat intro to case buyers | R7: Attach rails everywhere | S7: Use as hero GWP + bag attach (ID03/ID46) | T7: High
A8: 1201 | B8: Backpacks | C8: High-consideration | D8: 77009769 | E8: 39702 | F8: =IF(E8=0,0,D8/E8) | G8: 5171423 | H8: =IF(G8=0,0,191289/G8) | I8: =IF(G8=0,0,E8/G8) | J8: Rs1,349-3,000+ | K8: High-consideration, hesitant | L8: Lowest view->purchase (0.77%) & ATC (3.7%) | M8: Risk reversal + carry-system bundle | N8: Kit -12% + trial/returns | O8: Bag + sleeve + organiser | P8: Laptop sleeve | Q8: Winback + wishlist for considered buyers | R8: Use-case hub (back-to-office/travel) | S8: Add risk-reversal + carry-system bundle (ID03/ID39) | T8: High
A9: 1702 | B9: Desk Organisers & Trays | C9: Add-on / Impulse | D9: 58528287 | E9: 44126 | F9: =IF(E9=0,0,D9/E9) | G9: 1716262 | H9: =IF(G9=0,0,158526/G9) | I9: =IF(G9=0,0,E9/G9) | J9: Rs799-2,499 | K9: Impulse + gifting | L9: Under-merchandised despite intent | M9: Desk-setup bundle | N9: Setup kit -12% | O9: Desk mat + organiser + tray | P9: Coaster/cable mgmt | Q9: Desk refresh CRM | R9: Shop-the-look | S9: Desk-setup complete-the-look bundle (ID10) | T9: High
A10: 1204 | B10: Laptop Sleeves | C10: Accessory / Attach | D10: 57414516 | E10: 24665 | F10: =IF(E10=0,0,D10/E10) | G10: 2992044 | H10: =IF(G10=0,0,118860/G10) | I10: =IF(G10=0,0,E10/G10) | J10: Rs900-1,800 | K10: Attach to bags/laptops | L10: Sold solo; natural bag attach | M10: Attach to backpack/laptop bag | N10: Kit with bag | O10: Bag + sleeve | P10: Tech organiser | Q10: Attach in bag flows | R10: Carry-system module | S10: Bundle into carry system (ID03) | T10: High
A11: 1103 | B11: Phone Cases (MagSafe/premium) | C11: Hero / Destination | D11: 55615165 | E11: 42193 | F11: =IF(E11=0,0,D11/E11) | G11: 3209429 | H11: =IF(G11=0,0,174079/G11) | I11: =IF(G11=0,0,E11/G11) | J11: Rs999-2,399 | K11: Premium case tier | L11: Higher ASP than clear cases | M11: Tier upsell + MagSafe bundle | N11: Upgrade toggle | O11: MagSafe case + power bank | P11: Screen guard | Q11: Ecosystem cross-sell | R11: Device hub premium tier | S11: Default recommend mid tier (ID16) | T11: High
A12: 1202 | B12: Premium Bags / Luggage | C12: High-consideration | D12: 49972854 | E12: 13378 | F12: =IF(E12=0,0,D12/E12) | G12: 2157624 | H12: =IF(G12=0,0,61983/G12) | I12: =IF(G12=0,0,E12/G12) | J12: Rs2,000-4,000+ | K12: Premium/luggage, highest ASP | L12: High ASP, low volume, considered | M12: Risk reversal + set pricing | N12: Set pricing | O12: Luggage set + organiser | P12: Packing organiser | Q12: VIP/high-AOV nurture | R12: Premium carry hub | S12: Set pricing + trial reassurance (ID39/ID03) | T12: Med
A13: 1805 | B13: Chargers & Adapters | C13: Ecosystem / Replace | D13: 46914557 | E13: 23368 | F13: =IF(E13=0,0,D13/E13) | G13: 2606672 | H13: =IF(G13=0,0,146025/G13) | I13: =IF(G13=0,0,E13/G13) | J13: Rs999-6,499 | K13: Ecosystem/replacement | L13: Chargers attach to phone/power ecosystem | M13: Attach to case/power bank | N13: Bundle | O13: Charger + cable | P13: Cable | Q13: Replacement reminders | R13: Device hub | S13: Attach to MagSafe/device ecosystem (ID02/ID33) | T13: Med
A14: 1203 | B14: Crossbody / Sling Bags | C14: High-consideration | D14: 43188218 | E14: 30156 | F14: =IF(E14=0,0,D14/E14) | G14: 3038751 | H14: =IF(G14=0,0,132325/G14) | I14: =IF(G14=0,0,E14/G14) | J14: Rs1,249-2,499 | K14: Fashion carry, women-led | L14: Solid volume; attach weak | M14: Cross-sell wallet/organiser | N14: Combo | O14: Sling + wallet | P14: Card holder | Q14: Style drops CRM | R14: Shop-by-style | S14: Sling + wallet combo (Zouk-style) (ID45) | T14: Med
A15: 1102 | B15: Phone Cases (clear/hybrid) | C15: Hero / Destination | D15: 26614245 | E15: 14905 | F15: =IF(E15=0,0,D15/E15) | G15: 1219444 | H15: =IF(G15=0,0,47938/G15) | I15: =IF(G15=0,0,E15/G15) | J15: varies | K15: See role | L15: Under-activated vs traffic | M15: Attach + CRM | N15: GWP/attach | O15: Complementary item | P15: Adjacent accy | Q15: Lifecycle CRM | R15: Merchandise in hub | S15: Attach + surface in relevant hub | T15: Med
A16: 1701 | B16: Desk Mats & Pads | C16: Add-on / Impulse | D16: 21554349 | E16: 22657 | F16: =IF(E16=0,0,D16/E16) | G16: 507203 | H16: =IF(G16=0,0,104953/G16) | I16: =IF(G16=0,0,E16/G16) | J16: varies | K16: See role | L16: Under-activated vs traffic | M16: Attach + CRM | N16: GWP/attach | O16: Complementary item | P16: Adjacent accy | Q16: Lifecycle CRM | R16: Merchandise in hub | S16: Attach + surface in relevant hub | T16: Med
A17: 1811 | B17: Cables & Charging Accy | C17: Impulse / Attach | D17: 19283567 | E17: 13335 | F17: =IF(E17=0,0,D17/E17) | G17: 1250037 | H17: =IF(G17=0,0,59003/G17) | I17: =IF(G17=0,0,E17/G17) | J17: varies | K17: See role | L17: Under-activated vs traffic | M17: Attach + CRM | N17: GWP/attach | O17: Complementary item | P17: Adjacent accy | Q17: Lifecycle CRM | R17: Merchandise in hub | S17: Attach + surface in relevant hub | T17: Med
A18: 1104 | B18: Phone Cases (custom/artist) | C18: Hero / Destination | D18: 15387327 | E18: 16713 | F18: =IF(E18=0,0,D18/E18) | G18: 807172 | H18: =IF(G18=0,0,59770/G18) | I18: =IF(G18=0,0,E18/G18) | J18: varies | K18: See role | L18: Under-activated vs traffic | M18: Attach + CRM | N18: GWP/attach | O18: Complementary item | P18: Adjacent accy | Q18: Lifecycle CRM | R18: Merchandise in hub | S18: Attach + surface in relevant hub | T18: Med
A19: 1814 | B19: Tech Accy (stands/mounts) | C19: Impulse / Attach | D19: 14987157 | E19: 11513 | F19: =IF(E19=0,0,D19/E19) | G19: 366384 | H19: =IF(G19=0,0,109794/G19) | I19: =IF(G19=0,0,E19/G19) | J19: varies | K19: See role | L19: Under-activated vs traffic | M19: Attach + CRM | N19: GWP/attach | O19: Complementary item | P19: Adjacent accy | Q19: Lifecycle CRM | R19: Merchandise in hub | S19: Attach + surface in relevant hub | T19: Low
A20: 1813 | B20: Tech Accy (misc) | C20: Impulse / Attach | D20: 13650558 | E20: 14562 | F20: =IF(E20=0,0,D20/E20) | G20: 796233 | H20: =IF(G20=0,0,85938/G20) | I20: =IF(G20=0,0,E20/G20) | J20: varies | K20: See role | L20: Under-activated vs traffic | M20: Attach + CRM | N20: GWP/attach | O20: Complementary item | P20: Adjacent accy | Q20: Lifecycle CRM | R20: Merchandise in hub | S20: Attach + surface in relevant hub | T20: Low
A21: 1205 | B21: Tote Bags | C21: Accessory / Add-on | D21: 11023656 | E21: 3200 | F21: =IF(E21=0,0,D21/E21) | G21: 550150 | H21: =IF(G21=0,0,18340/G21) | I21: =IF(G21=0,0,E21/G21) | J21: varies | K21: See role | L21: Under-activated vs traffic | M21: Attach + CRM | N21: GWP/attach | O21: Complementary item | P21: Adjacent accy | Q21: Lifecycle CRM | R21: Merchandise in hub | S21: Attach + surface in relevant hub | T21: Low
A22: 1301 | B22: Wallets (bifold/leather) | C22: Gifting / Repeat | D22: 9770788 | E22: 12072 | F22: =IF(E22=0,0,D22/E22) | G22: 658364 | H22: =IF(G22=0,0,47019/G22) | I22: =IF(G22=0,0,E22/G22) | J22: varies | K22: See role | L22: Under-activated vs traffic | M22: Attach + CRM | N22: GWP/attach | O22: Complementary item | P22: Adjacent accy | Q22: Lifecycle CRM | R22: Merchandise in hub | S22: Attach + surface in relevant hub | T22: Low
A23: 1812 | B23: Tech Accy (grips/rings) | C23: Impulse / Attach | D23: 6648714 | E23: 10586 | F23: =IF(E23=0,0,D23/E23) | G23: 132387 | H23: =IF(G23=0,0,38819/G23) | I23: =IF(G23=0,0,E23/G23) | J23: varies | K23: See role | L23: Under-activated vs traffic | M23: Attach + CRM | N23: GWP/attach | O23: Complementary item | P23: Adjacent accy | Q23: Lifecycle CRM | R23: Merchandise in hub | S23: Attach + surface in relevant hub | T23: Low
A24: 1304 | B24: Card Holders / Slim Wallets | C24: Gifting / Impulse | D24: 5764217 | E24: 6883 | F24: =IF(E24=0,0,D24/E24) | G24: 635184 | H24: =IF(G24=0,0,31044/G24) | I24: =IF(G24=0,0,E24/G24) | J24: varies | K24: See role | L24: Under-activated vs traffic | M24: Attach + CRM | N24: GWP/attach | O24: Complementary item | P24: Adjacent accy | Q24: Lifecycle CRM | R24: Merchandise in hub | S24: Attach + surface in relevant hub | T24: Low
A25: 1815 | B25: Tech Accy (screen guards) | C25: Attach / Replace | D25: 5479024 | E25: 7176 | F25: =IF(E25=0,0,D25/E25) | G25: 115872 | H25: =IF(G25=0,0,47517/G25) | I25: =IF(G25=0,0,E25/G25) | J25: varies | K25: See role | L25: Under-activated vs traffic | M25: Attach + CRM | N25: GWP/attach | O25: Complementary item | P25: Adjacent accy | Q25: Lifecycle CRM | R25: Merchandise in hub | S25: Attach + surface in relevant hub | T25: Low
A26: 1402 | B26: AirPods Cases | C26: Impulse / Attach | D26: 5012482 | E26: 13056 | F26: =IF(E26=0,0,D26/E26) | G26: 301454 | H26: =IF(G26=0,0,41307/G26) | I26: =IF(G26=0,0,E26/G26) | J26: varies | K26: See role | L26: Under-activated vs traffic | M26: Attach + CRM | N26: GWP/attach | O26: Complementary item | P26: Adjacent accy | Q26: Lifecycle CRM | R26: Merchandise in hub | S26: Attach + surface in relevant hub | T26: Low
A27: 1403 | B27: AirPods Pro Cases | C27: Impulse / Attach | D27: 4385984 | E27: 4416 | F27: =IF(E27=0,0,D27/E27) | G27: 246992 | H27: =IF(G27=0,0,14093/G27) | I27: =IF(G27=0,0,E27/G27) | J27: varies | K27: See role | L27: Under-activated vs traffic | M27: Attach + CRM | N27: GWP/attach | O27: Complementary item | P27: Adjacent accy | Q27: Lifecycle CRM | R27: Merchandise in hub | S27: Attach + surface in relevant hub | T27: Low
A28: 1302 | B28: Wallets (zip/travel) | C28: Gifting / Repeat | D28: 4321887 | E28: 7379 | F28: =IF(E28=0,0,D28/E28) | G28: 554915 | H28: =IF(G28=0,0,34390/G28) | I28: =IF(G28=0,0,E28/G28) | J28: varies | K28: See role | L28: Under-activated vs traffic | M28: Attach + CRM | N28: GWP/attach | O28: Complementary item | P28: Adjacent accy | Q28: Lifecycle CRM | R28: Merchandise in hub | S28: Attach + surface in relevant hub | T28: Low
A29: 1307 | B29: Wallets (money clip/misc) | C29: Gifting / Impulse | D29: 3668524 | E29: 5790 | F29: =IF(E29=0,0,D29/E29) | G29: 381418 | H29: =IF(G29=0,0,28130/G29) | I29: =IF(G29=0,0,E29/G29) | J29: varies | K29: See role | L29: Under-activated vs traffic | M29: Attach + CRM | N29: GWP/attach | O29: Complementary item | P29: Adjacent accy | Q29: Lifecycle CRM | R29: Merchandise in hub | S29: Attach + surface in relevant hub | T29: Low
A30: 1207 | B30: Bags (misc / laptop bags) | C30: Accessory / Attach | D30: 2926530 | E30: 5920 | F30: =IF(E30=0,0,D30/E30) | G30: 352841 | H30: =IF(G30=0,0,25588/G30) | I30: =IF(G30=0,0,E30/G30) | J30: varies | K30: See role | L30: Under-activated vs traffic | M30: Attach + CRM | N30: GWP/attach | O30: Complementary item | P30: Adjacent accy | Q30: Lifecycle CRM | R30: Merchandise in hub | S30: Attach + surface in relevant hub | T30: Low
A31: 1305 | B31: Wallets for Men | C31: Gifting / Repeat | D31: 2838951 | E31: 2666 | F31: =IF(E31=0,0,D31/E31) | G31: 174026 | H31: =IF(G31=0,0,10788/G31) | I31: =IF(G31=0,0,E31/G31) | J31: varies | K31: See role | L31: Under-activated vs traffic | M31: Attach + CRM | N31: GWP/attach | O31: Complementary item | P31: Adjacent accy | Q31: Lifecycle CRM | R31: Merchandise in hub | S31: Attach + surface in relevant hub | T31: Low
A32: 1705 | B32: Drinkware / Coasters | C32: Impulse / Gifting | D32: 2532741 | E32: 3259 | F32: =IF(E32=0,0,D32/E32) | G32: 242071 | H32: =IF(G32=0,0,10985/G32) | I32: =IF(G32=0,0,E32/G32) | J32: varies | K32: See role | L32: Under-activated vs traffic | M32: Attach + CRM | N32: GWP/attach | O32: Complementary item | P32: Adjacent accy | Q32: Lifecycle CRM | R32: Merchandise in hub | S32: Attach + surface in relevant hub | T32: Low
A33: 1401 | B33: AirPods (misc) | C33: Impulse / Attach | D33: 1887587 | E33: 2163 | F33: =IF(E33=0,0,D33/E33) | G33: 95051 | H33: =IF(G33=0,0,7185/G33) | I33: =IF(G33=0,0,E33/G33) | J33: varies | K33: See role | L33: Under-activated vs traffic | M33: Attach + CRM | N33: GWP/attach | O33: Complementary item | P33: Adjacent accy | Q33: Lifecycle CRM | R33: Merchandise in hub | S33: Attach + surface in relevant hub | T33: Low
A34: 1303 | B34: Wallets (passport) | C34: Gifting / Low-freq | D34: 1477440 | E34: 1566 | F34: =IF(E34=0,0,D34/E34) | G34: 79578 | H34: =IF(G34=0,0,5326/G34) | I34: =IF(G34=0,0,E34/G34) | J34: varies | K34: See role | L34: Under-activated vs traffic | M34: Attach + CRM | N34: GWP/attach | O34: Complementary item | P34: Adjacent accy | Q34: Lifecycle CRM | R34: Merchandise in hub | S34: Attach + surface in relevant hub | T34: Low
A35: 1604 | B35: Gift Sets / Bundles | C35: Gifting | D35: 1113000 | E35: 490 | F35: =IF(E35=0,0,D35/E35) | G35: 33381 | H35: =IF(G35=0,0,2195/G35) | I35: =IF(G35=0,0,E35/G35) | J35: varies | K35: See role | L35: Under-activated vs traffic | M35: Attach + CRM | N35: GWP/attach | O35: Complementary item | P35: Adjacent accy | Q35: Lifecycle CRM | R35: Merchandise in hub | S35: Attach + surface in relevant hub | T35: Low
A36: 1602 | B36: Gift Cards | C36: Gifting | D36: 1084610 | E36: 290 | F36: =IF(E36=0,0,D36/E36) | G36: 22852 | H36: =IF(G36=0,0,537/G36) | I36: =IF(G36=0,0,E36/G36) | J36: varies | K36: See role | L36: Under-activated vs traffic | M36: Attach + CRM | N36: GWP/attach | O36: Complementary item | P36: Adjacent accy | Q36: Lifecycle CRM | R36: Merchandise in hub | S36: Attach + surface in relevant hub | T36: Low
A37: 1603 | B37: Gifting (corporate/curated) | C37: Gifting | D37: 1004492 | E37: 308 | F37: =IF(E37=0,0,D37/E37) | G37: 66359 | H37: =IF(G37=0,0,1135/G37) | I37: =IF(G37=0,0,E37/G37) | J37: varies | K37: See role | L37: Under-activated vs traffic | M37: Attach + CRM | N37: GWP/attach | O37: Complementary item | P37: Adjacent accy | Q37: Lifecycle CRM | R37: Merchandise in hub | S37: Attach + surface in relevant hub | T37: Low
A38: 1707 | B38: Drinkware (bottles/flasks) | C38: Impulse / Gifting | D38: 881169 | E38: 1001 | F38: =IF(E38=0,0,D38/E38) | G38: 75861 | H38: =IF(G38=0,0,4155/G38) | I38: =IF(G38=0,0,E38/G38) | J38: varies | K38: See role | L38: Under-activated vs traffic | M38: Attach + CRM | N38: GWP/attach | O38: Complementary item | P38: Adjacent accy | Q38: Lifecycle CRM | R38: Merchandise in hub | S38: Attach + surface in relevant hub | T38: Low
B39: TOTAL | D39: =SUM(D4:D38) | E39: =SUM(E4:E38) | G39: =SUM(G4:G38)

Sheet 6. Basket Affinity
A1: BASKET AFFINITY & TOP-20 BUNDLE OPPORTUNITIES
A2: Attach rate & lift are HYPOTHESES (no order-line SKU data available; GA4 provides no true co-purchase). Validate with a market-basket run on order-line data, then bundle. Combined ASP & saving are formula-driven.
A3: Rank | B3: Primary Product | C3: Primary Cat | D3: Secondary Product | E3: Secondary Cat | F3: Est. Attach Rate (HYP) | G3: Est. Lift (HYP) | H3: Primary ASP | I3: Secondary ASP | J3: Combined ASP | K3: Bundle Exists? | L3: Recommended Bundle Price | M3: Customer Saving | N3: Recommended Placement | O3: Priority (/100) | P3: Idea Ref
A4: 1 | B4: Phone Case | C4: 1101 | D4: Tempered Screen Guard | E4: 1815 | F4: 0.35 | G4: 4.2 | H4: 1068 | I4: 764 | J4: =H4+I4 | K4: None yet | L4: =ROUND(J4*0.9,0) | M4: =J4-L4 | N4: PDP FBT + Cart rail | O4: 100
A5: 2 | B5: MagSafe Case | C5: 1103 | D5: Screen Guard | E5: 1815 | F5: 0.33 | G5: 4 | H5: 1318 | I5: 764 | J5: =H5+I5 | K5: None yet | L5: =ROUND(J5*0.9,0) | M5: =J5-L5 | N5: PDP FBT + Cart rail | O5: 89.8
A6: 3 | B6: Desk Organiser | C6: 1702 | D6: Desk Mat | E6: 1701 | F6: 0.28 | G6: 3.4 | H6: 1326 | I6: 951 | J6: =H6+I6 | K6: None yet | L6: =ROUND(J6*0.9,0) | M6: =J6-L6 | N6: PDP FBT + Cart rail | O6: 64.8
A7: 4 | B7: Backpack | C7: 1201 | D7: Laptop Sleeve | E7: 1204 | F7: 0.2 | G7: 3.6 | H7: 1940 | I7: 2328 | J7: =H7+I7 | K7: Combo (ad hoc) | L7: =ROUND(J7*0.9,0) | M7: =J7-L7 | N7: PDP FBT + Cart rail | O7: 49
A8: 5 | B8: Desk Mat | C8: 1701 | D8: Cable Organiser | E8: 1703 | F8: 0.22 | G8: 2.9 | H8: 951 | I8: 1126 | J8: =H8+I8 | K8: None yet | L8: =ROUND(J8*0.9,0) | M8: =J8-L8 | N8: PDP FBT + Cart rail | O8: 43.4
