Workbook

Sheet Bucket Summary
A1: Marketing Spend by Bucket – FY24 to FY26 (Actuals)
A2: INR in crores (converted from finance sheet INR millions ÷ 10) · Source: Finance advertisement expense sheet, mapped to buckets in "Line Item Mapping"
A4: Marketing bucket | B4: What it covers | C4: FY24 (₹ Cr) | D4: FY25 (₹ Cr) | E4: FY26 (₹ Cr) | F4: FY24 mix % | G4: FY25 mix % | H4: FY26 mix % | I4: YoY FY25 | J4: YoY FY26 | K4: FY26 % of revenue
A5: Performance Marketing – D2C Website | B5: Meta (Facebook/Instagram) & Google ads driving traffic to dailyobjects.com | C5: =SUMIFS('Line Item Mapping'!$F$5:$F$77,'Line Item Mapping'!$C$5:$C$77,$A5) -> 12.998116 | D5: =SUMIFS('Line Item Mapping'!$G$5:$G$77,'Line Item Mapping'!$C$5:$C$77,$A5) -> 17.75321 | E5: =SUMIFS('Line Item Mapping'!$H$5:$H$77,'Line Item Mapping'!$C$5:$C$77,$A5) -> 24.839866 | F5: =IF(C$16=0,0,C5/C$16) -> 0.70513324 | G5: =IF(D$16=0,0,D5/D$16) -> 0.68311975 | H5: =IF(E$16=0,0,E5/E$16) -> 0.59779784 | I5: =IF(C5=0,"n.m.",D5/C5-1) -> 0.36582946 | J5: =IF(D5=0,"n.m.",E5/D5-1) -> 0.39917603 | K5: =IF($E$18=0,0,E5/$E$18) -> 0.1207423
A6: Marketplace Ads | B6: Sponsored ads on Amazon, Myntra, Flipkart, Nykaa | C6: =SUMIFS('Line Item Mapping'!$F$5:$F$77,'Line Item Mapping'!$C$5:$C$77,$A6) -> 1.7165222 | D6: =SUMIFS('Line Item Mapping'!$G$5:$G$77,'Line Item Mapping'!$C$5:$C$77,$A6) -> 3.8127162 | E6: =SUMIFS('Line Item Mapping'!$H$5:$H$77,'Line Item Mapping'!$C$5:$C$77,$A6) -> 12.04506 | F6: =IF(C$16=0,0,C6/C$16) -> 0.093119404 | G6: =IF(D$16=0,0,D6/D$16) -> 0.14670821 | H6: =IF(E$16=0,0,E6/E$16) -> 0.2898772 | I6: =IF(C6=0,"n.m.",D6/C6-1) -> 1.2211867 | J6: =IF(D6=0,"n.m.",E6/D6-1) -> 2.1591808 | K6: =IF($E$18=0,0,E6/$E$18) -> 0.058548956
A7: Quick Commerce Ads | B7: Ads on Blinkit, Zepto, Swiggy Instamart | C7: =SUMIFS('Line Item Mapping'!$F$5:$F$77,'Line Item Mapping'!$C$5:$C$77,$A7) -> 0 | D7: =SUMIFS('Line Item Mapping'!$G$5:$G$77,'Line Item Mapping'!$C$5:$C$77,$A7) -> 0.215 | E7: =SUMIFS('Line Item Mapping'!$H$5:$H$77,'Line Item Mapping'!$C$5:$C$77,$A7) -> 0.85448946 | F7: =IF(C$16=0,0,C7/C$16) -> 0 | G7: =IF(D$16=0,0,D7/D$16) -> 0.008272912 | H7: =IF(E$16=0,0,E7/E$16) -> 0.020564199 | I7: =IF(C7=0,"n.m.",D7/C7-1) -> n.m. | J7: =IF(D7=0,"n.m.",E7/D7-1) -> 2.9743696 | K7: =IF($E$18=0,0,E7/$E$18) -> 0.0041535257
A8: Affiliate & Ad Networks | B8: Affiliate & CPS/CPA networks (Admitad, vCommission etc.) | C8: =SUMIFS('Line Item Mapping'!$F$5:$F$77,'Line Item Mapping'!$C$5:$C$77,$A8) -> 1.1390134 | D8: =SUMIFS('Line Item Mapping'!$G$5:$G$77,'Line Item Mapping'!$C$5:$C$77,$A8) -> 0.79732287 | E8: =SUMIFS('Line Item Mapping'!$H$5:$H$77,'Line Item Mapping'!$C$5:$C$77,$A8) -> 0.81849705 | F8: =IF(C$16=0,0,C8/C$16) -> 0.0617902 | G8: =IF(D$16=0,0,D8/D$16) -> 0.030679916 | H8: =IF(E$16=0,0,E8/E$16) -> 0.019698003 | I8: =IF(C8=0,"n.m.",D8/C8-1) -> -0.29998814 | J8: =IF(D8=0,"n.m.",E8/D8-1) -> 0.026556589 | K8: =IF($E$18=0,0,E8/$E$18) -> 0.0039785728
A9: Other Digital Media | B9: Twitter/X, LinkedIn, Microsoft/Bing, co-marketing & other paid placements | C9: =SUMIFS('Line Item Mapping'!$F$5:$F$77,'Line Item Mapping'!$C$5:$C$77,$A9) -> 0.12151193 | D9: =SUMIFS('Line Item Mapping'!$G$5:$G$77,'Line Item Mapping'!$C$5:$C$77,$A9) -> 0.10658553 | E9: =SUMIFS('Line Item Mapping'!$H$5:$H$77,'Line Item Mapping'!$C$5:$C$77,$A9) -> 0.02 | F9: =IF(C$16=0,0,C9/C$16) -> 0.0065918861 | G9: =IF(D$16=0,0,D9/D$16) -> 0.0041012684 | H9: =IF(E$16=0,0,E9/E$16) -> 0.00048132131 | I9: =IF(C9=0,"n.m.",D9/C9-1) -> -0.12283897 | J9: =IF(D9=0,"n.m.",E9/D9-1) -> -0.81235727 | K9: =IF($E$18=0,0,E9/$E$18) -> 9.7216546e-05
A10: CRM, Retention & SMS | B10: MoEngage, Wigzo, GupShup, SMS charges | C10: =SUMIFS('Line Item Mapping'!$F$5:$F$77,'Line Item Mapping'!$C$5:$C$77,$A10) -> 0.31482672 | D10: =SUMIFS('Line Item Mapping'!$G$5:$G$77,'Line Item Mapping'!$C$5:$C$77,$A10) -> 0.39851883 | E10: =SUMIFS('Line Item Mapping'!$H$5:$H$77,'Line Item Mapping'!$C$5:$C$77,$A10) -> 1.116663 | F10: =IF(C$16=0,0,C10/C$16) -> 0.017078997 | G10: =IF(D$16=0,0,D10/D$16) -> 0.015334471 | H10: =IF(E$16=0,0,E10/E$16) -> 0.026873685 | I10: =IF(C10=0,"n.m.",D10/C10-1) -> 0.26583545 | J10: =IF(D10=0,"n.m.",E10/D10-1) -> 1.8020332 | K10: =IF($E$18=0,0,E10/$E$18) -> 0.005427906
A11: Brand, Content & Production | B11: Brand campaigns, ad films, shoots, models, videography, creative & PR agencies | C11: =SUMIFS('Line Item Mapping'!$F$5:$F$77,'Line Item Mapping'!$C$5:$C$77,$A11) -> 0.0763441 | D11: =SUMIFS('Line Item Mapping'!$G$5:$G$77,'Line Item Mapping'!$C$5:$C$77,$A11) -> 1.5464863 | E11: =SUMIFS('Line Item Mapping'!$H$5:$H$77,'Line Item Mapping'!$C$5:$C$77,$A11) -> 1.0772397 | F11: =IF(C$16=0,0,C11/C$16) -> 0.0041415819 | G11: =IF(D$16=0,0,D11/D$16) -> 0.059506721 | H11: =IF(E$16=0,0,E11/E$16) -> 0.02592492 | I11: =IF(C11=0,"n.m.",D11/C11-1) -> 19.256789 | J11: =IF(D11=0,"n.m.",E11/D11-1) -> -0.3034276 | K11: =IF($E$18=0,0,E11/$E$18) -> 0.005236276
A12: Influencer & Creator Marketing | B12: Influencer payouts & creator collaborations | C12: =SUMIFS('Line Item Mapping'!$F$5:$F$77,'Line Item Mapping'!$C$5:$C$77,$A12) -> 0.038568508 | D12: =SUMIFS('Line Item Mapping'!$G$5:$G$77,'Line Item Mapping'!$C$5:$C$77,$A12) -> 0.098795763 | E12: =SUMIFS('Line Item Mapping'!$H$5:$H$77,'Line Item Mapping'!$C$5:$C$77,$A12) -> 0.3794468 | F12: =IF(C$16=0,0,C12/C$16) -> 0.0020922983 | G12: =IF(D$16=0,0,D12/D$16) -> 0.0038015286 | H12: =IF(E$16=0,0,E12/E$16) -> 0.0091317915 | I12: =IF(C12=0,"n.m.",D12/C12-1) -> 1.5615656 | J12: =IF(D12=0,"n.m.",E12/D12-1) -> 2.8407194 | K12: =IF($E$18=0,0,E12/$E$18) -> 0.0018444254
A13: Sampling, Freebies & Gifting | B13: Freebies, product sampling & gifting | C13: =SUMIFS('Line Item Mapping'!$F$5:$F$77,'Line Item Mapping'!$C$5:$C$77,$A13) -> 1.7839522 | D13: =SUMIFS('Line Item Mapping'!$G$5:$G$77,'Line Item Mapping'!$C$5:$C$77,$A13) -> 0.91940623 | E13: =SUMIFS('Line Item Mapping'!$H$5:$H$77,'Line Item Mapping'!$C$5:$C$77,$A13) -> 0.13714212 | F13: =IF(C$16=0,0,C13/C$16) -> 0.096777408 | G13: =IF(D$16=0,0,D13/D$16) -> 0.03537752 | H13: =IF(E$16=0,0,E13/E$16) -> 0.0033004712 | I13: =IF(C13=0,"n.m.",D13/C13-1) -> -0.48462396 | J13: =IF(D13=0,"n.m.",E13/D13-1) -> -0.85083621 | K13: =IF($E$18=0,0,E13/$E$18) -> 0.00066662415
A14: Marketing Tools & Subscriptions | B14: Design / marketing software subscriptions | C14: =SUMIFS('Line Item Mapping'!$F$5:$F$77,'Line Item Mapping'!$C$5:$C$77,$A14) -> 0.01815665 | D14: =SUMIFS('Line Item Mapping'!$G$5:$G$77,'Line Item Mapping'!$C$5:$C$77,$A14) -> 0.028092792 | E14: =SUMIFS('Line Item Mapping'!$H$5:$H$77,'Line Item Mapping'!$C$5:$C$77,$A14) -> 0.030403944 | F14: =IF(C$16=0,0,C14/C$16) -> 0.00098497792 | G14: =IF(D$16=0,0,D14/D$16) -> 0.001080973 | H14: =IF(E$16=0,0,E14/E$16) -> 0.0007317033 | I14: =IF(C14=0,"n.m.",D14/C14-1) -> 0.54724533 | J14: =IF(D14=0,"n.m.",E14/D14-1) -> 0.082268505 | K14: =IF($E$18=0,0,E14/$E$18) -> 0.00014778832
A15: Misc. / Unallocated | B15: Provisions, unmapped vendor entries, entertainment, unreconciled difference | C15: =SUMIFS('Line Item Mapping'!$F$5:$F$77,'Line Item Mapping'!$C$5:$C$77,$A15) -> 0.22654851 | D15: =SUMIFS('Line Item Mapping'!$G$5:$G$77,'Line Item Mapping'!$C$5:$C$77,$A15) -> 0.312296 | E15: =SUMIFS('Line Item Mapping'!$H$5:$H$77,'Line Item Mapping'!$C$5:$C$77,$A15) -> 0.23347675 | F15: =IF(C$16=0,0,C15/C$16) -> 0.012290003 | G15: =IF(D$16=0,0,D15/D$16) -> 0.012016732 | H15: =IF(E$16=0,0,E15/E$16) -> 0.0056188667 | I15: =IF(C15=0,"n.m.",D15/C15-1) -> 0.37849505 | J15: =IF(D15=0,"n.m.",E15/D15-1) -> -0.25238636 | K15: =IF($E$18=0,0,E15/$E$18) -> 0.0011348901
A16: Total marketing spend | C16: =SUM(C5:C15) -> 18.43356 | D16: =SUM(D5:D15) -> 25.988431 | E16: =SUM(E5:E15) -> 41.552285 | F16: =SUM(F5:F15) -> 1 | G16: =SUM(G5:G15) -> 1 | H16: =SUM(H5:H15) -> 1 | I16: =D16/C16-1 -> 0.40984325 | J16: =E16/D16-1 -> 0.59887626 | K16: =E16/$E$18 -> 0.20197848
A18: Total revenue (as per IS) | B18: Cached from finance model IS!C5/D5/F5 (linked workbook) | C18: 84.381491 | D18: 110.28212 | E18: 205.7263
A19: Marketing spend % of revenue | C19: =C16/C18 -> 0.21845502 | D19: =D16/D18 -> 0.23565408 | E19: =E16/E18 -> 0.20197848
A22: Roll-up view
A23: Group | B23: Buckets included | C23: FY24 (₹ Cr) | D23: FY25 (₹ Cr) | E23: FY26 (₹ Cr) | F23: FY26 mix %
A24: Performance / Paid Media | B24: Performance Marketing – D2C Website, Marketplace Ads, Quick Commerce Ads, Affiliate & Ad Networks, Other Digital Media | C24: =C5+C6+C7+C8+C9 -> 15.975164 | D24: =D5+D6+D7+D8+D9 -> 22.684835 | E24: =E5+E6+E7+E8+E9 -> 38.577912 | F24: =E24/$E$16 -> 0.92841856
A25: Brand & Content | B25: Brand, Content & Production, Influencer & Creator Marketing, Sampling, Freebies & Gifting | C25: =C11+C12+C13 -> 1.8988648 | D25: =D11+D12+D13 -> 2.5646883 | E25: =E11+E12+E13 -> 1.5938286 | F25: =E25/$E$16 -> 0.038357183
A26: CRM, Tools & Other | B26: CRM, Retention & SMS, Marketing Tools & Subscriptions, Misc. / Unallocated | C26: =C10+C14+C15 -> 0.55953188 | D26: =D10+D14+D15 -> 0.73890762 | E26: =E10+E14+E15 -> 1.3805437 | F26: =E26/$E$16 -> 0.033224255
A27: Total | C27: =SUM(C24:C26) -> 18.43356 | D27: =SUM(D24:D26) -> 25.988431 | E27: =SUM(E24:E26) -> 41.552285 | F27: =SUM(F24:F26) -> 1
A29: Notes
A30: 1. FY24–FY26 are actuals from the finance advertisement expense schedule (Management information). FY27 budget is not part of this data – see "FY27 Budget" tab.
A31: 2. FY26 total here (41.55 Cr) ties to the finance schedule; finance notes a 0.03 Cr difference vs. the audited FS figure (41.58 Cr).
A32: 3. "Misc. / Unallocated" in FY26 includes a 0.38 Cr unreconciled difference and a -0.21 Cr reversal on unidentified vendor entries (per finance).
A33: 4. Mapping of smaller vendors is inferred from vendor name – see confidence column in "Line Item Mapping". Change the bucket there and this summary updates.

Sheet FY26 Activity Detail
A1: FY26 Marketing Spend – Bucket > Activity breakdown
A2: INR in crores (converted from finance sheet INR millions ÷ 10) · Line items with zero FY26 spend omitted
A4: Bucket / activity | B4: Vendor / line item | C4: FY26 (₹ Cr) | D4: % of bucket | E4: % of total
A5: Performance Marketing – D2C Website | C5: =SUMIFS('Line Item Mapping'!$H$5:$H$77,'Line Item Mapping'!$C$5:$C$77,A5) -> 24.839866 | E5: =C5/$C$49 -> 0.59779784
A6: Meta ads | B6: Facebook | C6: ='Line Item Mapping'!H5 -> 19.811684 | D6: =IF($C$5=0,0,C6/$C$5) -> 0.7975761 | E6: =C6/$C$49 -> 0.47678927
A7: Google ads | B7: Google | C7: ='Line Item Mapping'!H6 -> 5.0281825 | D7: =IF($C$5=0,0,C7/$C$5) -> 0.2024239 | E7: =C7/$C$49 -> 0.12100857
A8: Marketplace Ads | C8: =SUMIFS('Line Item Mapping'!$H$5:$H$77,'Line Item Mapping'!$C$5:$C$77,A8) -> 12.04506 | E8: =C8/$C$49 -> 0.2898772
A9: Amazon sponsored ads | B9: Amazon | C9: ='Line Item Mapping'!H7 -> 10.703484 | D9: =IF($C$8=0,0,C9/$C$8) -> 0.88862025 | E9: =C9/$C$49 -> 0.25759075
A10: Myntra ads | B10: Myntra Designs Pvt. Ltd. | C10: ='Line Item Mapping'!H8 -> 0.78260712 | D10: =IF($C$8=0,0,C10/$C$8) -> 0.064973286 | E10: =C10/$C$49 -> 0.018834274
A11: Flipkart ads | B11: Flipkart | C11: ='Line Item Mapping'!H9 -> 0.32921782 | D11: =IF($C$8=0,0,C11/$C$8) -> 0.027332186 | E11: =C11/$C$49 -> 0.0079229775
A12: Nykaa ads | B12: Nykaa | C12: ='Line Item Mapping'!H10 -> 0.22975077 | D12: =IF($C$8=0,0,C12/$C$8) -> 0.019074274 | E12: =C12/$C$49 -> 0.0055291971
A13: Quick Commerce Ads | C13: =SUMIFS('Line Item Mapping'!$H$5:$H$77,'Line Item Mapping'!$C$5:$C$77,A13) -> 0.85448946 | E13: =C13/$C$49 -> 0.020564199
A14: Blinkit ads | B14: Blink Commerce Pvt. Ltd. | C14: ='Line Item Mapping'!H11 -> 0.7 | D14: =IF($C$13=0,0,C14/$C$13) -> 0.81920261 | E14: =C14/$C$49 -> 0.016846246
A15: Zepto ads | B15: Zepto Limited | C15: ='Line Item Mapping'!H12 -> 0.11081856 | D15: =IF($C$13=0,0,C15/$C$13) -> 0.12968979 | E15: =C15/$C$49 -> 0.0026669667
A16: Swiggy Instamart ads | B16: Swiggy Limited | C16: ='Line Item Mapping'!H13 -> 0.0436709 | D16: =IF($C$13=0,0,C16/$C$13) -> 0.051107594 | E16: =C16/$C$49 -> 0.0010509867
A17: Affiliate & Ad Networks | C17: =SUMIFS('Line Item Mapping'!$H$5:$H$77,'Line Item Mapping'!$C$5:$C$77,A17) -> 0.81849705 | E17: =C17/$C$49 -> 0.019698003
A18: Affiliate network | B18: Admitad Media Private Limited | C18: ='Line Item Mapping'!H14 -> 0.79997 | D18: =IF($C$17=0,0,C18/$C$17) -> 0.97736455 | E18: =C18/$C$49 -> 0.01925213
A19: Ad-tech / performance vendor | B19: INSPIRELABS SOLUTIONS PVT LTD | C19: ='Line Item Mapping'!H16 -> 0.011027047 | D19: =IF($C$17=0,0,C19/$C$17) -> 0.013472311 | E19: =C19/$C$49 -> 0.00026537763
A20: Digital ad vendor | B20: Pixel Viilage E-Sources Private Limited | C20: ='Line Item Mapping'!H15 -> 0.0075 | D20: =IF($C$17=0,0,C20/$C$17) -> 0.0091631363 | E20: =C20/$C$49 -> 0.00018049549
A21: Other Digital Media | C21: =SUMIFS('Line Item Mapping'!$H$5:$H$77,'Line Item Mapping'!$C$5:$C$77,A21) -> 0.02 | E21: =C21/$C$49 -> 0.00048132131
A22: Digital media vendor | B22: Edel Tech | C22: ='Line Item Mapping'!H24 -> 0.02 | D22: =IF($C$21=0,0,C22/$C$21) -> 1 | E22: =C22/$C$49 -> 0.00048132131
A23: CRM, Retention & SMS | C23: =SUMIFS('Line Item Mapping'!$H$5:$H$77,'Line Item Mapping'!$C$5:$C$77,A23) -> 1.116663 | E23: =C23/$C$49 -> 0.026873685
A24: SMS charges | B24: SMS charges | C24: ='Line Item Mapping'!H39 -> 0.891663 | D24: =IF($C$23=0,0,C24/$C$23) -> 0.7985068 | E24: =C24/$C$49 -> 0.02145882
A25: MoEngage – CRM / engagement platform | B25: MoEngage India Private Limited | C25: ='Line Item Mapping'!H38 -> 0.225 | D25: =IF($C$23=0,0,C25/$C$23) -> 0.2014932 | E25: =C25/$C$49 -> 0.0054148647
A26: Brand, Content & Production | C26: =SUMIFS('Line Item Mapping'!$H$5:$H$77,'Line Item Mapping'!$C$5:$C$77,A26) -> 1.0772397 | E26: =C26/$C$49 -> 0.02592492
A27: Branding expenses | B27: Branding expenses | C27: ='Line Item Mapping'!H49 -> 0.52076367 | D27: =IF($C$26=0,0,C27/$C$26) -> 0.48342415 | E27: =C27/$C$49 -> 0.012532732
A28: Model fees for shoots | B28: Modeling expenses | C28: ='Line Item Mapping'!H50 -> 0.278976 | D28: =IF($C$26=0,0,C28/$C$26) -> 0.25897301 | E28: =C28/$C$49 -> 0.0067138546
A29: Videography | B29: Videography expenses | C29: ='Line Item Mapping'!H51 -> 0.1555 | D29: =IF($C$26=0,0,C29/$C$26) -> 0.14435042 | E29: =C29/$C$49 -> 0.0037422732
A30: Design / creative agency | B30: Ved Uttam Design | C30: ='Line Item Mapping'!H40 -> 0.09 | D30: =IF($C$26=0,0,C30/$C$26) -> 0.083546868 | E30: =C30/$C$49 -> 0.0021659459
A31: Creative / PR agency | B31: Bun Maska Communications | C31: ='Line Item Mapping'!H41 -> 0.032 | D31: =IF($C$26=0,0,C31/$C$26) -> 0.029705553 | E31: =C31/$C$49 -> 0.00077011409
A32: Influencer & Creator Marketing | C32: =SUMIFS('Line Item Mapping'!$H$5:$H$77,'Line Item Mapping'!$C$5:$C$77,A32) -> 0.3794468 | E32: =C32/$C$49 -> 0.0091317915
A33: Influencer expenses | B33: Influencer expenses | C33: ='Line Item Mapping'!H63 -> 0.350192 | D33: =IF($C$32=0,0,C33/$C$32) -> 0.92290144 | E33: =C33/$C$49 -> 0.0084277435
A34: Individual creator payout | B34: Yogesh | C34: ='Line Item Mapping'!H52 -> 0.0202548 | D34: =IF($C$32=0,0,C34/$C$32) -> 0.053379815 | E34: =C34/$C$49 -> 0.00048745334
A35: Individual creator payout | B35: Monty | C35: ='Line Item Mapping'!H53 -> 0.009 | D35: =IF($C$32=0,0,C35/$C$32) -> 0.02371874 | E35: =C35/$C$49 -> 0.00021659459
A36: Sampling, Freebies & Gifting | C36: =SUMIFS('Line Item Mapping'!$H$5:$H$77,'Line Item Mapping'!$C$5:$C$77,A36) -> 0.13714212 | E36: =C36/$C$49 -> 0.0033004712
A37: Product sampling | B37: Sampling expenses | C37: ='Line Item Mapping'!H65 -> 0.13714212 | D37: =IF($C$36=0,0,C37/$C$36) -> 1 | E37: =C37/$C$49 -> 0.0033004712
A38: Marketing Tools & Subscriptions | C38: =SUMIFS('Line Item Mapping'!$H$5:$H$77,'Line Item Mapping'!$C$5:$C$77,A38) -> 0.030403944 | E38: =C38/$C$49 -> 0.0007317033
A39: Subscription charges | B39: Subscription charges | C39: ='Line Item Mapping'!H71 -> 0.0148 | D39: =IF($C$38=0,0,C39/$C$38) -> 0.48677895 | E39: =C39/$C$49 -> 0.00035617777
A40: Software / SaaS reseller | B40: CloudStuff Technology Private Limited | C40: ='Line Item Mapping'!H66 -> 0.01196 | D40: =IF($C$38=0,0,C40/$C$38) -> 0.39337002 | E40: =C40/$C$49 -> 0.00028783014
A41: Tech / SaaS vendor | B41: Wittybyte Technologies Private Limited | C41: ='Line Item Mapping'!H67 -> 0.00211 | D41: =IF($C$38=0,0,C41/$C$38) -> 0.069398891 | E41: =C41/$C$49 -> 5.0779398e-05
...

Sheet Quarterly Paid Media
A1: Quarterly Ad Spend – Platform-level (FY24–FY26)
A2: INR in crores (converted from finance sheet INR millions ÷ 10) · Quarterly split available from finance only for ad platforms & vendor lines (not for SMS, branding, influencer, freebies, others)
A4: Platform | B4: Q1FY24 | C4: Q2FY24 | D4: Q3FY24 | E4: Q4FY24 | F4: Q1FY25 | G4: Q2FY25 | H4: Q3FY25 | I4: Q4FY25 | J4: Q1FY26 | K4: Q2FY26 | L4: Q3FY26 | M4: Q4FY26
A5: Performance Marketing – D2C Website | B5: =SUM(B6:B7) -> 2.976425 | C5: =SUM(C6:C7) -> 3.0551367 | D5: =SUM(D6:D7) -> 3.3653559 | E5: =SUM(E6:E7) -> 3.6011986 | F5: =SUM(F6:F7) -> 3.7075795 | G5: =SUM(G6:G7) -> 4.258839 | H5: =SUM(H6:H7) -> 4.6119556 | I5: =SUM(I6:I7) -> 5.174836 | ... M5: =SUM(M6:M7) -> 7.7386514
A6: Meta ads | B6: 1.8987883 | C6: 2.090611 | D6: 2.2495992 | E6: 2.600002 | F6: 2.6960759 | G6: 3.2295242 | H6: 3.4198615 | I6: 3.9118405 | J6: 3.9684046 | K6: 4.5758122 | L6: 4.9321366 | M6: 6.3353302
A7: Google ads | B7: 1.0776367 | C7: 0.96452572 | D7: 1.1157567 | E7: 1.0011966 | F7: 1.0115035 | G7: 1.0293149 | H7: 1.1920941 | I7: 1.2629955 | J7: 1.2275543 | K7: 1.2764756 | L7: 1.1208314 | M7: 1.4033212
A8: Marketplace Ads | B8: =SUM(B9:B12) -> 0.67648045 | C8: =SUM(C9:C12) -> 0.43021715 | D8: =SUM(D9:D12) -> 0.33506431 | E8: =SUM(E9:E12) -> 0.27476024 | F8: =SUM(F9:F12) -> 0.42905028 | G8: =SUM(G9:G12) -> 1.0701394 | H8: =SUM(H9:H12) -> 0.94826152 | I8: =SUM(I9:I12) -> 1.365265 | ... M8: =SUM(M9:M12) -> 3.6455185
A9: Amazon sponsored ads | B9: 0.56256375 | C9: 0.32781466 | D9: 0.21166187 | E9: 0.19369876 | F9: 0.37177635 | G9: 0.96915683 | H9: 0.83830727 | I9: 1.2769768 | J9: 1.912699 | K9: 2.7580355 | L9: 2.8622946 | M9: 3.1704551
A10: Myntra ads | B10: 0 | C10: 0 | D10: 0 | E10: 0 | F10: 0 | G10: 0 | H10: 0 | I10: 0 | J10: 0.11918909 | K10: 0.14023694 | L10: 0.23144175 | M10: 0.29173935
A11: Flipkart ads | B11: 0.042918395 | C11: 0.066647388 | D11: 0.10411614 | E11: 0.051030483 | F11: 0.034378027 | G11: 0.068410457 | H11: 0.067627553 | I11: 0.04742286 | J11: 0.091896898 | K11: 0.10560336 | L11: 0.11245459 | M11: 0.019262965
A12: Nykaa ads | B12: 0.0709983 | C12: 0.0357551 | D12: 0.0192863 | E12: 0.030031 | F12: 0.0228959 | G12: 0.0325721 | H12: 0.0423267 | I12: 0.0408654 | J12: 0.035772 | K12: 0.0219881 | L12: 0.0079296 | M12: 0.16406107
A13: Quick Commerce Ads | B13: =SUM(B14:B16) -> 0 | C13: =SUM(C14:C16) -> 0 | D13: =SUM(D14:D16) -> 0 | E13: =SUM(E14:E16) -> 0 | F13: =SUM(F14:F16) -> 0 | G13: =SUM(G14:G16) -> 0 | H13: =SUM(H14:H16) -> 0 | I13: =SUM(I14:I16) -> 0.215 | ... M13: =SUM(M14:M16) -> 0.4961709
A14: Blinkit ads | B14: 0 | C14: 0 | D14: 0 | E14: 0 | F14: 0 | G14: 0 | H14: 0 | I14: 0 | J14: 0 | K14: 0.03 | L14: 0.26 | M14: 0.41
A15: Zepto ads | B15: 0 | C15: 0 | D15: 0 | E15: 0 | F15: 0 | G15: 0 | H15: 0 | I15: 0.215 | J15: 0.01831856 | K15: 0 | L15: 0.05 | M15: 0.0425
A16: Swiggy Instamart ads | B16: 0 | C16: 0 | D16: 0 | E16: 0 | F16: 0 | G16: 0 | H16: 0 | I16: 0 | J16: 0 | K16: 0 | L16: 0 | M16: 0.0436709

Sheet FY27 Budget
A1: FY27 Marketing Budget by Bucket
A2: INR in crores (converted from finance sheet INR millions ÷ 10) · Yellow cells to be filled by marketing (FY27 budget is not in the finance data shared)
A4: Marketing bucket | B4: FY26 actual (₹ Cr) | C4: FY27 budget (₹ Cr) | D4: Growth vs FY26 | E4: FY27 mix % | F4: Planned key activities
A5: Performance Marketing – D2C Website | B5: ='Bucket Summary'!E5 -> 24.839866 | D5: =IF(OR(B5=0,C5=""),"",C5/B5-1) | E5: =IF(C$16=0,"",C5/C$16)
A6: Marketplace Ads | B6: ='Bucket Summary'!E6 -> 12.04506 | D6: =IF(OR(B6=0,C6=""),"",C6/B6-1) | E6: =IF(C$16=0,"",C6/C$16)
A7: Quick Commerce Ads | B7: ='Bucket Summary'!E7 -> 0.85448946 | D7: =IF(OR(B7=0,C7=""),"",C7/B7-1) | E7: =IF(C$16=0,"",C7/C$16)
A8: Affiliate & Ad Networks | B8: ='Bucket Summary'!E8 -> 0.81849705 | D8: =IF(OR(B8=0,C8=""),"",C8/B8-1) | E8: =IF(C$16=0,"",C8/C$16)
A9: Other Digital Media | B9: ='Bucket Summary'!E9 -> 0.02 | D9: =IF(OR(B9=0,C9=""),"",C9/B9-1) | E9: =IF(C$16=0,"",C9/C$16)
A10: CRM, Retention & SMS | B10: ='Bucket Summary'!E10 -> 1.116663 | D10: =IF(OR(B10=0,C10=""),"",C10/B10-1) | E10: =IF(C$16=0,"",C10/C$16)
A11: Brand, Content & Production | B11: ='Bucket Summary'!E11 -> 1.0772397 | D11: =IF(OR(B11=0,C11=""),"",C11/B11-1) | E11: =IF(C$16=0,"",C11/C$16)
A12: Influencer & Creator Marketing | B12: ='Bucket Summary'!E12 -> 0.3794468 | D12: =IF(OR(B12=0,C12=""),"",C12/B12-1) | E12: =IF(C$16=0,"",C12/C$16)
A13: Sampling, Freebies & Gifting | B13: ='Bucket Summary'!E13 -> 0.13714212 | D13: =IF(OR(B13=0,C13=""),"",C13/B13-1) | E13: =IF(C$16=0,"",C13/C$16)
A14: Marketing Tools & Subscriptions | B14: ='Bucket Summary'!E14 -> 0.030403944 | D14: =IF(OR(B14=0,C14=""),"",C14/B14-1) | E14: =IF(C$16=0,"",C14/C$16)
A15: Misc. / Unallocated | B15: ='Bucket Summary'!E15 -> 0.23347675 | D15: =IF(OR(B15=0,C15=""),"",C15/B15-1) | E15: =IF(C$16=0,"",C15/C$16)
A16: Total | B16: =SUM(B5:B15) -> 41.552285 | C16: =SUM(C5:C15) -> 0 | D16: =IF(C16=0,"",C16/B16-1)
A18: Example: Performance Marketing – D2C Website → FY27 budget 30.00, activities "Meta prospecting + retargeting, Google Search/PMax/Shopping".

Sheet Line Item Mapping
A1: Advertisement expense – line-item mapping to marketing buckets
A2: INR in crores (converted from finance sheet INR millions ÷ 10) · Actuals · Source: Finance "Advertisement" sheet (Management information)
A4: # | B4: Vendor / line item (as per finance) | C4: Marketing bucket | D4: Activity | E4: Mapping confidence | F4: FY24 (₹ Cr) | G4: FY25 (₹ Cr) | H4: FY26 (₹ Cr)
A5: 1 | B5: Facebook | C5: Performance Marketing – D2C Website | D5: Meta ads | E5: High | F5: 8.8390005 | G5: 13.257302 | H5: 19.811684
A6: 2 | B6: Google | C6: Performance Marketing – D2C Website | D6: Google ads | E6: High | F6: 4.1591157 | G6: 4.495908 | H6: 5.0281825
A7: 3 | B7: Amazon | C7: Marketplace Ads | D7: Amazon sponsored ads | E7: High | F7: 1.295739 | G7: 3.4562172 | H7: 10.703484
A8: 4 | B8: Myntra Designs Pvt. Ltd. | C8: Marketplace Ads | D8: Myntra ads | E8: High | F8: 0 | G8: 0 | H8: 0.78260712
A9: 5 | B9: Flipkart | C9: Marketplace Ads | D9: Flipkart ads | E9: High | F9: 0.26471241 | G9: 0.2178389 | H9: 0.32921782
A10: 6 | B10: Nykaa | C10: Marketplace Ads | D10: Nykaa ads | E10: High | F10: 0.1560707 | G10: 0.1386601 | H10: 0.22975077
A11: 7 | B11: Blink Commerce Pvt. Ltd. | C11: Quick Commerce Ads | D11: Blinkit ads | E11: High | F11: 0 | G11: 0 | H11: 0.7
A12: 8 | B12: Zepto Limited | C12: Quick Commerce Ads | D12: Zepto ads | E12: High | F12: 0 | G12: 0.215 | H12: 0.11081856
A13: 9 | B13: Swiggy Limited | C13: Quick Commerce Ads | D13: Swiggy Instamart ads | E13: High | F13: 0 | G13: 0 | H13: 0.0436709
A14: 10 | B14: Admitad Media Private Limited | C14: Affiliate & Ad Networks | D14: Affiliate network | E14: High | F14: 0.76407541 | G14: 0.65622132 | H14: 0.79997
A15: 11 | B15: Pixel Viilage E-Sources Private Limited | C15: Affiliate & Ad Networks | D15: Digital ad vendor | E15: Low | F15: 0 | G15: 0 | H15: 0.0075
A16: 12 | B16: INSPIRELABS SOLUTIONS PVT LTD | C16: Affiliate & Ad Networks | D16: Ad-tech / performance vendor | E16: Low | F16: 0 | G16: 0.016758311 | H16: 0.011027047
... A77: 73 | B77: Unreconciled difference | C77: Misc. / Unallocated | D77: Unreconciled difference (per finance) | E77: High | F77: 0.14721743 | G77: 0 | H77: 0.38326202
B78: Total | F78: =SUM(F5:F77) -> 18.43356 | G78: =SUM(G5:G77) -> 25.988431 | H78: =SUM(H5:H77) -> 41.552285
B79: Per finance sheet total | F79: 18.43356 | G79: 25.988431 | H79: 41.552285
B80: Check (should be 0) | F80: =F78-F79 -> 0 | G80: =G78-G79 -> 0 | H80: =H78-H79 -> 0
B82: Blue = values copied from finance sheet. Orange-shaded confidence = vendor nature not obvious from name; please confirm with finance/marketing and change the bucket in column C if needed – all summaries update automatically.
