Workbook

Sheet Summary
A1: Widget effectiveness tracker - summary
A2: Cumulative since each widget's go-live, counting only days with actuals filled, so planned and actual cover the same days. % to plan: green ≥100%, amber 80-99%, red <80%.
A4: Widget | B4: Placement | C4: Go-live | D4: Days live (with actuals) | E4: ATC events - plan | F4: ATC events - actual | G4: % to plan | H4: ATC users - plan | I4: ATC users - actual | J4: % to plan | K4: Widget orders - plan | L4: Widget orders - actual | M4: % to plan | N4: Attributed rev - plan (₹) | O4: Attributed rev - actual (₹) | P4: % to plan | Q4: Net incr rev - plan (₹) | R4: Net incr rev - actual est. (₹) | S4: % to plan | T4: Steady-state net incr rev / day (₹)
A5: =Inputs!C6 -> Build Your Stack | B5: =Inputs!C7 -> PDP | C5: =Inputs!C9 -> 46301 | D5: =COUNTIFS('BYS Daily'!$C$6:$C$98,1,'BYS Daily'!$G$6:$G$98,"<>") -> 0 | E5: =SUMIFS('BYS Daily'!$F$6:$F$98,'BYS Daily'!$C$6:$C$98,1,'BYS Daily'!$G$6:$G$98,"<>") -> 0 | F5: =SUMIFS('BYS Daily'!$G$6:$G$98,'BYS Daily'!$C$6:$C$98,1,'BYS Daily'!$G$6:$G$98,"<>") -> 0 | G5: =IF(E5=0,"",F5/E5) | H5: =SUMIFS('BYS Daily'!$I$6:$I$98,'BYS Daily'!$C$6:$C$98,1,'BYS Daily'!$G$6:$G$98,"<>") -> 0 | I5: =SUMIFS('BYS Daily'!$J$6:$J$98,'BYS Daily'!$C$6:$C$98,1,'BYS Daily'!$G$6:$G$98,"<>") -> 0 | J5: =IF(H5=0,"",I5/H5) | K5: =SUMIFS('BYS Daily'!$N$6:$N$98,'BYS Daily'!$C$6:$C$98,1,'BYS Daily'!$G$6:$G$98,"<>") -> 0 | L5: =SUMIFS('BYS Daily'!$O$6:$O$98,'BYS Daily'!$C$6:$C$98,1,'BYS Daily'!$G$6:$G$98,"<>") -> 0 | M5: =IF(K5=0,"",L5/K5) | N5: =SUMIFS('BYS Daily'!$R$6:$R$98,'BYS Daily'!$C$6:$C$98,1,'BYS Daily'!$G$6:$G$98,"<>") -> 0 | O5: =SUMIFS('BYS Daily'!$S$6:$S$98,'BYS Daily'!$C$6:$C$98,1,'BYS Daily'!$G$6:$G$98,"<>") -> 0 | P5: =IF(N5=0,"",O5/N5) | Q5: =SUMIFS('BYS Daily'!$U$6:$U$98,'BYS Daily'!$C$6:$C$98,1,'BYS Daily'!$G$6:$G$98,"<>") -> 0 | R5: =SUMIFS('BYS Daily'!$V$6:$V$98,'BYS Daily'!$C$6:$C$98,1,'BYS Daily'!$G$6:$G$98,"<>") -> 0 | S5: =IF(Q5=0,"",R5/Q5) | T5: =Inputs!C36 -> 25545.648
A6: =Inputs!D6 -> CYP | B6: =Inputs!D7 -> TBC (assumed cart / pre-checkout) | C6: =Inputs!D9 -> 46303 | D6: =COUNTIFS('CYP Daily'!$C$6:$C$98,1,'CYP Daily'!$G$6:$G$98,"<>") -> 0 | E6: =SUMIFS('CYP Daily'!$F$6:$F$98,'CYP Daily'!$C$6:$C$98,1,'CYP Daily'!$G$6:$G$98,"<>") -> 0 | F6: =SUMIFS('CYP Daily'!$G$6:$G$98,'CYP Daily'!$C$6:$C$98,1,'CYP Daily'!$G$6:$G$98,"<>") -> 0 | G6: =IF(E6=0,"",F6/E6) | H6: =SUMIFS('CYP Daily'!$I$6:$I$98,'CYP Daily'!$C$6:$C$98,1,'CYP Daily'!$G$6:$G$98,"<>") -> 0 | I6: =SUMIFS('CYP Daily'!$J$6:$J$98,'CYP Daily'!$C$6:$C$98,1,'CYP Daily'!$G$6:$G$98,"<>") -> 0 | J6: =IF(H6=0,"",I6/H6) | K6: =SUMIFS('CYP Daily'!$N$6:$N$98,'CYP Daily'!$C$6:$C$98,1,'CYP Daily'!$G$6:$G$98,"<>") -> 0 | L6: =SUMIFS('CYP Daily'!$O$6:$O$98,'CYP Daily'!$C$6:$C$98,1,'CYP Daily'!$G$6:$G$98,"<>") -> 0 | M6: =IF(K6=0,"",L6/K6) | N6: =SUMIFS('CYP Daily'!$R$6:$R$98,'CYP Daily'!$C$6:$C$98,1,'CYP Daily'!$G$6:$G$98,"<>") -> 0 | O6: =SUMIFS('CYP Daily'!$S$6:$S$98,'CYP Daily'!$C$6:$C$98,1,'CYP Daily'!$G$6:$G$98,"<>") -> 0 | P6: =IF(N6=0,"",O6/N6) | Q6: =SUMIFS('CYP Daily'!$U$6:$U$98,'CYP Daily'!$C$6:$C$98,1,'CYP Daily'!$G$6:$G$98,"<>") -> 0 | R6: =SUMIFS('CYP Daily'!$V$6:$V$98,'CYP Daily'!$C$6:$C$98,1,'CYP Daily'!$G$6:$G$98,"<>") -> 0 | S6: =IF(Q6=0,"",R6/Q6) | T6: =Inputs!D36 -> 21000
A7: =Inputs!E6 -> You May Also Like (new logic) | B7: =Inputs!E7 -> PDP | C7: =Inputs!E9 -> 46310 | D7: =COUNTIFS('YMAL Daily'!$C$6:$C$98,1,'YMAL Daily'!$G$6:$G$98,"<>") -> 0 | E7: =SUMIFS('YMAL Daily'!$F$6:$F$98,'YMAL Daily'!$C$6:$C$98,1,'YMAL Daily'!$G$6:$G$98,"<>") -> 0 | F7: =SUMIFS('YMAL Daily'!$G$6:$G$98,'YMAL Daily'!$C$6:$C$98,1,'YMAL Daily'!$G$6:$G$98,"<>") -> 0 | G7: =IF(E7=0,"",F7/E7) | H7: =SUMIFS('YMAL Daily'!$I$6:$I$98,'YMAL Daily'!$C$6:$C$98,1,'YMAL Daily'!$G$6:$G$98,"<>") -> 0 | I7: =SUMIFS('YMAL Daily'!$J$6:$J$98,'YMAL Daily'!$C$6:$C$98,1,'YMAL Daily'!$G$6:$G$98,"<>") -> 0 | J7: =IF(H7=0,"",I7/H7) | K7: =SUMIFS('YMAL Daily'!$N$6:$N$98,'YMAL Daily'!$C$6:$C$98,1,'YMAL Daily'!$G$6:$G$98,"<>") -> 0 | L7: =SUMIFS('YMAL Daily'!$O$6:$O$98,'YMAL Daily'!$C$6:$C$98,1,'YMAL Daily'!$G$6:$G$98,"<>") -> 0 | M7: =IF(K7=0,"",L7/K7) | N7: =SUMIFS('YMAL Daily'!$R$6:$R$98,'YMAL Daily'!$C$6:$C$98,1,'YMAL Daily'!$G$6:$G$98,"<>") -> 0 | O7: =SUMIFS('YMAL Daily'!$S$6:$S$98,'YMAL Daily'!$C$6:$C$98,1,'YMAL Daily'!$G$6:$G$98,"<>") -> 0 | P7: =IF(N7=0,"",O7/N7) | Q7: =SUMIFS('YMAL Daily'!$U$6:$U$98,'YMAL Daily'!$C$6:$C$98,1,'YMAL Daily'!$G$6:$G$98,"<>") -> 0 | R7: =SUMIFS('YMAL Daily'!$V$6:$V$98,'YMAL Daily'!$C$6:$C$98,1,'YMAL Daily'!$G$6:$G$98,"<>") -> 0 | S7: =IF(Q7=0,"",R7/Q7) | T7: =Inputs!E36 -> 9886.4126
A8: TOTAL | E8: =SUM(E5:E7) -> 0 | F8: =SUM(F5:F7) -> 0 | G8: =IF(E8=0,"",F8/E8) | H8: =SUM(H5:H7) -> 0 | I8: =SUM(I5:I7) -> 0 | J8: =IF(H8=0,"",I8/H8) | K8: =SUM(K5:K7) -> 0 | L8: =SUM(L5:L7) -> 0 | M8: =IF(K8=0,"",L8/K8) | N8: =SUM(N5:N7) -> 0 | O8: =SUM(O5:O7) -> 0 | P8: =IF(N8=0,"",O8/N8) | Q8: =SUM(Q5:Q7) -> 0 | R8: =SUM(R5:R7) -> 0 | S8: =IF(Q8=0,"",R8/Q8) | T8: =SUM(T5:T7) -> 56432.061
A11: Site-level read (since first go-live vs baseline)
A12: Metric | B12: Baseline / day (30-Sep to 5-Oct) | C12: Since 6-Oct / day (actual) | D12: Change | E12: Plan / day | F12: Var vs plan
A13: PDP viewers | B13: =Inputs!C45 -> 35391.833 | C13: =IFERROR(AVERAGEIFS('Site Daily'!$E$6:$E$98,'Site Daily'!$A$6:$A$98,">="&Inputs!$C$9,'Site Daily'!$E$6:$E$98,"<>"),"") | D13: =IF(OR(C13="",B13=0),"",C13/B13-1)
A14: Orders | B14: =Inputs!C47 -> 1383.6667 | C14: =IFERROR(AVERAGEIFS('Site Daily'!$G$6:$G$98,'Site Daily'!$A$6:$A$98,">="&Inputs!$C$9,'Site Daily'!$G$6:$G$98,"<>"),"") | D14: =IF(OR(C14="",B14=0),"",C14/B14-1) | E14: =Inputs!C47 -> 1383.6667 | F14: =IF(OR(C14="",E14=0),"",C14/E14-1)
A15: Revenue (₹) | B15: =Inputs!C48 -> 2792289.7 | C15: =IFERROR(AVERAGEIFS('Site Daily'!$H$6:$H$98,'Site Daily'!$A$6:$A$98,">="&Inputs!$C$9,'Site Daily'!$H$6:$H$98,"<>"),"") | D15: =IF(OR(C15="",B15=0),"",C15/B15-1) | E15: =Inputs!C48+Inputs!C52 -> 2848721.7 | F15: =IF(OR(C15="",E15=0),"",C15/E15-1)
A16: AOV (₹) | B16: =Inputs!C49 -> 2018.0364 | C16: =IFERROR(C15/C14,"") | D16: =IF(OR(C16="",B16=0),"",C16/B16-1) | E16: =Inputs!C49+Inputs!C54 -> 2058.8208 | F16: =IF(OR(C16="",E16=0),"",C16/E16-1)
A17: Orders / PDP viewers | B17: =IFERROR(Inputs!C47/Inputs!C45,0) -> 0.039095648 | C17: =IFERROR(C14/C13,"") | D17: =IF(OR(C17="",B17=0),"",C17/B17-1)
A18: Revenue / PDP viewer (₹) | B18: =IFERROR(Inputs!C48/Inputs!C45,0) -> 78.89644 | C18: =IFERROR(C15/C13,"") | D18: =IF(OR(C18="",B18=0),"",C18/B18-1)
A20: Site AOV/revenue moves with traffic mix, offers and Diwali - use it as a sanity check only. Judge each widget on its own sheet (ATC users, orders, attributed revenue) and, ideally, a holdout.

Sheet Read Me
A1: How to use this tracker
A3: Purpose | B3: Track the 3 recommendation widgets - Build Your Stack (BYS), CYP and You May Also Like (YMAL) - daily, planned vs actual, from each go-live date.
A4: Tabs | B4: Summary (scorecard) · Inputs (go-live dates, baseline, plan levers, planned impact) · Site Daily · BYS / CYP / YMAL Daily · Plan by Week · Metric Dictionary.
A5: Daily routine | B5: Next morning, for the closed day: fill blue cells on Site Daily (D-H, S) and on each live widget sheet (G, J, O, Q). Everything else calculates.
A6: Colour legend | B6: Blue text = input · Green text = link to another sheet · Black = formula · Yellow fill = plan lever to agree · Green rows on widget sheets = widget live.
A7: Changing a go-live | B7: Edit Inputs row 9. Planned numbers on every sheet shift automatically (with a linear ramp from Inputs row 29).
A8: Planned numbers | B8: Built from the 30-Sep to 5-Oct MoEngage baseline x plan levers (Inputs rows 23-29). The earlier per-widget sizing was not available in this session - overwrite the yellow levers with those numbers and the whole tracker updates.
A9: Baseline caveat | B9: add_to_cart and begin_checkout tracking changed on 29/30-Sep (events ~3x with flat PDP views). The baseline uses only 30-Sep onwards. Do not compare against older data.
A10: Open items | B10: 1) CYP needs a unique referer before go-live, or it cannot be measured. 2) Confirm YMAL = dp/cross-sell. 3) Add widget impression/click events. 4) A 10-20% holdout per widget would replace the incrementality assumption with a measured number.
A11: Data source | B11: MoEngage (workspace: DailyObjects). Queries for each column are in the header comments on the widget sheets and in the Metric Dictionary.

Sheet Inputs
A1: Widget plan inputs & planned impact
A2: Blue = editable input · Green = linked from another sheet · Black = formula. Yellow-filled cells are the plan levers to agree with the team.
A4: Field | B4: Unit | C4: BYS | D4: CYP | E4: YMAL | F4: Source / note
A5: 1. Initiative definition & timeline
A6: Widget | C6: Build Your Stack | D6: CYP | E6: You May Also Like (new logic) | F6: CYP full name / placement to be confirmed by product.
A7: Placement | C7: PDP | D7: TBC (assumed cart / pre-checkout) | E7: PDP
A8: MoEngage identifier | B8: add_to_cart.referer | C8: dp/quick-sell | D8: TBC - ask tech to tag a unique referer before go-live | E8: dp/cross-sell | F8: BYS identified from today's post-launch spike (only referer that jumped after 1:20 PM). YMAL assumed to be the existing PDP cross-sell rail - confirm.
A9: Go-live date | B9: date | C9: 46301 | D9: 46303 | E9: 46310 | F9: BYS live 6-Oct ~1:20 PM. CYP Thu 8-Oct (Fri 9-Oct fallback - change this cell). YMAL logic mid-Oct. Every planned number on the daily sheets keys off this date.
A10: What changes at go-live | C10: SKU recommendations added to BYS for a large share of PDPs (coverage expansion) | D10: New widget | E10: Recommendation logic upgrade on the existing rail
A12: 2. Baseline (pre-launch) - links to 30-Sep to 5-Oct rows on each daily sheet
A13: Widget ATC events / day | B13: events | C13: =AVERAGE('BYS Daily'!G6:G11) -> 566.5 | D13: 0 | E13: =AVERAGE('YMAL Daily'!G6:G11) -> 946.33333 | F13: MoEngage behavior: add_to_cart, filter referer = identifier, daily. CYP = 0 (new widget).
A14: Widget ATC users / day | B14: users | C14: =AVERAGE('BYS Daily'!J6:J11) -> 419.16667 | D14: 0 | E14: =AVERAGE('YMAL Daily'!J6:J11) -> 706.33333 | F14: MoEngage behavior, analysis type = users, same filter.
A15: Widget ATC value / day | B15: ₹ | C15: =AVERAGE('BYS Daily'!Q6:Q11) -> 752888.83 | D15: 0 | E15: =AVERAGE('YMAL Daily'!Q6:Q11) -> 856060.17 | F15: Sum of add_to_cart.value for widget ATCs (₹, item value added to cart).
A16: Value per widget ATC user | B16: ₹ | C16: =IFERROR(C15/C14,0) -> 1796.1563 | D16: =IFERROR(D15/D14,0) -> 0 | E16: =IFERROR(E15/E14,0) -> 1211.9776
A17: Widget ATC user → order (24h) | B17: % | C17: =IFERROR(SUM('BYS Daily'!O6:O11)/SUM('BYS Daily'!J6:J11),0) -> 0.11252485 | D17: 0 | E17: =IFERROR(SUM('YMAL Daily'!O6:O11)/SUM('YMAL Daily'!J6:J11),0) -> 0.045540349 | F17: MoEngage funnel: add_to_cart (referer filter) → purchase, 24h window, unique users.
A18: Widget-driven orders / day | B18: orders | C18: =C14*C17 -> 47.166667 | D18: =D14*D17 -> 0 | E18: =E14*E17 -> 32.166667
A19: Widget-attributed revenue / day | B19: ₹ | C19: =C18*C16 -> 84718.704 | D19: =D18*D16 -> 0 | E19: =E18*E16 -> 38985.279 | F19: Orders x value per ATC user (proxy for revenue of widget-added items in converted carts).
A20: ATC events per ATC user | B20: x | C20: =IFERROR(C13/C14,0) -> 1.3514911 | D20: =IFERROR(D13/D14,0) -> 0 | E20: =IFERROR(E13/E14,0) -> 1.3397829
A22: 3. Plan levers (steady state, after ramp-up) - yellow = agree with team
A23: ATC users multiplier vs baseline | B23: x | C23: 1.6 | E23: 1.25 | F23: BYS: coverage expansion; 6-Oct early read was +18% users / 2.3-3x events in first hours. YMAL: better relevance. CYP: n/a (new) - set target users directly in row 24.
A24: Target widget ATC users / day | B24: users | C24: =C14*C23 -> 670.66667 | D24: 250 | E24: =E14*E23 -> 882.91667 | F24: CYP assumption: ~2% of daily ATC users (~12k/day) add from CYP.
A25: Target ATC events per ATC user | B25: x | C25: 1.6 | D25: 1.2 | E25: 1.4 | F25: BYS should lift this (multi-item stacks). Baseline: BYS 1.35, YMAL 1.34.
A26: Target ATC user → order (24h) | B26: % | C26: 0.1125 | D26: 0.2 | E26: 0.055 | F26: BYS held at baseline 11.3%. CYP is late-funnel so higher intent (assumed 20%). YMAL 4.6% → 5.5% with better relevance.
A27: Target value per widget ATC user | B27: ₹ | C27: 1800 | D27: 700 | E27: 1210 | F27: BYS/YMAL ≈ baseline. CYP assumes accessory-led add-ons (~₹700).
A28: Incrementality (share of uplift that is net new) | B28: % | C28: 0.5 | D28: 0.6 | E28: 0.5 | F28: Discount for cannibalisation of items users would have bought anyway. Replace with holdout read when available.
A29: Ramp-up days to steady state | B29: days | C29: 3 | D29: 5 | E29: 7 | F29: Linear ramp from baseline to target over these days after go-live.
A31: 4. Planned impact per day at steady state
A32: Planned widget ATC events / day | B32: events | C32: =C24*C25 -> 1073.0667 | D32: =D24*D25 -> 300 | E32: =E24*E25 -> 1236.0833
A33: Planned widget-driven orders / day | B33: orders | C33: =C24*C26 -> 75.45 | D33: =D24*D26 -> 50 | E33: =E24*E26 -> 48.560417
A34: Planned widget-attributed revenue / day | B34: ₹ | C34: =C33*C27 -> 135810 | D34: =D33*D27 -> 35000 | E34: =E33*E27 -> 58758.104
A35: Uplift in attributed revenue vs baseline / day | B35: ₹ | C35: =C34-C19 -> 51091.296 | D35: =D34-D19 -> 35000 | E35: =E34-E19 -> 19772.825
A36: Planned NET incremental revenue / day | B36: ₹ | C36: =C35*C28 -> 25545.648 | D36: =D35*D28 -> 21000 | E36: =E35*E28 -> 9886.4126 | F36: Uplift x incrementality. This is the number to hold each widget to.
A37: Planned NET incremental revenue / 30 days | B37: ₹ | C37: =C36*30 -> 766369.44 | D37: =D36*30 -> 630000 | E37: =E36*30 -> 296592.38
A38: Planned AOV uplift | B38: ₹ per order | C38: =IFERROR(C36/$C$47,0) -> 18.462285 | D38: =IFERROR(D36/$C$47,0) -> 15.177066 | E38: =IFERROR(E36/$C$47,0) -> 7.1450826 | F38: AOV uplift assumes widget items attach to orders that would have happened anyway (no new orders).
A39: Planned AOV uplift | B39: % | C39: =IFERROR(C38/$C$49,0) -> 0.0091486383 | D39: =IFERROR(D38/$C$49,0) -> 0.0075207097 | E39: =IFERROR(E38/$C$49,0) -> 0.0035406114
A40: Net incremental revenue as % of site revenue | B40: % | C40: =IFERROR(C36/$C$48,0) -> 0.0091486383 | D40: =IFERROR(D36/$C$48,0) -> 0.0075207097 | E40: =IFERROR(E36/$C$48,0) -> 0.0035406114
A41: Planned widget ATC events vs baseline | B41: % | C41: =IFERROR(C32/C13-1,0) -> 0.89420418 | D41: ="new" -> new | E41: =IFERROR(E32/E13-1,0) -> 0.30618175
A43: 5. Site baseline (30-Sep to 5-Oct, per day) - links to 'Site Daily'
A44: PDP views / day | B44: events | C44: =AVERAGE('Site Daily'!D6:D11) -> 129515.5 | F44: Baseline starts 30-Sep because add_to_cart / begin_checkout tracking changed on 29/30-Sep (ATC events ~3x overnight with flat PDP views). Pre-30-Sep data is not comparable.
A45: PDP viewers / day | B45: users | C45: =AVERAGE('Site Daily'!E6:E11) -> 35391.833
...

Sheet Site Daily
A1: Site-level daily view - PDP funnel, revenue, AOV (planned vs actual)
A2: Fill blue columns daily from MoEngage (day must be closed). Planned = baseline + sum of live widgets' planned net incremental revenue. Planned is flat (no weekday / festive seasonality) - read variance against the widget sheets, not just here. Diwali (8-Nov) will inflate actuals.
A4: Status | D4: ACTUALS - site funnel (fill blue) | M4: PLAN vs ACTUAL | S4: Guardrail
A5: Date | B5: Day | C5: Widgets live | D5: PDP views | E5: PDP viewers | F5: All ATC users | G5: Orders | H5: Revenue (₹) | I5: AOV (₹) | J5: ATC users / PDP viewers | K5: Orders / PDP viewers | L5: Revenue / PDP viewer (₹) | M5: Planned revenue (₹) | N5: Revenue var vs plan | O5: Planned AOV (₹) | P5: AOV var vs plan | Q5: Widget net incr. rev - planned (₹) | R5: Widget net incr. rev - actual est. (₹) | S5: Main PDP ATC events (referer = dp) | T5: Notes
A6: 46295 | B6: =TEXT(A6,"ddd") -> Wed | C6: =('BYS Daily'!C6=1)+('CYP Daily'!C6=1)+('YMAL Daily'!C6=1) -> 0 | D6: 119492 | E6: 34505 | F6: 12602 | G6: 1379 | H6: 2644422.9 | I6: =IF(G6="","",IFERROR(H6/G6,"")) -> 1917.6381 | J6: =IF(E6="","",IFERROR(F6/E6,"")) -> 0.36522243 | K6: =IF(E6="","",IFERROR(G6/E6,"")) -> 0.039965222 | L6: =IF(E6="","",IFERROR(H6/E6,"")) -> 76.638832 | M6: =Inputs!$C$48+Q6 -> 2792289.7 | N6: =IF(H6="","",IFERROR(H6/M6-1,"")) -> -0.052955378 | O6: =IFERROR(M6/Inputs!$C$47,0) -> 2018.0364 | P6: =IF(I6="","",IFERROR(I6/O6-1,"")) -> -0.04975049 | Q6: ='BYS Daily'!U6+'CYP Daily'!U6+'YMAL Daily'!U6 -> 0 | R6: =IF(AND('BYS Daily'!V6="",'CYP Daily'!V6="",'YMAL Daily'!V6=""),"",N('BYS Daily'!V6)+N('CYP Daily'!V6)+N('YMAL Daily'!V6)) | S6: 18963
A7: 46296 | B7: =TEXT(A7,"ddd") -> Thu | C7: =('BYS Daily'!C7=1)+('CYP Daily'!C7=1)+('YMAL Daily'!C7=1) -> 0 | D7: 120770 | E7: 34173 | F7: 12240 | G7: 1276 | H7: 2404727.3 | I7: =IF(G7="","",IFERROR(H7/G7,"")) -> 1884.5825 | J7: =IF(E7="","",IFERROR(F7/E7,"")) -> 0.35817751 | K7: =IF(E7="","",IFERROR(G7/E7,"")) -> 0.03733942 | L7: =IF(E7="","",IFERROR(H7/E7,"")) -> 70.369218 | M7: =Inputs!$C$48+Q7 -> 2792289.7 | N7: =IF(H7="","",IFERROR(H7/M7-1,"")) -> -0.13879734 | O7: =IFERROR(M7/Inputs!$C$47,0) -> 2018.0364 | P7: =IF(I7="","",IFERROR(I7/O7-1,"")) -> -0.066130549 | Q7: ='BYS Daily'!U7+'CYP Daily'!U7+'YMAL Daily'!U7 -> 0 | R7: =IF(AND('BYS Daily'!V7="",'CYP Daily'!V7="",'YMAL Daily'!V7=""),"",N('BYS Daily'!V7)+N('CYP Daily'!V7)+N('YMAL Daily'!V7)) | S7: 17733
A8: 46297 | B8: =TEXT(A8,"ddd") -> Fri | C8: =('BYS Daily'!C8=1)+('CYP Daily'!C8=1)+('YMAL Daily'!C8=1) -> 0 | D8: 138639 | E8: 38042 | F8: 14006 | G8: 1508 | H8: 3166751 | I8: =IF(G8="","",IFERROR(H8/G8,"")) -> 2099.9675 | J8: =IF(E8="","",IFERROR(F8/E8,"")) -> 0.36817202 | K8: =IF(E8="","",IFERROR(G8/E8,"")) -> 0.039640397 | L8: =IF(E8="","",IFERROR(H8/E8,"")) -> 83.243547 | M8: =Inputs!$C$48+Q8 -> 2792289.7 | N8: =IF(H8="","",IFERROR(H8/M8-1,"")) -> 0.13410549 | O8: =IFERROR(M8/Inputs!$C$47,0) -> 2018.0364 | P8: =IF(I8="","",IFERROR(I8/O8-1,"")) -> 0.040599443 | Q8: ='BYS Daily'!U8+'CYP Daily'!U8+'YMAL Daily'!U8 -> 0 | R8: =IF(AND('BYS Daily'!V8="",'CYP Daily'!V8="",'YMAL Daily'!V8=""),"",N('BYS Daily'!V8)+N('CYP Daily'!V8)+N('YMAL Daily'!V8)) | S8: 20592
A9: 46298 | B9: =TEXT(A9,"ddd") -> Sat | C9: =('BYS Daily'!C9=1)+('CYP Daily'!C9=1)+('YMAL Daily'!C9=1) -> 0 | D9: 131730 | E9: 34527 | F9: 11229 | G9: 1346 | H9: 2880679.7 | I9: =IF(G9="","",IFERROR(H9/G9,"")) -> 2140.1781 | J9: =IF(E9="","",IFERROR(F9/E9,"")) -> 0.32522374 | K9: =IF(E9="","",IFERROR(G9/E9,"")) -> 0.038983984 | L9: =IF(E9="","",IFERROR(H9/E9,"")) -> 83.432666 | M9: =Inputs!$C$48+Q9 -> 2792289.7 | N9: =IF(H9="","",IFERROR(H9/M9-1,"")) -> 0.031655031 | O9: =IFERROR(M9/Inputs!$C$47,0) -> 2018.0364 | P9: =IF(I9="","",IFERROR(I9/O9-1,"")) -> 0.060525021 | Q9: ='BYS Daily'!U9+'CYP Daily'!U9+'YMAL Daily'!U9 -> 0 | R9: =IF(AND('BYS Daily'!V9="",'CYP Daily'!V9="",'YMAL Daily'!V9=""),"",N('BYS Daily'!V9)+N('CYP Daily'!V9)+N('YMAL Daily'!V9)) | S9: 16637
A10: 46299 | B10: =TEXT(A10,"ddd") -> Sun | C10: =('BYS Daily'!C10=1)+('CYP Daily'!C10=1)+('YMAL Daily'!C10=1) -> 0 | D10: 142710 | E10: 36847 | F10: 11940 | G10: 1417 | H10: 2913660.8 | I10: =IF(G10="","",IFERROR(H10/G10,"")) -> 2056.2179 | J10: =IF(E10="","",IFERROR(F10/E10,"")) -> 0.32404266 | K10: =IF(E10="","",IFERROR(G10/E10,"")) -> 0.038456319 | L10: =IF(E10="","",IFERROR(H10/E10,"")) -> 79.074572 | M10: =Inputs!$C$48+Q10 -> 2792289.7 | N10: =IF(H10="","",IFERROR(H10/M10-1,"")) -> 0.04346652 | O10: =IFERROR(M10/Inputs!$C$47,0) -> 2018.0364 | P10: =IF(I10="","",IFERROR(I10/O10-1,"")) -> 0.018920143 | Q10: ='BYS Daily'!U10+'CYP Daily'!U10+'YMAL Daily'!U10 -> 0 | R10: =IF(AND('BYS Daily'!V10="",'CYP Daily'!V10="",'YMAL Daily'!V10=""),"",N('BYS Daily'!V10)+N('CYP Daily'!V10)+N('YMAL Daily'!V10)) | S10: 17774
A11: 46300 | B11: =TEXT(A11,"ddd") -> Mon | C11: =('BYS Daily'!C11=1)+('CYP Daily'!C11=1)+('YMAL Daily'!C11=1) -> 0 | D11: 123752 | E11: 34257 | F11: 11668 | G11: 1376 | H11: 2743496.3 | I11: =IF(G11="","",IFERROR(H11/G11,"")) -> 1993.82 | J11: =IF(E11="","",IFERROR(F11/E11,"")) -> 0.34060192 | K11: =IF(E11="","",IFERROR(G11/E11,"")) -> 0.040166973 | L11: =IF(E11="","",IFERROR(H11/E11,"")) -> 80.085713 | M11: =Inputs!$C$48+Q11 -> 2792289.7 | N11: =IF(H11="","",IFERROR(H11/M11-1,"")) -> -0.017474324 | O11: =IFERROR(M11/Inputs!$C$47,0) -> 2018.0364 | P11: =IF(I11="","",IFERROR(I11/O11-1,"")) -> -0.011999981 | Q11: ='BYS Daily'!U11+'CYP Daily'!U11+'YMAL Daily'!U11 -> 0 | R11: =IF(AND('BYS Daily'!V11="",'CYP Daily'!V11="",'YMAL Daily'!V11=""),"",N('BYS Daily'!V11)+N('CYP Daily'!V11)+N('YMAL Daily'!V11)) | S11: 16430
A12: 46301 | B12: =TEXT(A12,"ddd") -> Tue | C12: =('BYS Daily'!C12=1)+('CYP Daily'!C12=1)+('YMAL Daily'!C12=1) -> 1 | I12: =IF(G12="","",IFERROR(H12/G12,"")) | J12: =IF(E12="","",IFERROR(F12/E12,"")) | K12: =IF(E12="","",IFERROR(G12/E12,"")) | L12: =IF(E12="","",IFERROR(H12/E12,"")) | M12: =Inputs!$C$48+Q12 -> 2800794 | N12: =IF(H12="","",IFERROR(H12/M12-1,"")) | O12: =IFERROR(M12/Inputs!$C$47,0) -> 2024.1826 | P12: =IF(I12="","",IFERROR(I12/O12-1,"")) | Q12: ='BYS Daily'!U12+'CYP Daily'!U12+'YMAL Daily'!U12 -> 8504.385 | R12: =IF(AND('BYS Daily'!V12="",'CYP Daily'!V12="",'YMAL Daily'!V12=""),"",N('BYS Daily'!V12)+N('CYP Daily'!V12)+N('YMAL Daily'!V12))
A13: 46302 | B13: =TEXT(A13,"ddd") -> Wed | C13: =('BYS Daily'!C13=1)+('CYP Daily'!C13=1)+('YMAL Daily'!C13=1) -> 1 | I13: =IF(G13="","",IFERROR(H13/G13,"")) | J13: =IF(E13="","",IFERROR(F13/E13,"")) | K13: =IF(E13="","",IFERROR(G13/E13,"")) | L13: =IF(E13="","",IFERROR(H13/E13,"")) | M13: =Inputs!$C$48+Q13 -> 2809309.3 | N13: =IF(H13="","",IFERROR(H13/M13-1,"")) | O13: =IFERROR(M13/Inputs!$C$47,0) -> 2030.3367 | P13: =IF(I13="","",IFERROR(I13/O13-1,"")) | Q13: ='BYS Daily'!U13+'CYP Daily'!U13+'YMAL Daily'!U13 -> 17019.602 | R13: =IF(AND('BYS Daily'!V13="",'CYP Daily'!V13="",'YMAL Daily'!V13=""),"",N('BYS Daily'!V13)+N('CYP Daily'!V13)+N('YMAL Daily'!V13))
A14: 46303 | B14: =TEXT(A14,"ddd") -> Thu | C14: =('BYS Daily'!C14=1)+('CYP Daily'!C14=1)+('YMAL Daily'!C14=1) -> 2 | I14: =IF(G14="","",IFERROR(H14/G14,"")) | J14: =IF(E14="","",IFERROR(F14/E14,"")) | K14: =IF(E14="","",IFERROR(G14/E14,"")) | L14: =IF(E14="","",IFERROR(H14/E14,"")) | M14: =Inputs!$C$48+Q14 -> 2818003.3 | N14: =IF(H14="","",IFERROR(H14/M14-1,"")) | O14: =IFERROR(M14/Inputs!$C$47,0) -> 2036.6201 | P14: =IF(I14="","",IFERROR(I14/O14-1,"")) | Q14: ='BYS Daily'!U14+'CYP Daily'!U14+'YMAL Daily'!U14 -> 25713.648 | R14: =IF(AND('BYS Daily'!V14="",'CYP Daily'!V14="",'YMAL Daily'!V14=""),"",N('BYS Daily'!V14)+N('CYP Daily'!V14)+N('YMAL Daily'!V14))
A15: 46304 | B15: =TEXT(A15,"ddd") -> Fri | C15: =('BYS Daily'!C15=1)+('CYP Daily'!C15=1)+('YMAL Daily'!C15=1) -> 2 | I15: =IF(G15="","",IFERROR(H15/G15,"")) | J15: =IF(E15="","",IFERROR(F15/E15,"")) | K15: =IF(E15="","",IFERROR(G15/E15,"")) | L15: =IF(E15="","",IFERROR(H15/E15,"")) | M15: =Inputs!$C$48+Q15 -> 2819179.3 | N15: =IF(H15="","",IFERROR(H15/M15-1,"")) | O15: =IFERROR(M15/Inputs!$C$47,0) -> 2037.47 | P15: =IF(I15="","",IFERROR(I15/O15-1,"")) | Q15: ='BYS Daily'!U15+'CYP Daily'!U15+'YMAL Daily'!U15 -> 26889.648 | R15: =IF(AND('BYS Daily'!V15="",'CYP Daily'!V15="",'YMAL Daily'!V15=""),"",N('BYS Daily'!V15)+N('CYP Daily'!V15)+N('YMAL Daily'!V15))
A16: 46305 | B16: =TEXT(A16,"ddd") -> Sat | C16: =('BYS Daily'!C16=1)+('CYP Daily'!C16=1)+('YMAL Daily'!C16=1) -> 2 | I16: =IF(G16="","",IFERROR(H16/G16,"")) | J16: =IF(E16="","",IFERROR(F16/E16,"")) | K16: =IF(E16="","",IFERROR(G16/E16,"")) | L16: =IF(E16="","",IFERROR(H16/E16,"")) | M16: =Inputs!$C$48+Q16 -> 2822371.3 | N16: =IF(H16="","",IFERROR(H16/M16-1,"")) | O16: =IFERROR(M16/Inputs!$C$47,0) -> 2039.7769 | P16: =IF(I16="","",IFERROR(I16/O16-1,"")) | Q16: ='BYS Daily'!U16+'CYP Daily'!U16+'YMAL Daily'!U16 -> 30081.648 | R16: =IF(AND('BYS Daily'!V16="",'CYP Daily'!V16="",'YMAL Daily'!V16=""),"",N('BYS Daily'!V16)+N('CYP Daily'!V16)+N('YMAL Daily'!V16))
A17: 46306 | B17: =TEXT(A17,"ddd") -> Sun | C17: =('BYS Daily'!C17=1)+('CYP Daily'!C17=1)+('YMAL Daily'!C17=1) -> 2 | I17: =IF(G17="","",IFERROR(H17/G17,"")) | J17: =IF(E17="","",IFERROR(F17/E17,"")) | K17: =IF(E17="","",IFERROR(G17/E17,"")) | L17: =IF(E17="","",IFERROR(H17/E17,"")) | M17: =Inputs!$C$48+Q17 -> 2828587.3 | N17: =IF(H17="","",IFERROR(H17/M17-1,"")) | O17: =IFERROR(M17/Inputs!$C$47,0) -> 2044.2693 | P17: =IF(I17="","",IFERROR(I17/O17-1,"")) | Q17: ='BYS Daily'!U17+'CYP Daily'!U17+'YMAL Daily'!U17 -> 36297.648 | R17: =IF(AND('BYS Daily'!V17="",'CYP Daily'!V17="",'YMAL Daily'!V17=""),"",N('BYS Daily'!V17)+N('CYP Daily'!V17)+N('YMAL Daily'!V17))
A18: 46307 | B18: =TEXT(A18,"ddd") -> Mon | C18: =('BYS Daily'!C18=1)+('CYP Daily'!C18=1)+('YMAL Daily'!C18=1) -> 2 | I18: =IF(G18="","",IFERROR(H18/G18,"")) | J18: =IF(E18="","",IFERROR(F18/E18,"")) | K18: =IF(E18="","",IFERROR(G18/E18,"")) | L18: =IF(E18="","",IFERROR(H18/E18,"")) | M18: =Inputs!$C$48+Q18 -> 2838835.3 | N18: =IF(H18="","",IFERROR(H18/M18-1,"")) | O18: =IFERROR(M18/Inputs!$C$47,0) -> 2051.6757 | P18: =IF(I18="","",IFERROR(I18/O18-1,"")) | Q18: ='BYS Daily'!U18+'CYP Daily'!U18+'YMAL Daily'!U18 -> 46545.648 | R18: =IF(AND('BYS Daily'!V18="",'CYP Daily'!V18="",'YMAL Daily'!V18=""),"",N('BYS Daily'!V18)+N('CYP Daily'!V18)+N('YMAL Daily'!V18))
A19: 46308 | B19: =TEXT(A19,"ddd") -> Tue | C19: =('BYS Daily'!C19=1)+('CYP Daily'!C19=1)+('YMAL Daily'!C19=1) -> 2 | I19: =IF(G19="","",IFERROR(H19/G19,"")) | J19: =IF(E19="","",IFERROR(F19/E19,"")) | K19: =IF(E19="","",IFERROR(G19/E19,"")) | L19: =IF(E19="","",IFERROR(H19/E19,"")) | M19: =Inputs!$C$48+Q19 -> 2838835.3 | N19: =IF(H19="","",IFERROR(H19/M19-1,"")) | O19: =IFERROR(M19/Inputs!$C$47,0) -> 2051.6757 | P19: =IF(I19="","",IFERROR(I19/O19-1,"")) | Q19: ='BYS Daily'!U19+'CYP Daily'!U19+'YMAL Daily'!U19 -> 46545.648 | R19: =IF(AND('BYS Daily'!V19="",'CYP Daily'!V19="",'YMAL Daily'!V19=""),"",N('BYS Daily'!V19)+N('CYP Daily'!V19)+N('YMAL Daily'!V19))
A20: 46309 | B20: =TEXT(A20,"ddd") -> Wed | C20: =('BYS Daily'!C20=1)+('CYP Daily'!C20=1)+('YMAL Daily'!C20=1) -> 2 | I20: =IF(G20="","",IFERROR(H20/G20,"")) | J20: =IF(E20="","",IFERROR(F20/E20,"")) | K20: =IF(E20="","",IFERROR(G20/E20,"")) | L20: =IF(E20="","",IFERROR(H20/E20,"")) | M20: =Inputs!$C$48+Q20 -> 2838835.3 | N20: =IF(H20="","",IFERROR(H20/M20-1,"")) | O20: =IFERROR(M20/Inputs!$C$47,0) -> 2051.6757 | P20: =IF(I20="","",IFERROR(I20/O20-1,"")) | Q20: ='BYS Daily'!U20+'CYP Daily'!U20+'YMAL Daily'!U20 -> 46545.648 | R20: =IF(AND('BYS Daily'!V20="",'CYP Daily'!V20="",'YMAL Daily'!V20=""),"",N('BYS Daily'!V20)+N('CYP Daily'!V20)+N('YMAL Daily'!V20))
A21: 46310 | B21: =TEXT(A21,"ddd") -> Thu | C21: =('BYS Daily'!C21=1)+('CYP Daily'!C21=1)+('YMAL Daily'!C21=1) -> 3 | I21: =IF(G21="","",IFERROR(H21/G21,"")) | J21: =IF(E21="","",IFERROR(F21/E21,"")) | K21: =IF(E21="","",IFERROR(G21/E21,"")) | L21: =IF(E21="","",IFERROR(H21/E21,"")) | M21: =Inputs!$C$48+Q21 -> 2840125.7 | N21: =IF(H21="","",IFERROR(H21/M21-1,"")) | O21: =IFERROR(M21/Inputs!$C$47,0) -> 2052.6083 | P21: =IF(I21="","",IFERROR(I21/O21-1,"")) | Q21: ='BYS Daily'!U21+'CYP Daily'!U21+'YMAL Daily'!U21 -> 47836.057 | R21: =IF(AND('BYS Daily'!V21="",'CYP Daily'!V21="",'YMAL Daily'!V21=""),"",N('BYS Daily'!V21)+N('CYP Daily'!V21)+N('YMAL Daily'!V21))
A22: 46311 | B22: =TEXT(A22,"ddd") -> Fri | C22: =('BYS Daily'!C22=1)+('CYP Daily'!C22=1)+('YMAL Daily'!C22=1) -> 3 | I22: =IF(G22="","",IFERROR(H22/G22,"")) | J22: =IF(E22="","",IFERROR(F22/E22,"")) | K22: =IF(E22="","",IFERROR(G22/E22,"")) | L22: =IF(E22="","",IFERROR(H22/E22,"")) | M22: =Inputs!$C$48+Q22 -> 2841456.8 | N22: =IF(H22="","",IFERROR(H22/M22-1,"")) | O22: =IFERROR(M22/Inputs!$C$47,0) -> 2053.5703 | P22: =IF(I22="","",IFERROR(I22/O22-1,"")) | Q22: ='BYS Daily'!U22+'CYP Daily'!U22+'YMAL Daily'!U22 -> 49167.16 | R22: =IF(AND('BYS Daily'!V22="",'CYP Daily'!V22="",'YMAL Daily'!V22=""),"",N('BYS Daily'!V22)+N('CYP Daily'!V22)+N('YMAL Daily'!V22))
A23: 46312 | B23: =TEXT(A23,"ddd") -> Sat | C23: =('BYS Daily'!C23=1)+('CYP Daily'!C23=1)+('YMAL Daily'!C23=1) -> 3 | I23: =IF(G23="","",IFERROR(H23/G23,"")) | J23: =IF(E23="","",IFERROR(F23/E23,"")) | K23: =IF(E23="","",IFERROR(G23/E23,"")) | L23: =IF(E23="","",IFERROR(H23/E23,"")) | M23: =Inputs!$C$48+Q23 -> 2842828.6 | N23: =IF(H23="","",IFERROR(H23/M23-1,"")) | O23: =IFERROR(M23/Inputs!$C$47,0) -> 2054.5617 | P23: =IF(I23="","",IFERROR(I23/O23-1,"")) | Q23: ='BYS Daily'!U23+'CYP Daily'!U23+'YMAL Daily'!U23 -> 50538.926 | R23: =IF(AND('BYS Daily'!V23="",'CYP Daily'!V23="",'YMAL Daily'!V23=""),"",N('BYS Daily'!V23)+N('CYP Daily'!V23)+N('YMAL Daily'!V23))
... A98: 46387 | B98: =TEXT(A98,"ddd") -> Thu | C98: =('BYS Daily'!C98=1)+('CYP Daily'!C98=1)+('YMAL Daily'!C98=1) -> 3 | I98: =IF(G98="","",IFERROR(H98/G98,"")) | J98: =IF(E98="","",IFERROR(F98/E98,"")) | K98: =IF(E98="","",IFERROR(G98/E98,"")) | L98: =IF(E98="","",IFERROR(H98/E98,"")) | M98: =Inputs!$C$48+Q98 -> 2848721.7 | N98: =IF(H98="","",IFERROR(H98/M98-1,"")) | O98: =IFERROR(M98/Inputs!$C$47,0) -> 2058.8208 | P98: =IF(I98="","",IFERROR(I98/O98-1,"")) | Q98: ='BYS Daily'!U98+'CYP Daily'!U98+'YMAL Daily'!U98 -> 56432.061 | R98: =IF(AND('BYS Daily'!V98="",'CYP Daily'!V98="",'YMAL Daily'!V98=""),"",N('BYS Daily'!V98)+N('CYP Daily'!V98)+N('YMAL Daily'!V98))

Sheet BYS Daily
A1: BYS - daily planned vs actual
A2: ="Identifier: "&Inputs!C8&" | Go-live: "&TEXT(Inputs!C9,"dd-mmm-yy")&" | Steady-state plan: "&TEXT(Inputs!C32,"#,##0")&" ATC events/day, ₹"&TEXT(Inputs!C36,"#,##0")&" net incremental revenue/day" -> Identifier: dp/quick-sell | Go-live: 06-Oct-26 | Steady-state plan: 1,073 ATC events/day, ₹25,546 net incremental revenue/day
A3: Fill blue columns G, J, O, Q (and W if removals are tracked) daily from MoEngage once the day closes. Rows before go-live are the baseline. Green rows = widget live.
A4: Status (auto from go-live date) | F4: Widget ATC events | I4: Widget ATC unique users | N4: Widget-driven orders (ATC user → purchase in 24h) | Q4: Revenue | W4: Guardrail
A5: Date | B5: Day | C5: Live? | D5: Day # live | E5: Ramp factor | F5: Planned | G5: Actual | H5: Var vs plan | I5: Planned | J5: Actual | K5: Var vs plan | L5: Items per ATC user | M5: ATC users per 1k PDP viewers | N5: Planned | O5: Actual | P5: ATC user→order % | Q5: Widget ATC value (₹) - actual | R5: Attributed revenue - planned (₹) | S5: Attributed revenue - actual (₹) | T5: Var vs plan | U5: NET incremental rev - planned (₹) | V5: NET incremental rev - actual est. (₹) | W5: Widget ATC removals (if tracked) | X5: Removal rate | Y5: Notes
A6: 46295 | B6: =TEXT(A6,"ddd") -> Wed | C6: =IF(A6>=Inputs!$C$9,1,0) -> 0 | D6: =IF(C6=1,A6-Inputs!$C$9+1,"") | E6: =IF(C6=1,MIN(1,D6/Inputs!$C$29),0) -> 0 | F6: =Inputs!$C$13+(Inputs!$C$32-Inputs!$C$13)*E6 -> 566.5 | G6: 469 | H6: =IF(G6="","",IFERROR(G6/F6-1,"")) -> -0.17210944 | I6: =Inputs!$C$14+(Inputs!$C$24-Inputs!$C$14)*E6 -> 419.16667 | J6: 374 | K6: =IF(J6="","",IFERROR(J6/I6-1,"")) -> -0.10775348 | L6: =IF(OR(G6="",J6=""),"",IFERROR(G6/J6,"")) -> 1.2540107 | M6: =IF(OR(J6="",'Site Daily'!E6=""),"",IFERROR(J6/'Site Daily'!E6*1000,"")) -> 10.839009 | N6: =I6*(Inputs!$C$17+(Inputs!$C$26-Inputs!$C$17)*E6) -> 47.166667 | O6: 51 | P6: =IF(OR(O6="",J6=""),"",IFERROR(O6/J6,"")) -> 0.13636364 | Q6: 614233 | R6: =N6*(Inputs!$C$16+(Inputs!$C$27-Inputs!$C$16)*E6) -> 84718.704 | S6: =IF(OR(O6="",Q6="",J6=""),"",IFERROR(O6*Q6/J6,"")) -> 83759.045 | T6: =IF(S6="","",IFERROR(S6/R6-1,"")) -> -0.011327584 | U6: =C6*(R6-Inputs!$C$19)*Inputs!$C$28 -> 0 | V6: =IF(OR(C6=0,S6=""),"",(S6-Inputs!$C$19)*Inputs!$C$28) | X6: =IF(OR(W6="",G6=""),"",IFERROR(W6/G6,""))
A7: 46296 | B7: =TEXT(A7,"ddd") -> Thu | C7: =IF(A7>=Inputs!$C$9,1,0) -> 0 | D7: =IF(C7=1,A7-Inputs!$C$9+1,"") | E7: =IF(C7=1,MIN(1,D7/Inputs!$C$29),0) -> 0 | F7: =Inputs!$C$13+(Inputs!$C$32-Inputs!$C$13)*E7 -> 566.5 | G7: 530 | H7: =IF(G7="","",IFERROR(G7/F7-1,"")) -> -0.064430715 | I7: =Inputs!$C$14+(Inputs!$C$24-Inputs!$C$14)*E7 -> 419.16667 | J7: 379 | K7: =IF(J7="","",IFERROR(J7/I7-1,"")) -> -0.09582505 | L7: =IF(OR(G7="",J7=""),"",IFERROR(G7/J7,"")) -> 1.3984169 | M7: =IF(OR(J7="",'Site Daily'!E7=""),"",IFERROR(J7/'Site Daily'!E7*1000,"")) -> 11.090627 | N7: =I7*(Inputs!$C$17+(Inputs!$C$26-Inputs!$C$17)*E7) -> 47.166667 | O7: 40 | P7: =IF(OR(O7="",J7=""),"",IFERROR(O7/J7,"")) -> 0.1055409 | Q7: 707477 | R7: =N7*(Inputs!$C$16+(Inputs!$C$27-Inputs!$C$16)*E7) -> 84718.704 | S7: =IF(OR(O7="",Q7="",J7=""),"",IFERROR(O7*Q7/J7,"")) -> 74667.757 | T7: =IF(S7="","",IFERROR(S7/R7-1,"")) -> -0.11863905 | U7: =C7*(R7-Inputs!$C$19)*Inputs!$C$28 -> 0 | V7: =IF(OR(C7=0,S7=""),"",(S7-Inputs!$C$19)*Inputs!$C$28) | X7: =IF(OR(W7="",G7=""),"",IFERROR(W7/G7,""))
A8: 46297 | B8: =TEXT(A8,"ddd") -> Fri | C8: =IF(A8>=Inputs!$C$9,1,0) -> 0 | D8: =IF(C8=1,A8-Inputs!$C$9+1,"") | E8: =IF(C8=1,MIN(1,D8/Inputs!$C$29),0) -> 0 | F8: =Inputs!$C$13+(Inputs!$C$32-Inputs!$C$13)*E8 -> 566.5 | G8: 703 | H8: =IF(G8="","",IFERROR(G8/F8-1,"")) -> 0.24095322 | I8: =Inputs!$C$14+(Inputs!$C$24-Inputs!$C$14)*E8 -> 419.16667 | J8: 519 | K8: =IF(J8="","",IFERROR(J8/I8-1,"")) -> 0.23817097 | L8: =IF(OR(G8="",J8=""),"",IFERROR(G8/J8,"")) -> 1.3545279 | M8: =IF(OR(J8="",'Site Daily'!E8=""),"",IFERROR(J8/'Site Daily'!E8*1000,"")) -> 13.642816 | N8: =I8*(Inputs!$C$17+(Inputs!$C$26-Inputs!$C$17)*E8) -> 47.166667 | O8: 49 | P8: =IF(OR(O8="",J8=""),"",IFERROR(O8/J8,"")) -> 0.094412331 | Q8: 932400 | R8: =N8*(Inputs!$C$16+(Inputs!$C$27-Inputs!$C$16)*E8) -> 84718.704 | S8: =IF(OR(O8="",Q8="",J8=""),"",IFERROR(O8*Q8/J8,"")) -> 88030.058 | T8: =IF(S8="","",IFERROR(S8/R8-1,"")) -> 0.039086458 | U8: =C8*(R8-Inputs!$C$19)*Inputs!$C$28 -> 0 | V8: =IF(OR(C8=0,S8=""),"",(S8-Inputs!$C$19)*Inputs!$C$28) | X8: =IF(OR(W8="",G8=""),"",IFERROR(W8/G8,""))
A9: 46298 | B9: =TEXT(A9,"ddd") -> Sat | C9: =IF(A9>=Inputs!$C$9,1,0) -> 0 | D9: =IF(C9=1,A9-Inputs!$C$9+1,"") | E9: =IF(C9=1,MIN(1,D9/Inputs!$C$29),0) -> 0 | F9: =Inputs!$C$13+(Inputs!$C$32-Inputs!$C$13)*E9 -> 566.5 | G9: 595 | H9: =IF(G9="","",IFERROR(G9/F9-1,"")) -> 0.050308914 | I9: =Inputs!$C$14+(Inputs!$C$24-Inputs!$C$14)*E9 -> 419.16667 | J9: 427 | K9: =IF(J9="","",IFERROR(J9/I9-1,"")) -> 0.018687873 | L9: =IF(OR(G9="",J9=""),"",IFERROR(G9/J9,"")) -> 1.3934426 | M9: =IF(OR(J9="",'Site Daily'!E9=""),"",IFERROR(J9/'Site Daily'!E9*1000,"")) -> 12.367133 | N9: =I9*(Inputs!$C$17+(Inputs!$C$26-Inputs!$C$17)*E9) -> 47.166667 | O9: 54 | P9: =IF(OR(O9="",J9=""),"",IFERROR(O9/J9,"")) -> 0.1264637 | Q9: 744113 | R9: =N9*(Inputs!$C$16+(Inputs!$C$27-Inputs!$C$16)*E9) -> 84718.704 | S9: =IF(OR(O9="",Q9="",J9=""),"",IFERROR(O9*Q9/J9,"")) -> 94103.283 | T9: =IF(S9="","",IFERROR(S9/R9-1,"")) -> 0.11077341 | U9: =C9*(R9-Inputs!$C$19)*Inputs!$C$28 -> 0 | V9: =IF(OR(C9=0,S9=""),"",(S9-Inputs!$C$19)*Inputs!$C$28) | X9: =IF(OR(W9="",G9=""),"",IFERROR(W9/G9,""))
A10: 46299 | B10: =TEXT(A10,"ddd") -> Sun | C10: =IF(A10>=Inputs!$C$9,1,0) -> 0 | D10: =IF(C10=1,A10-Inputs!$C$9+1,"") | E10: =IF(C10=1,MIN(1,D10/Inputs!$C$29),0) -> 0 | F10: =Inputs!$C$13+(Inputs!$C$32-Inputs!$C$13)*E10 -> 566.5 | G10: 579 | H10: =IF(G10="","",IFERROR(G10/F10-1,"")) -> 0.022065313 | I10: =Inputs!$C$14+(Inputs!$C$24-Inputs!$C$14)*E10 -> 419.16667 | J10: 410 | K10: =IF(J10="","",IFERROR(J10/I10-1,"")) -> -0.021868787 | L10: =IF(OR(G10="",J10=""),"",IFERROR(G10/J10,"")) -> 1.4121951 | M10: =IF(OR(J10="",'Site Daily'!E10=""),"",IFERROR(J10/'Site Daily'!E10*1000,"")) -> 11.127093 | N10: =I10*(Inputs!$C$17+(Inputs!$C$26-Inputs!$C$17)*E10) -> 47.166667 | O10: 43 | P10: =IF(OR(O10="",J10=""),"",IFERROR(O10/J10,"")) -> 0.10487805 | Q10: 800023 | R10: =N10*(Inputs!$C$16+(Inputs!$C$27-Inputs!$C$16)*E10) -> 84718.704 | S10: =IF(OR(O10="",Q10="",J10=""),"",IFERROR(O10*Q10/J10,"")) -> 83904.851 | T10: =IF(S10="","",IFERROR(S10/R10-1,"")) -> -0.0096065267 | U10: =C10*(R10-Inputs!$C$19)*Inputs!$C$28 -> 0 | V10: =IF(OR(C10=0,S10=""),"",(S10-Inputs!$C$19)*Inputs!$C$28) | X10: =IF(OR(W10="",G10=""),"",IFERROR(W10/G10,""))
A11: 46300 | B11: =TEXT(A11,"ddd") -> Mon | C11: =IF(A11>=Inputs!$C$9,1,0) -> 0 | D11: =IF(C11=1,A11-Inputs!$C$9+1,"") | E11: =IF(C11=1,MIN(1,D11/Inputs!$C$29),0) -> 0 | F11: =Inputs!$C$13+(Inputs!$C$32-Inputs!$C$13)*E11 -> 566.5 | G11: 523 | H11: =IF(G11="","",IFERROR(G11/F11-1,"")) -> -0.07678729 | I11: =Inputs!$C$14+(Inputs!$C$24-Inputs!$C$14)*E11 -> 419.16667 | J11: 406 | K11: =IF(J11="","",IFERROR(J11/I11-1,"")) -> -0.031411531 | L11: =IF(OR(G11="",J11=""),"",IFERROR(G11/J11,"")) -> 1.2881773 | M11: =IF(OR(J11="",'Site Daily'!E11=""),"",IFERROR(J11/'Site Daily'!E11*1000,"")) -> 11.851592 | N11: =I11*(Inputs!$C$17+(Inputs!$C$26-Inputs!$C$17)*E11) -> 47.166667 | O11: 46 | P11: =IF(OR(O11="",J11=""),"",IFERROR(O11/J11,"")) -> 0.11330049 | Q11: 719087 | R11: =N11*(Inputs!$C$16+(Inputs!$C$27-Inputs!$C$16)*E11) -> 84718.704 | S11: =IF(OR(O11="",Q11="",J11=""),"",IFERROR(O11*Q11/J11,"")) -> 81472.911 | T11: =IF(S11="","",IFERROR(S11/R11-1,"")) -> -0.038312583 | U11: =C11*(R11-Inputs!$C$19)*Inputs!$C$28 -> 0 | V11: =IF(OR(C11=0,S11=""),"",(S11-Inputs!$C$19)*Inputs!$C$28) | X11: =IF(OR(W11="",G11=""),"",IFERROR(W11/G11,""))
A12: 46301 | B12: =TEXT(A12,"ddd") -> Tue | C12: =IF(A12>=Inputs!$C$9,1,0) -> 1 | D12: =IF(C12=1,A12-Inputs!$C$9+1,"") -> 1 | E12: =IF(C12=1,MIN(1,D12/Inputs!$C$29),0) -> 0.33333333 | F12: =Inputs!$C$13+(Inputs!$C$32-Inputs!$C$13)*E12 -> 735.35556 | H12: =IF(G12="","",IFERROR(G12/F12-1,"")) | I12: =Inputs!$C$14+(Inputs!$C$24-Inputs!$C$14)*E12 -> 503 | K12: =IF(J12="","",IFERROR(J12/I12-1,"")) | L12: =IF(OR(G12="",J12=""),"",IFERROR(G12/J12,"")) | M12: =IF(OR(J12="",'Site Daily'!E12=""),"",IFERROR(J12/'Site Daily'!E12*1000,"")) | N12: =I12*(Inputs!$C$17+(Inputs!$C$26-Inputs!$C$17)*E12) -> 56.595833 | P12: =IF(OR(O12="",J12=""),"",IFERROR(O12/J12,"")) | R12: =N12*(Inputs!$C$16+(Inputs!$C$27-Inputs!$C$16)*E12) -> 101727.47 | S12: =IF(OR(O12="",Q12="",J12=""),"",IFERROR(O12*Q12/J12,"")) | T12: =IF(S12="","",IFERROR(S12/R12-1,"")) | U12: =C12*(R12-Inputs!$C$19)*Inputs!$C$28 -> 8504.385 | V12: =IF(OR(C12=0,S12=""),"",(S12-Inputs!$C$19)*Inputs!$C$28) | X12: =IF(OR(W12="",G12=""),"",IFERROR(W12/G12,""))
A13: 46302 | B13: =TEXT(A13,"ddd") -> Wed | C13: =IF(A13>=Inputs!$C$9,1,0) -> 1 | D13: =IF(C13=1,A13-Inputs!$C$9+1,"") -> 2 | E13: =IF(C13=1,MIN(1,D13/Inputs!$C$29),0) -> 0.66666667 | F13: =Inputs!$C$13+(Inputs!$C$32-Inputs!$C$13)*E13 -> 904.21111 | H13: =IF(G13="","",IFERROR(G13/F13-1,"")) | I13: =Inputs!$C$14+(Inputs!$C$24-Inputs!$C$14)*E13 -> 586.83333 | K13: =IF(J13="","",IFERROR(J13/I13-1,"")) | L13: =IF(OR(G13="",J13=""),"",IFERROR(G13/J13,"")) | M13: =IF(OR(J13="",'Site Daily'!E13=""),"",IFERROR(J13/'Site Daily'!E13*1000,"")) | N13: =I13*(Inputs!$C$17+(Inputs!$C$26-Inputs!$C$17)*E13) -> 66.023611 | P13: =IF(OR(O13="",J13=""),"",IFERROR(O13/J13,"")) | R13: =N13*(Inputs!$C$16+(Inputs!$C$27-Inputs!$C$16)*E13) -> 118757.91 | S13: =IF(OR(O13="",Q13="",J13=""),"",IFERROR(O13*Q13/J13,"")) | T13: =IF(S13="","",IFERROR(S13/R13-1,"")) | U13: =C13*(R13-Inputs!$C$19)*Inputs!$C$28 -> 17019.602 | V13: =IF(OR(C13=0,S13=""),"",(S13-Inputs!$C$19)*Inputs!$C$28) | X13: =IF(OR(W13="",G13=""),"",IFERROR(W13/G13,""))
A14: 46303 | B14: =TEXT(A14,"ddd") -> Thu | C14: =IF(A14>=Inputs!$C$9,1,0) -> 1 | D14: =IF(C14=1,A14-Inputs!$C$9+1,"") -> 3 | E14: =IF(C14=1,MIN(1,D14/Inputs!$C$29),0) -> 1 | F14: =Inputs!$C$13+(Inputs!$C$32-Inputs!$C$13)*E14 -> 1073.0667 | H14: =IF(G14="","",IFERROR(G14/F14-1,"")) | I14: =Inputs!$C$14+(Inputs!$C$24-Inputs!$C$14)*E14 -> 670.66667 | K14: =IF(J14="","",IFERROR(J14/I14-1,"")) | L14: =IF(OR(G14="",J14=""),"",IFERROR(G14/J14,"")) | M14: =IF(OR(J14="",'Site Daily'!E14=""),"",IFERROR(J14/'Site Daily'!E14*1000,"")) | N14: =I14*(Inputs!$C$17+(Inputs!$C$26-Inputs!$C$17)*E14) -> 75.45 | P14: =IF(OR(O14="",J14=""),"",IFERROR(O14/J14,"")) | R14: =N14*(Inputs!$C$16+(Inputs!$C$27-Inputs!$C$16)*E14) -> 135810 | S14: =IF(OR(O14="",Q14="",J14=""),"",IFERROR(O14*Q14/J14,"")) | T14: =IF(S14="","",IFERROR(S14/R14-1,"")) | U14: =C14*(R14-Inputs!$C$19)*Inputs!$C$28 -> 25545.648 | V14: =IF(OR(C14=0,S14=""),"",(S14-Inputs!$C$19)*Inputs!$C$28) | X14: =IF(OR(W14="",G14=""),"",IFERROR(W14/G14,""))
A15: 46304 | B15: =TEXT(A15,"ddd") -> Fri | C15: =IF(A15>=Inputs!$C$9,1,0) -> 1 | D15: =IF(C15=1,A15-Inputs!$C$9+1,"") -> 4 | E15: =IF(C15=1,MIN(1,D15/Inputs!$C$29),0) -> 1 | F15: =Inputs!$C$13+(Inputs!$C$32-Inputs!$C$13)*E15 -> 1073.0667 | H15: =IF(G15="","",IFERROR(G15/F15-1,"")) | I15: =Inputs!$C$14+(Inputs!$C$24-Inputs!$C$14)*E15 -> 670.66667 | K15: =IF(J15="","",IFERROR(J15/I15-1,"")) | L15: =IF(OR(G15="",J15=""),"",IFERROR(G15/J15,"")) | M15: =IF(OR(J15="",'Site Daily'!E15=""),"",IFERROR(J15/'Site Daily'!E15*1000,"")) | N15: =I15*(Inputs!$C$17+(Inputs!$C$26-Inputs!$C$17)*E15) -> 75.45 | P15: =IF(OR(O15="",J15=""),"",IFERROR(O15/J15,"")) | R15: =N15*(Inputs!$C$16+(Inputs!$C$27-Inputs!$C$16)*E15) -> 135810 | S15: =IF(OR(O15="",Q15="",J15=""),"",IFERROR(O15*Q15/J15,"")) | T15: =IF(S15="","",IFERROR(S15/R15-1,"")) | U15: =C15*(R15-Inputs!$C$19)*Inputs!$C$28 -> 25545.648 | V15: =IF(OR(C15=0,S15=""),"",(S15-Inputs!$C$19)*Inputs!$C$28) | X15: =IF(OR(W15="",G15=""),"",IFERROR(W15/G15,""))
A16: 46305 | B16: =TEXT(A16,"ddd") -> Sat | C16: =IF(A16>=Inputs!$C$9,1,0) -> 1 | D16: =IF(C16=1,A16-Inputs!$C$9+1,"") -> 5 | E16: =IF(C16=1,MIN(1,D16/Inputs!$C$29),0) -> 1 | F16: =Inputs!$C$13+(Inputs!$C$32-Inputs!$C$13)*E16 -> 1073.0667 | H16: =IF(G16="","",IFERROR(G16/F16-1,"")) | I16: =Inputs!$C$14+(Inputs!$C$24-Inputs!$C$14)*E16 -> 670.66667 | K16: =IF(J16="","",IFERROR(J16/I16-1,"")) | L16: =IF(OR(G16="",J16=""),"",IFERROR(G16/J16,"")) | M16: =IF(OR(J16="",'Site Daily'!E16=""),"",IFERROR(J16/'Site Daily'!E16*1000,"")) | N16: =I16*(Inputs!$C$17+(Inputs!$C$26-Inputs!$C$17)*E16) -> 75.45 | P16: =IF(OR(O16="",J16=""),"",IFERROR(O16/J16,"")) | R16: =N16*(Inputs!$C$16+(Inputs!$C$27-Inputs!$C$16)*E16) -> 135810 | S16: =IF(OR(O16="",Q16="",J16=""),"",IFERROR(O16*Q16/J16,"")) | T16: =IF(S16="","",IFERROR(S16/R16-1,"")) | U16: =C16*(R16-Inputs!$C$19)*Inputs!$C$28 -> 25545.648 | V16: =IF(OR(C16=0,S16=""),"",(S16-Inputs!$C$19)*Inputs!$C$28) | X16: =IF(OR(W16="",G16=""),"",IFERROR(W16/G16,""))
A17: 46306 | B17: =TEXT(A17,"ddd") -> Sun | C17: =IF(A17>=Inputs!$C$9,1,0) -> 1 | D17: =IF(C17=1,A17-Inputs!$C$9+1,"") -> 6 | E17: =IF(C17=1,MIN(1,D17/Inputs!$C$29),0) -> 1 | F17: =Inputs!$C$13+(Inputs!$C$32-Inputs!$C$13)*E17 -> 1073.0667 | H17: =IF(G17="","",IFERROR(G17/F17-1,"")) | I17: =Inputs!$C$14+(Inputs!$C$24-Inputs!$C$14)*E17 -> 670.66667 | K17: =IF(J17="","",IFERROR(J17/I17-1,"")) | L17: =IF(OR(G17="",J17=""),"",IFERROR(G17/J17,"")) | M17: =IF(OR(J17="",'Site Daily'!E17=""),"",IFERROR(J17/'Site Daily'!E17*1000,"")) | N17: =I17*(Inputs!$C$17+(Inputs!$C$26-Inputs!$C$17)*E17) -> 75.45 | P17: =IF(OR(O17="",J17=""),"",IFERROR(O17/J17,"")) | R17: =N17*(Inputs!$C$16+(Inputs!$C$27-Inputs!$C$16)*E17) -> 135810 | S17: =IF(OR(O17="",Q17="",J17=""),"",IFERROR(O17*Q17/J17,"")) | T17: =IF(S17="","",IFERROR(S17/R17-1,"")) | U17: =C17*(R17-Inputs!$C$19)*Inputs!$C$28 -> 25545.648 | V17: =IF(OR(C17=0,S17=""),"",(S17-Inputs!$C$19)*Inputs!$C$28) | X17: =IF(OR(W17="",G17=""),"",IFERROR(W17/G17,""))
A18: 46307 | B18: =TEXT(A18,"ddd") -> Mon | C18: =IF(A18>=Inputs!$C$9,1,0) -> 1 | D18: =IF(C18=1,A18-Inputs!$C$9+1,"") -> 7 | E18: =IF(C18=1,MIN(1,D18/Inputs!$C$29),0) -> 1 | F18: =Inputs!$C$13+(Inputs!$C$32-Inputs!$C$13)*E18 -> 1073.0667 | H18: =IF(G18="","",IFERROR(G18/F18-1,"")) | I18: =Inputs!$C$14+(Inputs!$C$24-Inputs!$C$14)*E18 -> 670.66667 | K18: =IF(J18="","",IFERROR(J18/I18-1,"")) | L18: =IF(OR(G18="",J18=""),"",IFERROR(G18/J18,"")) | M18: =IF(OR(J18="",'Site Daily'!E18=""),"",IFERROR(J18/'Site Daily'!E18*1000,"")) | N18: =I18*(Inputs!$C$17+(Inputs!$C$26-Inputs!$C$17)*E18) -> 75.45 | P18: =IF(OR(O18="",J18=""),"",IFERROR(O18/J18,"")) | R18: =N18*(Inputs!$C$16+(Inputs!$C$27-Inputs!$C$16)*E18) -> 135810 | S18: =IF(OR(O18="",Q18="",J18=""),"",IFERROR(O18*Q18/J18,"")) | T18: =IF(S18="","",IFERROR(S18/R18-1,"")) | U18: =C18*(R18-Inputs!$C$19)*Inputs!$C$28 -> 25545.648 | V18: =IF(OR(C18=0,S18=""),"",(S18-Inputs!$C$19)*Inputs!$C$28) | X18: =IF(OR(W18="",G18=""),"",IFERROR(W18/G18,""))
A19: 46308 | B19: =TEXT(A19,"ddd") -> Tue | C19: =IF(A19>=Inputs!$C$9,1,0) -> 1 | D19: =IF(C19=1,A19-Inputs!$C$9+1,"") -> 8 | E19: =IF(C19=1,MIN(1,D19/Inputs!$C$29),0) -> 1 | F19: =Inputs!$C$13+(Inputs!$C$32-Inputs!$C$13)*E19 -> 1073.0667 | H19: =IF(G19="","",IFERROR(G19/F19-1,"")) | I19: =Inputs!$C$14+(Inputs!$C$24-Inputs!$C$14)*E19 -> 670.66667 | K19: =IF(J19="","",IFERROR(J19/I19-1,"")) | L19: =IF(OR(G19="",J19=""),"",IFERROR(G19/J19,"")) | M19: =IF(OR(J19="",'Site Daily'!E19=""),"",IFERROR(J19/'Site Daily'!E19*1000,"")) | N19: =I19*(Inputs!$C$17+(Inputs!$C$26-Inputs!$C$17)*E19) -> 75.45 | P19: =IF(OR(O19="",J19=""),"",IFERROR(O19/J19,"")) | R19: =N19*(Inputs!$C$16+(Inputs!$C$27-Inputs!$C$16)*E19) -> 135810 | S19: =IF(OR(O19="",Q19="",J19=""),"",IFERROR(O19*Q19/J19,"")) | T19: =IF(S19="","",IFERROR(S19/R19-1,"")) | U19: =C19*(R19-Inputs!$C$19)*Inputs!$C$28 -> 25545.648 | V19: =IF(OR(C19=0,S19=""),"",(S19-Inputs!$C$19)*Inputs!$C$28) | X19: =IF(OR(W19="",G19=""),"",IFERROR(W19/G19,""))
A20: 46309 | B20: =TEXT(A20,"ddd") -> Wed | C20: =IF(A20>=Inputs!$C$9,1,0) -> 1 | D20: =IF(C20=1,A20-Inputs!$C$9+1,"") -> 9 | E20: =IF(C20=1,MIN(1,D20/Inputs!$C$29),0) -> 1 | F20: =Inputs!$C$13+(Inputs!$C$32-Inputs!$C$13)*E20 -> 1073.0667 | H20: =IF(G20="","",IFERROR(G20/F20-1,"")) | I20: =Inputs!$C$14+(Inputs!$C$24-Inputs!$C$14)*E20 -> 670.66667 | K20: =IF(J20="","",IFERROR(J20/I20-1,"")) | L20: =IF(OR(G20="",J20=""),"",IFERROR(G20/J20,"")) | M20: =IF(OR(J20="",'Site Daily'!E20=""),"",IFERROR(J20/'Site Daily'!E20*1000,"")) | N20: =I20*(Inputs!$C$17+(Inputs!$C$26-Inputs!$C$17)*E20) -> 75.45 | P20: =IF(OR(O20="",J20=""),"",IFERROR(O20/J20,"")) | R20: =N20*(Inputs!$C$16+(Inputs!$C$27-Inputs!$C$16)*E20) -> 135810 | S20: =IF(OR(O20="",Q20="",J20=""),"",IFERROR(O20*Q20/J20,"")) | T20: =IF(S20="","",IFERROR(S20/R20-1,"")) | U20: =C20*(R20-Inputs!$C$19)*Inputs!$C$28 -> 25545.648 | V20: =IF(OR(C20=0,S20=""),"",(S20-Inputs!$C$19)*Inputs!$C$28) | X20: =IF(OR(W20="",G20=""),"",IFERROR(W20/G20,""))
A21: 46310 | B21: =TEXT(A21,"ddd") -> Thu | C21: =IF(A21>=Inputs!$C$9,1,0) -> 1 | D21: =IF(C21=1,A21-Inputs!$C$9+1,"") -> 10 | E21: =IF(C21=1,MIN(1,D21/Inputs!$C$29),0) -> 1 | F21: =Inputs!$C$13+(Inputs!$C$32-Inputs!$C$13)*E21 -> 1073.0667 | H21: =IF(G21="","",IFERROR(G21/F21-1,"")) | I21: =Inputs!$C$14+(Inputs!$C$24-Inputs!$C$14)*E21 -> 670.66667 | K21: =IF(J21="","",IFERROR(J21/I21-1,"")) | L21: =IF(OR(G21="",J21=""),"",IFERROR(G21/J21,"")) | M21: =IF(OR(J21="",'Site Daily'!E21=""),"",IFERROR(J21/'Site Daily'!E21*1000,"")) | N21: =I21*(Inputs!$C$17+(Inputs!$C$26-Inputs!$C$17)*E21) -> 75.45 | P21: =IF(OR(O21="",J21=""),"",IFERROR(O21/J21,"")) | R21: =N21*(Inputs!$C$16+(Inputs!$C$27-Inputs!$C$16)*E21) -> 135810 | S21: =IF(OR(O21="",Q21="",J21=""),"",IFERROR(O21*Q21/J21,"")) | T21: =IF(S21="","",IFERROR(S21/R21-1,"")) | U21: =C21*(R21-Inputs!$C$19)*Inputs!$C$28 -> 25545.648 | V21: =IF(OR(C21=0,S21=""),"",(S21-Inputs!$C$19)*Inputs!$C$28) | X21: =IF(OR(W21="",G21=""),"",IFERROR(W21/G21,""))
A22: 46311 | B22: =TEXT(A22,"ddd") -> Fri | C22: =IF(A22>=Inputs!$C$9,1,0) -> 1 | D22: =IF(C22=1,A22-Inputs!$C$9+1,"") -> 11 | E22: =IF(C22=1,MIN(1,D22/Inputs!$C$29),0) -> 1 | F22: =Inputs!$C$13+(Inputs!$C$32-Inputs!$C$13)*E22 -> 1073.0667 | H22: =IF(G22="","",IFERROR(G22/F22-1,"")) | I22: =Inputs!$C$14+(Inputs!$C$24-Inputs!$C$14)*E22 -> 670.66667 | K22: =IF(J22="","",IFERROR(J22/I22-1,"")) | L22: =IF(OR(G22="",J22=""),"",IFERROR(G22/J22,"")) | M22: =IF(OR(J22="",'Site Daily'!E22=""),"",IFERROR(J22/'Site Daily'!E22*1000,"")) | N22: =I22*(Inputs!$C$17+(Inputs!$C$26-Inputs!$C$17)*E22) -> 75.45 | P22: =IF(OR(O22="",J22=""),"",IFERROR(O22/J22,"")) | R22: =N22*(Inputs!$C$16+(Inputs!$C$27-Inputs!$C$16)*E22) -> 135810 | S22: =IF(OR(O22="",Q22="",J22=""),"",IFERROR(O22*Q22/J22,"")) | T22: =IF(S22="","",IFERROR(S22/R22-1,"")) | U22: =C22*(R22-Inputs!$C$19)*Inputs!$C$28 -> 25545.648 | V22: =IF(OR(C22=0,S22=""),"",(S22-Inputs!$C$19)*Inputs!$C$28) | X22: =IF(OR(W22="",G22=""),"",IFERROR(W22/G22,""))
A23: 46312 | B23: =TEXT(A23,"ddd") -> Sat | C23: =IF(A23>=Inputs!$C$9,1,0) -> 1 | D23: =IF(C23=1,A23-Inputs!$C$9+1,"") -> 12 | E23: =IF(C23=1,MIN(1,D23/Inputs!$C$29),0) -> 1 | F23: =Inputs!$C$13+(Inputs!$C$32-Inputs!$C$13)*E23 -> 1073.0667 | H23: =IF(G23="","",IFERROR(G23/F23-1,"")) | I23: =Inputs!$C$14+(Inputs!$C$24-Inputs!$C$14)*E23 -> 670.66667 | K23: =IF(J23="","",IFERROR(J23/I23-1,"")) | L23: =IF(OR(G23="",J23=""),"",IFERROR(G23/J23,"")) | M23: =IF(OR(J23="",'Site Daily'!E23=""),"",IFERROR(J23/'Site Daily'!E23*1000,"")) | N23: =I23*(Inputs!$C$17+(Inputs!$C$26-Inputs!$C$17)*E23) -> 75.45 | P23: =IF(OR(O23="",J23=""),"",IFERROR(O23/J23,"")) | R23: =N23*(Inputs!$C$16+(Inputs!$C$27-Inputs!$C$16)*E23) -> 135810 | S23: =IF(OR(O23="",Q23="",J23=""),"",IFERROR(O23*Q23/J23,"")) | T23: =IF(S23="","",IFERROR(S23/R23-1,"")) | U23: =C23*(R23-Inputs!$C$19)*Inputs!$C$28 -> 25545.648 | V23: =IF(OR(C23=0,S23=""),"",(S23-Inputs!$C$19)*Inputs!$C$28) | X23: =IF(OR(W23="",G23=""),"",IFERROR(W23/G23,""))
... A98: 46387 | B98: =TEXT(A98,"ddd") -> Thu | C98: =IF(A98>=Inputs!$C$9,1,0) -> 1 | D98: =IF(C98=1,A98-Inputs!$C$9+1,"") -> 87 | E98: =IF(C98=1,MIN(1,D98/Inputs!$C$29),0) -> 1 | F98: =Inputs!$C$13+(Inputs!$C$32-Inputs!$C$13)*E98 -> 1073.0667 | H98: =IF(G98="","",IFERROR(G98/F98-1,"")) | I98: =Inputs!$C$14+(Inputs!$C$24-Inputs!$C$14)*E98 -> 670.66667 | K98: =IF(J98="","",IFERROR(J98/I98-1,"")) | L98: =IF(OR(G98="",J98=""),"",IFERROR(G98/J98,"")) | M98: =IF(OR(J98="",'Site Daily'!E98=""),"",IFERROR(J98/'Site Daily'!E98*1000,"")) | N98: =I98*(Inputs!$C$17+(Inputs!$C$26-Inputs!$C$17)*E98) -> 75.45 | P98: =IF(OR(O98="",J98=""),"",IFERROR(O98/J98,"")) | R98: =N98*(Inputs!$C$16+(Inputs!$C$27-Inputs!$C$16)*E98) -> 135810 | S98: =IF(OR(O98="",Q98="",J98=""),"",IFERROR(O98*Q98/J98,"")) | T98: =IF(S98="","",IFERROR(S98/R98-1,"")) | U98: =C98*(R98-Inputs!$C$19)*Inputs!$C$28 -> 25545.648 | V98: =IF(OR(C98=0,S98=""),"",(S98-Inputs!$C$19)*Inputs!$C$28) | X98: =IF(OR(W98="",G98=""),"",IFERROR(W98/G98,""))

Sheet CYP Daily
A1: CYP - daily planned vs actual
A2: ="Identifier: "&Inputs!D8&" | Go-live: "&TEXT(Inputs!D9,"dd-mmm-yy")&" | Steady-state plan: "&TEXT(Inputs!D32,"#,##0")&" ATC events/day, ₹"&TEXT(Inputs!D36,"#,##0")&" net incremental revenue/day" -> Identifier: TBC - ask tech to tag a unique referer before go-live | Go-live: 08-Oct-26 | Steady-state plan: 300 ATC events/day, ₹21,000 net incremental revenue/day
A3: Fill blue columns G, J, O, Q (and W if removals are tracked) daily from MoEngage once the day closes. Rows before go-live are the baseline. Green rows = widget live.
A4: Status (auto from go-live date) | F4: Widget ATC events | I4: Widget ATC unique users | N4: Widget-driven orders (ATC user → purchase in 24h) | Q4: Revenue | W4: Guardrail
A5: Date | B5: Day | C5: Live? | D5: Day # live | E5: Ramp factor | F5: Planned | G5: Actual | H5: Var vs plan | I5: Planned | J5: Actual | K5: Var vs plan | L5: Items per ATC user | M5: ATC users per 1k PDP viewers | N5: Planned | O5: Actual | P5: ATC user→order % | Q5: Widget ATC value (₹) - actual | R5: Attributed revenue - planned (₹) | S5: Attributed revenue - actual (₹) | T5: Var vs plan | U5: NET incremental rev - planned (₹) | V5: NET incremental rev - actual est. (₹) | W5: Widget ATC removals (if tracked) | X5: Removal rate | Y5: Notes
A6: 46295 | B6: =TEXT(A6,"ddd") -> Wed | C6: =IF(A6>=Inputs!$D$9,1,0) -> 0 | D6: =IF(C6=1,A6-Inputs!$D$9+1,"") | E6: =IF(C6=1,MIN(1,D6/Inputs!$D$29),0) -> 0 | F6: =Inputs!$D$13+(Inputs!$D$32-Inputs!$D$13)*E6 -> 0 | H6: =IF(G6="","",IFERROR(G6/F6-1,"")) | I6: =Inputs!$D$14+(Inputs!$D$24-Inputs!$D$14)*E6 -> 0 | K6: =IF(J6="","",IFERROR(J6/I6-1,"")) | L6: =IF(OR(G6="",J6=""),"",IFERROR(G6/J6,"")) | M6: =IF(OR(J6="",'Site Daily'!E6=""),"",IFERROR(J6/'Site Daily'!E6*1000,"")) | N6: =I6*(Inputs!$D$17+(Inputs!$D$26-Inputs!$D$17)*E6) -> 0 | P6: =IF(OR(O6="",J6=""),"",IFERROR(O6/J6,"")) | R6: =N6*(Inputs!$D$16+(Inputs!$D$27-Inputs!$D$16)*E6) -> 0 | S6: =IF(OR(O6="",Q6="",J6=""),"",IFERROR(O6*Q6/J6,"")) | T6: =IF(S6="","",IFERROR(S6/R6-1,"")) | U6: =C6*(R6-Inputs!$D$19)*Inputs!$D$28 -> 0 | V6: =IF(OR(C6=0,S6=""),"",(S6-Inputs!$D$19)*Inputs!$D$28) | X6: =IF(OR(W6="",G6=""),"",IFERROR(W6/G6,""))
A7: 46296 | B7: =TEXT(A7,"ddd") -> Thu | C7: =IF(A7>=Inputs!$D$9,1,0) -> 0 | D7: =IF(C7=1,A7-Inputs!$D$9+1,"") | E7: =IF(C7=1,MIN(1,D7/Inputs!$D$29),0) -> 0 | F7: =Inputs!$D$13+(Inputs!$D$32-Inputs!$D$13)*E7 -> 0 | H7: =IF(G7="","",IFERROR(G7/F7-1,"")) | I7: =Inputs!$D$14+(Inputs!$D$24-Inputs!$D$14)*E7 -> 0 | K7: =IF(J7="","",IFERROR(J7/I7-1,"")) | L7: =IF(OR(G7="",J7=""),"",IFERROR(G7/J7,"")) | M7: =IF(OR(J7="",'Site Daily'!E7=""),"",IFERROR(J7/'Site Daily'!E7*1000,"")) | N7: =I7*(Inputs!$D$17+(Inputs!$D$26-Inputs!$D$17)*E7) -> 0 | P7: =IF(OR(O7="",J7=""),"",IFERROR(O7/J7,"")) | R7: =N7*(Inputs!$D$16+(Inputs!$D$27-Inputs!$D$16)*E7) -> 0 | S7: =IF(OR(O7="",Q7="",J7=""),"",IFERROR(O7*Q7/J7,"")) | T7: =IF(S7="","",IFERROR(S7/R7-1,"")) | U7: =C7*(R7-Inputs!$D$19)*Inputs!$D$28 -> 0 | V7: =IF(OR(C7=0,S7=""),"",(S7-Inputs!$D$19)*Inputs!$D$28) | X7: =IF(OR(W7="",G7=""),"",IFERROR(W7/G7,""))
A8: 46297 | B8: =TEXT(A8,"ddd") -> Fri | C8: =IF(A8>=Inputs!$D$9,1,0) -> 0 | D8: =IF(C8=1,A8-Inputs!$D$9+1,"") | E8: =IF(C8=1,MIN(1,D8/Inputs!$D$29),0) -> 0 | F8: =Inputs!$D$13+(Inputs!$D$32-Inputs!$D$13)*E8 -> 0 | H8: =IF(G8="","",IFERROR(G8/F8-1,"")) | I8: =Inputs!$D$14+(Inputs!$D$24-Inputs!$D$14)*E8 -> 0 | K8: =IF(J8="","",IFERROR(J8/I8-1,"")) | L8: =IF(OR(G8="",J8=""),"",IFERROR(G8/J8,"")) | M8: =IF(OR(J8="",'Site Daily'!E8=""),"",IFERROR(J8/'Site Daily'!E8*1000,"")) | N8: =I8*(Inputs!$D$17+(Inputs!$D$26-Inputs!$D$17)*E8) -> 0 | P8: =IF(OR(O8="",J8=""),"",IFERROR(O8/J8,"")) | R8: =N8*(Inputs!$D$16+(Inputs!$D$27-Inputs!$D$16)*E8) -> 0 | S8: =IF(OR(O8="",Q8="",J8=""),"",IFERROR(O8*Q8/J8,"")) | T8: =IF(S8="","",IFERROR(S8/R8-1,"")) | U8: =C8*(R8-Inputs!$D$19)*Inputs!$D$28 -> 0 | V8: =IF(OR(C8=0,S8=""),"",(S8-Inputs!$D$19)*Inputs!$D$28) | X8: =IF(OR(W8="",G8=""),"",IFERROR(W8/G8,""))
A9: 46298 | B9: =TEXT(A9,"ddd") -> Sat | C9: =IF(A9>=Inputs!$D$9,1,0) -> 0 | D9: =IF(C9=1,A9-Inputs!$D$9+1,"") | E9: =IF(C9=1,MIN(1,D9/Inputs!$D$29),0) -> 0 | F9: =Inputs!$D$13+(Inputs!$D$32-Inputs!$D$13)*E9 -> 0 | H9: =IF(G9="","",IFERROR(G9/F9-1,"")) | I9: =Inputs!$D$14+(Inputs!$D$24-Inputs!$D$14)*E9 -> 0 | K9: =IF(J9="","",IFERROR(J9/I9-1,"")) | L9: =IF(OR(G9="",J9=""),"",IFERROR(G9/J9,"")) | M9: =IF(OR(J9="",'Site Daily'!E9=""),"",IFERROR(J9/'Site Daily'!E9*1000,"")) | N9: =I9*(Inputs!$D$17+(Inputs!$D$26-Inputs!$D$17)*E9) -> 0 | P9: =IF(OR(O9="",J9=""),"",IFERROR(O9/J9,"")) | R9: =N9*(Inputs!$D$16+(Inputs!$D$27-Inputs!$D$16)*E9) -> 0 | S9: =IF(OR(O9="",Q9="",J9=""),"",IFERROR(O9*Q9/J9,"")) | T9: =IF(S9="","",IFERROR(S9/R9-1,"")) | U9: =C9*(R9-Inputs!$D$19)*Inputs!$D$28 -> 0 | V9: =IF(OR(C9=0,S9=""),"",(S9-Inputs!$D$19)*Inputs!$D$28) | X9: =IF(OR(W9="",G9=""),"",IFERROR(W9/G9,""))
A10: 46299 | B10: =TEXT(A10,"ddd") -> Sun | C10: =IF(A10>=Inputs!$D$9,1,0) -> 0 | D10: =IF(C10=1,A10-Inputs!$D$9+1,"") | E10: =IF(C10=1,MIN(1,D10/Inputs!$D$29),0) -> 0 | F10: =Inputs!$D$13+(Inputs!$D$32-Inputs!$D$13)*E10 -> 0 | H10: =IF(G10="","",IFERROR(G10/F10-1,"")) | I10: =Inputs!$D$14+(Inputs!$D$24-Inputs!$D$14)*E10 -> 0 | K10: =IF(J10="","",IFERROR(J10/I10-1,"")) | L10: =IF(OR(G10="",J10=""),"",IFERROR(G10/J10,"")) | M10: =IF(OR(J10="",'Site Daily'!E10=""),"",IFERROR(J10/'Site Daily'!E10*1000,"")) | N10: =I10*(Inputs!$D$17+(Inputs!$D$26-Inputs!$D$17)*E10) -> 0 | P10: =IF(OR(O10="",J10=""),"",IFERROR(O10/J10,"")) | R10: =N10*(Inputs!$D$16+(Inputs!$D$27-Inputs!$D$16)*E10) -> 0 | S10: =IF(OR(O10="",Q10="",J10=""),"",IFERROR(O10*Q10/J10,"")) | T10: =IF(S10="","",IFERROR(S10/R10-1,"")) | U10: =C10*(R10-Inputs!$D$19)*Inputs!$D$28 -> 0 | V10: =IF(OR(C10=0,S10=""),"",(S10-Inputs!$D$19)*Inputs!$D$28) | X10: =IF(OR(W10="",G10=""),"",IFERROR(W10/G10,""))
A11: 46300 | B11: =TEXT(A11,"ddd") -> Mon | C11: =IF(A11>=Inputs!$D$9,1,0) -> 0 | D11: =IF(C11=1,A11-Inputs!$D$9+1,"") | E11: =IF(C11=1,MIN(1,D11/Inputs!$D$29),0) -> 0 | F11: =Inputs!$D$13+(Inputs!$D$32-Inputs!$D$13)*E11 -> 0 | H11: =IF(G11="","",IFERROR(G11/F11-1,"")) | I11: =Inputs!$D$14+(Inputs!$D$24-Inputs!$D$14)*E11 -> 0 | K11: =IF(J11="","",IFERROR(J11/I11-1,"")) | L11: =IF(OR(G11="",J11=""),"",IFERROR(G11/J11,"")) | M11: =IF(OR(J11="",'Site Daily'!E11=""),"",IFERROR(J11/'Site Daily'!E11*1000,"")) | N11: =I11*(Inputs!$D$17+(Inputs!$D$26-Inputs!$D$17)*E11) -> 0 | P11: =IF(OR(O11="",J11=""),"",IFERROR(O11/J11,"")) | R11: =N11*(Inputs!$D$16+(Inputs!$D$27-Inputs!$D$16)*E11) -> 0 | S11: =IF(OR(O11="",Q11="",J11=""),"",IFERROR(O11*Q11/J11,"")) | T11: =IF(S11="","",IFERROR(S11/R11-1,"")) | U11: =C11*(R11-Inputs!$D$19)*Inputs!$D$28 -> 0 | V11: =IF(OR(C11=0,S11=""),"",(S11-Inputs!$D$19)*Inputs!$D$28) | X11: =IF(OR(W11="",G11=""),"",IFERROR(W11/G11,""))
A12: 46301 | B12: =TEXT(A12,"ddd") -> Tue | C12: =IF(A12>=Inputs!$D$9,1,0) -> 0 | D12: =IF(C12=1,A12-Inputs!$D$9+1,"") | E12: =IF(C12=1,MIN(1,D12/Inputs!$D$29),0) -> 0 | F12: =Inputs!$D$13+(Inputs!$D$32-Inputs!$D$13)*E12 -> 0 | H12: =IF(G12="","",IFERROR(G12/F12-1,"")) | I12: =Inputs!$D$14+(Inputs!$D$24-Inputs!$D$14)*E12 -> 0 | K12: =IF(J12="","",IFERROR(J12/I12-1,"")) | L12: =IF(OR(G12="",J12=""),"",IFERROR(G12/J12,"")) | M12: =IF(OR(J12="",'Site Daily'!E12=""),"",IFERROR(J12/'Site Daily'!E12*1000,"")) | N12: =I12*(Inputs!$D$17+(Inputs!$D$26-Inputs!$D$17)*E12) -> 0 | P12: =IF(OR(O12="",J12=""),"",IFERROR(O12/J12,"")) | R12: =N12*(Inputs!$D$16+(Inputs!$D$27-Inputs!$D$16)*E12) -> 0 | S12: =IF(OR(O12="",Q12="",J12=""),"",IFERROR(O12*Q12/J12,"")) | T12: =IF(S12="","",IFERROR(S12/R12-1,"")) | U12: =C12*(R12-Inputs!$D$19)*Inputs!$D$28 -> 0 | V12: =IF(OR(C12=0,S12=""),"",(S12-Inputs!$D$19)*Inputs!$D$28) | X12: =IF(OR(W12="",G12=""),"",IFERROR(W12/G12,""))
A13: 46302 | B13: =TEXT(A13,"ddd") -> Wed | C13: =IF(A13>=Inputs!$D$9,1,0) -> 0 | D13: =IF(C13=1,A13-Inputs!$D$9+1,"") | E13: =IF(C13=1,MIN(1,D13/Inputs!$D$29),0) -> 0 | F13: =Inputs!$D$13+(Inputs!$D$32-Inputs!$D$13)*E13 -> 0 | H13: =IF(G13="","",IFERROR(G13/F13-1,"")) | I13: =Inputs!$D$14+(Inputs!$D$24-Inputs!$D$14)*E13 -> 0 | K13: =IF(J13="","",IFERROR(J13/I13-1,"")) | L13: =IF(OR(G13="",J13=""),"",IFERROR(G13/J13,"")) | M13: =IF(OR(J13="",'Site Daily'!E13=""),"",IFERROR(J13/'Site Daily'!E13*1000,"")) | N13: =I13*(Inputs!$D$17+(Inputs!$D$26-Inputs!$D$17)*E13) -> 0 | P13: =IF(OR(O13="",J13=""),"",IFERROR(O13/J13,"")) | R13: =N13*(Inputs!$D$16+(Inputs!$D$27-Inputs!$D$16)*E13) -> 0 | S13: =IF(OR(O13="",Q13="",J13=""),"",IFERROR(O13*Q13/J13,"")) | T13: =IF(S13="","",IFERROR(S13/R13-1,"")) | U13: =C13*(R13-Inputs!$D$19)*Inputs!$D$28 -> 0 | V13: =IF(OR(C13=0,S13=""),"",(S13-Inputs!$D$19)*Inputs!$D$28) | X13: =IF(OR(W13="",G13=""),"",IFERROR(W13/G13,""))
A14: 46303 | B14: =TEXT(A14,"ddd") -> Thu | C14: =IF(A14>=Inputs!$D$9,1,0) -> 1 | D14: =IF(C14=1,A14-Inputs!$D$9+1,"") -> 1 | E14: =IF(C14=1,MIN(1,D14/Inputs!$D$29),0) -> 0.2 | F14: =Inputs!$D$13+(Inputs!$D$32-Inputs!$D$13)*E14 -> 60 | H14: =IF(G14="","",IFERROR(G14/F14-1,"")) | I14: =Inputs!$D$14+(Inputs!$D$24-Inputs!$D$14)*E14 -> 50 | K14: =IF(J14="","",IFERROR(J14/I14-1,"")) | L14: =IF(OR(G14="",J14=""),"",IFERROR(G14/J14,"")) | M14: =IF(OR(J14="",'Site Daily'!E14=""),"",IFERROR(J14/'Site Daily'!E14*1000,"")) | N14: =I14*(Inputs!$D$17+(Inputs!$D$26-Inputs!$D$17)*E14) -> 2 | P14: =IF(OR(O14="",J14=""),"",IFERROR(O14/J14,"")) | R14: =N14*(Inputs!$D$16+(Inputs!$D$27-Inputs!$D$16)*E14) -> 280 | S14: =IF(OR(O14="",Q14="",J14=""),"",IFERROR(O14*Q14/J14,"")) | T14: =IF(S14="","",IFERROR(S14/R14-1,"")) | U14: =C14*(R14-Inputs!$D$19)*Inputs!$D$28 -> 168 | V14: =IF(OR(C14=0,S14=""),"",(S14-Inputs!$D$19)*Inputs!$D$28) | X14: =IF(OR(W14="",G14=""),"",IFERROR(W14/G14,""))
